{
    "registryname": "chromasteel_forge",
    "localizedname": "炫钢熔炉",
    "requires-blueprint": true,
    "failure-action": "still",
    "color": "00838f",
    "modifiers": [
        {
            "elements": "modularmachinery:blockcasing@1",
            "x": 0,
            "y": 1,
            "z": 0,
            "description": "将控制器上方紧挨着的方块换成此方块以降低配方制作时间至75%！",
            "modifier": {
                "io": "output",
                "target": "duration",
                "operation": 1,
                "multiplier": 0.75
            }
        },
        {
            "elements": "modularmachinery:blockcasing@2",
            "x": 0,
            "y": 1,
            "z": 0,
            "description": "将控制器上方紧挨着的方块换成此方块以降低配方制作时间至66%！",
            "modifier": {
                "io": "output",
                "target": "duration",
                "operation": 1,
                "multiplier": 0.66
            }
        },
        {
            "elements": "modularmachinery:blockcasing@3",
            "x": 0,
            "y": 1,
            "z": 0,
            "description": "将控制器上方紧挨着的方块换成此方块以降低配方制作时间至50%！",
            "modifier": {
                "io": "output",
                "target": "duration",
                "operation": 1,
                "multiplier": 0.5
            }
        },
        {
            "elements": "modularmachinery:blockcasing@5",
            "x": 0,
            "y": 1,
            "z": 0,
            "description": "将控制器上方紧挨着的方块换成此方块以降低配方制作时间至33%！",
            "modifier": {
                "io": "output",
                "target": "duration",
                "operation": 1,
                "multiplier": 0.33
            }
        }
    ],
    "parts": [
        {
            "x": [-2, -1, 0, 1, 2],
            "y": [1, 2, 3, 4],
            "z": [1, 3],
            "elements": ["gct_tcon:solidpyrotheumblock"]
        },
        {
            "x": [-2, 2],
            "y": [1, 2, 3, 4],
            "z": [2],
            "elements": ["gct_tcon:solidpyrotheumblock"]
        },
        {
            "x": -1,
            "y": 0,
            "z": 0,
            "elements": ["modularmachinery:blockcasing@4"]
        },
        {
            "x": -3,
            "y": 0,
            "z": 4,
            "elements": ["additions:greedycraft-aeonsteel_block@0"]
        },
        {
            "x": -2,
            "y": 0,
            "z": 0,
            "elements": ["modularmachinery:blockcasing@4"]
        },
        {
            "x": 3,
            "y": 4,
            "z": 2,
            "elements": "casings_all"
        },
        {
            "x": 1,
            "y": 0,
            "z": 0,
            "elements": ["modularmachinery:blockcasing@4"]
        },
        {
            "x": -3,
            "y": 0,
            "z": 0,
            "elements": ["additions:greedycraft-aeonsteel_block@0"]
        },
        {
            "x": 3,
            "y": 2,
            "z": 1,
            "elements": ["thermalfoundation:glass@7"]
        },
        {
            "x": 2,
            "y": 0,
            "z": 0,
            "elements": ["modularmachinery:blockcasing@4"]
        },
        {
            "x": -2,
            "y": 0,
            "z": 4,
            "elements": ["modularmachinery:blockcasing@4"]
        },
        {
            "x": 3,
            "y": 0,
            "z": 0,
            "elements": ["additions:greedycraft-aeonsteel_block@0"]
        },
        {
            "x": -1,
            "y": 0,
            "z": 4,
            "elements": ["modularmachinery:blockcasing@4"]
        },
        {
            "x": 0,
            "y": 0,
            "z": 4,
            "elements": ["modularmachinery:blockcasing@4"]
        },
        {
            "x": 1,
            "y": 0,
            "z": 4,
            "elements": ["modularmachinery:blockcasing@4"]
        },
        {
            "x": 2,
            "y": 0,
            "z": 4,
            "elements": ["modularmachinery:blockcasing@4"]
        },
        {
            "x": 3,
            "y": 0,
            "z": 4,
            "elements": ["additions:greedycraft-aeonsteel_block@0"]
        },
        {
            "x": -3,
            "y": 5,
            "z": 2,
            "elements": ["draconicevolution:draconium_block@0"]
        },
        {
            "x": -3,
            "y": 3,
            "z": 1,
            "elements": ["thermalfoundation:glass@7"]
        },
        {
            "x": -3,
            "y": 1,
            "z": 0,
            "elements": "casings_all"
        },
        {
            "x": -2,
            "y": 1,
            "z": 0,
            "elements": ["thermalfoundation:glass@7"]
        },
        {
            "x": -1,
            "y": 1,
            "z": 0,
            "elements": ["thermalfoundation:glass@7"]
        },
        {
            "x": 0,
            "y": 1,
            "z": 0,
            "elements": ["thermalfoundation:glass@7"]
        },
        {
            "x": -3,
            "y": 1,
            "z": 4,
            "elements": "casings_all"
        },
        {
            "x": 3,
            "y": 5,
            "z": 2,
            "elements": ["draconicevolution:draconium_block@0"]
        },
        {
            "x": 1,
            "y": 1,
            "z": 0,
            "elements": ["thermalfoundation:glass@7"]
        },
        {
            "x": -2,
            "y": 1,
            "z": 4,
            "elements": ["thermalfoundation:glass@7"]
        },
        {
            "x": 3,
            "y": 3,
            "z": 1,
            "elements": ["thermalfoundation:glass@7"]
        },
        {
            "x": 2,
            "y": 1,
            "z": 0,
            "elements": ["thermalfoundation:glass@7"]
        },
        {
            "x": 3,
            "y": 1,
            "z": 0,
            "elements": "casings_all"
        },
        {
            "x": -1,
            "y": 1,
            "z": 4,
            "elements": ["thermalfoundation:glass@7"]
        },
        {
            "x": 0,
            "y": 1,
            "z": 4,
            "elements": ["thermalfoundation:glass@7"]
        },
        {
            "x": 1,
            "y": 1,
            "z": 4,
            "elements": ["thermalfoundation:glass@7"]
        },
        {
            "x": 2,
            "y": 1,
            "z": 4,
            "elements": ["thermalfoundation:glass@7"]
        },
        {
            "x": 3,
            "y": 1,
            "z": 4,
            "elements": "casings_all"
        },
        {
            "x": -3,
            "y": 4,
            "z": 1,
            "elements": "casings_all"
        },
        {
            "x": -2,
            "y": 6,
            "z": 2,
            "elements": ["draconicevolution:draconic_block@0"]
        },
        {
            "x": -3,
            "y": 2,
            "z": 0,
            "elements": "casings_all"
        },
        {
            "x": -1,
            "y": 6,
            "z": 2,
            "elements": "iron_bars"
        },
        {
            "x": -2,
            "y": 2,
            "z": 0,
            "elements": ["thermalfoundation:glass@7"]
        },
        {
            "x": 0,
            "y": 6,
            "z": 2,
            "elements": "iron_bars"
        },
        {
            "x": 1,
            "y": 6,
            "z": 2,
            "elements": "iron_bars"
        },
        {
            "x": -1,
            "y": 2,
            "z": 0,
            "elements": ["thermalfoundation:glass@7"]
        },
        {
            "x": 2,
            "y": 6,
            "z": 2,
            "elements": ["draconicevolution:draconic_block@0"]
        },
        {
            "x": 0,
            "y": 2,
            "z": 0,
            "elements": ["thermalfoundation:glass@7"]
        },
        {
            "x": -3,
            "y": 2,
            "z": 4,
            "elements": "casings_all"
        },
        {
            "x": 1,
            "y": 2,
            "z": 0,
            "elements": ["thermalfoundation:glass@7"]
        },
        {
            "x": -3,
            "y": 0,
            "z": 3,
            "elements": ["modularmachinery:blockcasing@4"]
        },
        {
            "x": -2,
            "y": 2,
            "z": 4,
            "elements": ["thermalfoundation:glass@7"]
        },
        {
            "x": 3,
            "y": 4,
            "z": 1,
            "elements": "casings_all"
        },
        {
            "x": 2,
            "y": 2,
            "z": 0,
            "elements": ["thermalfoundation:glass@7"]
        },
        {
            "x": 3,
            "y": 2,
            "z": 0,
            "elements": "casings_all"
        },
        {
            "x": -2,
            "y": 0,
            "z": 3,
            "elements": ["modularmachinery:blockcasing@4"]
        },
        {
            "x": -1,
            "y": 2,
            "z": 4,
            "elements": ["thermalfoundation:glass@7"]
        },
        {
            "x": 0,
            "y": 2,
            "z": 4,
            "elements": ["thermalfoundation:glass@7"]
        },
        {
            "x": -1,
            "y": 0,
            "z": 3,
            "elements": ["modularmachinery:blockcasing@4"]
        },
        {
            "x": 0,
            "y": 0,
            "z": 3,
            "elements": ["modularmachinery:blockcasing@4"]
        },
        {
            "x": 1,
            "y": 2,
            "z": 4,
            "elements": ["thermalfoundation:glass@7"]
        },
        {
            "x": 2,
            "y": 2,
            "z": 4,
            "elements": ["thermalfoundation:glass@7"]
        },
        {
            "x": 1,
            "y": 0,
            "z": 3,
            "elements": ["modularmachinery:blockcasing@4"]
        },
        {
            "x": 3,
            "y": 2,
            "z": 4,
            "elements": "casings_all"
        },
        {
            "x": 2,
            "y": 0,
            "z": 3,
            "elements": ["modularmachinery:blockcasing@4"]
        },
        {
            "x": 3,
            "y": 0,
            "z": 3,
            "elements": ["modularmachinery:blockcasing@4"]
        },
        {
            "x": -3,
            "y": 5,
            "z": 1,
            "elements": ["draconicevolution:draconium_block@0"]
        },
        {
            "x": -3,
            "y": 3,
            "z": 0,
            "elements": "casings_all"
        },
        {
            "x": -2,
            "y": 3,
            "z": 0,
            "elements": ["thermalfoundation:glass@7"]
        },
        {
            "x": -1,
            "y": 3,
            "z": 0,
            "elements": ["thermalfoundation:glass@7"]
        },
        {
            "x": 0,
            "y": 3,
            "z": 0,
            "elements": ["thermalfoundation:glass@7"]
        },
        {
            "x": 1,
            "y": 3,
            "z": 0,
            "elements": ["thermalfoundation:glass@7"]
        },
        {
            "x": -3,
            "y": 3,
            "z": 4,
            "elements": "casings_all"
        },
        {
            "x": -3,
            "y": 1,
            "z": 3,
            "elements": "casings_all"
        },
        {
            "x": -2,
            "y": 3,
            "z": 4,
            "elements": ["thermalfoundation:glass@7"]
        },
        {
            "x": 3,
            "y": 5,
            "z": 1,
            "elements": ["draconicevolution:draconium_block@0"]
        },
        {
            "x": 2,
            "y": 3,
            "z": 0,
            "elements": ["thermalfoundation:glass@7"]
        },
        {
            "x": -1,
            "y": 3,
            "z": 4,
            "elements": ["thermalfoundation:glass@7"]
        },
        {
            "x": 3,
            "y": 3,
            "z": 0,
            "elements": "casings_all"
        },
        {
            "x": 0,
            "y": 3,
            "z": 4,
            "elements": ["thermalfoundation:glass@7"]
        },
        {
            "x": 1,
            "y": 3,
            "z": 4,
            "elements": ["thermalfoundation:glass@7"]
        },
        {
            "x": 2,
            "y": 3,
            "z": 4,
            "elements": ["thermalfoundation:glass@7"]
        },
        {
            "x": 3,
            "y": 3,
            "z": 4,
            "elements": "casings_all"
        },
        {
            "x": 3,
            "y": 1,
            "z": 3,
            "elements": "casings_all"
        },
        {
            "x": -3,
            "y": 4,
            "z": 0,
            "elements": "casings_all"
        },
        {
            "x": -2,
            "y": 6,
            "z": 1,
            "elements": ["additions:greedycraft-aeonsteel_block@0"]
        },
        {
            "x": -2,
            "y": 4,
            "z": 0,
            "elements": ["thermalfoundation:glass@7"]
        },
        {
            "x": -1,
            "y": 6,
            "z": 1,
            "elements": ["draconicevolution:infused_obsidian@0"]
        },
        {
            "x": -1,
            "y": 4,
            "z": 0,
            "elements": ["thermalfoundation:glass@7"]
        },
        {
            "x": 0,
            "y": 6,
            "z": 1,
            "elements": ["draconicevolution:infused_obsidian@0"]
        },
        {
            "x": 1,
            "y": 6,
            "z": 1,
            "elements": ["draconicevolution:infused_obsidian@0"]
        },
        {
            "x": 0,
            "y": 4,
            "z": 0,
            "elements": ["thermalfoundation:glass@7"]
        },
        {
            "x": 2,
            "y": 6,
            "z": 1,
            "elements": ["additions:greedycraft-aeonsteel_block@0"]
        },
        {
            "x": 1,
            "y": 4,
            "z": 0,
            "elements": ["thermalfoundation:glass@7"]
        },
        {
            "x": -3,
            "y": 4,
            "z": 4,
            "elements": "casings_all"
        },
        {
            "x": -3,
            "y": 2,
            "z": 3,
            "elements": ["thermalfoundation:glass@7"]
        },
        {
            "x": -2,
            "y": 4,
            "z": 4,
            "elements": ["thermalfoundation:glass@7"]
        },
        {
            "x": 2,
            "y": 4,
            "z": 0,
            "elements": ["thermalfoundation:glass@7"]
        },
        {
            "x": -3,
            "y": 0,
            "z": 2,
            "elements": ["modularmachinery:blockcasing@4"]
        },
        {
            "x": -1,
            "y": 4,
            "z": 4,
            "elements": ["thermalfoundation:glass@7"]
        },
        {
            "x": 3,
            "y": 4,
            "z": 0,
            "elements": "casings_all"
        },
        {
            "x": 0,
            "y": 4,
            "z": 4,
            "elements": ["thermalfoundation:glass@7"]
        },
        {
            "x": -2,
            "y": 0,
            "z": 2,
            "elements": ["modularmachinery:blockcasing@4"]
        },
        {
            "x": 1,
            "y": 4,
            "z": 4,
            "elements": ["thermalfoundation:glass@7"]
        },
        {
            "x": -1,
            "y": 0,
            "z": 2,
            "elements": ["modularmachinery:blockcasing@4"]
        },
        {
            "x": 0,
            "y": 0,
            "z": 2,
            "elements": ["modularmachinery:blockcasing@4"]
        },
        {
            "x": 2,
            "y": 4,
            "z": 4,
            "elements": ["thermalfoundation:glass@7"]
        },
        {
            "x": 3,
            "y": 4,
            "z": 4,
            "elements": "casings_all"
        },
        {
            "x": 1,
            "y": 0,
            "z": 2,
            "elements": ["modularmachinery:blockcasing@4"]
        },
        {
            "x": 3,
            "y": 2,
            "z": 3,
            "elements": ["thermalfoundation:glass@7"]
        },
        {
            "x": 2,
            "y": 0,
            "z": 2,
            "elements": ["modularmachinery:blockcasing@4"]
        },
        {
            "x": 3,
            "y": 0,
            "z": 2,
            "elements": ["modularmachinery:blockcasing@4"]
        },
        {
            "x": -3,
            "y": 5,
            "z": 0,
            "elements": ["additions:greedycraft-aeonsteel_block@0"]
        },
        {
            "x": -2,
            "y": 5,
            "z": 0,
            "elements": ["draconicevolution:infused_obsidian@0"]
        },
        {
            "x": -1,
            "y": 5,
            "z": 0,
            "elements": ["draconicevolution:draconium_block@0"]
        },
        {
            "x": 0,
            "y": 5,
            "z": 0,
            "elements": ["draconicevolution:draconium_block@0"]
        },
        {
            "x": 1,
            "y": 5,
            "z": 0,
            "elements": ["draconicevolution:draconium_block@0"]
        },
        {
            "x": -3,
            "y": 5,
            "z": 4,
            "elements": ["additions:greedycraft-aeonsteel_block@0"]
        },
        {
            "x": 2,
            "y": 5,
            "z": 0,
            "elements": ["draconicevolution:infused_obsidian@0"]
        },
        {
            "x": -3,
            "y": 3,
            "z": 3,
            "elements": ["thermalfoundation:glass@7"]
        },
        {
            "x": -2,
            "y": 5,
            "z": 4,
            "elements": ["draconicevolution:infused_obsidian@0"]
        },
        {
            "x": -3,
            "y": 1,
            "z": 2,
            "elements": "casings_all"
        },
        {
            "x": -1,
            "y": 5,
            "z": 4,
            "elements": ["draconicevolution:draconium_block@0"]
        },
        {
            "x": 3,
            "y": 5,
            "z": 0,
            "elements": ["additions:greedycraft-aeonsteel_block@0"]
        },
        {
            "x": 0,
            "y": 5,
            "z": 4,
            "elements": ["draconicevolution:draconium_block@0"]
        },
        {
            "x": 1,
            "y": 5,
            "z": 4,
            "elements": ["draconicevolution:draconium_block@0"]
        },
        {
            "x": -1,
            "y": 1,
            "z": 2,
            "elements": ["draconicevolution:infused_obsidian@0"]
        },
        {
            "x": 2,
            "y": 5,
            "z": 4,
            "elements": ["draconicevolution:infused_obsidian@0"]
        },
        {
            "x": 0,
            "y": 1,
            "z": 2,
            "elements": ["draconicevolution:infused_obsidian@0"]
        },
        {
            "x": 3,
            "y": 5,
            "z": 4,
            "elements": ["additions:greedycraft-aeonsteel_block@0"]
        },
        {
            "x": 1,
            "y": 1,
            "z": 2,
            "elements": ["draconicevolution:infused_obsidian@0"]
        },
        {
            "x": 3,
            "y": 3,
            "z": 3,
            "elements": ["thermalfoundation:glass@7"]
        },
        {
            "x": 3,
            "y": 1,
            "z": 2,
            "elements": "casings_all"
        },
        {
            "x": -3,
            "y": 4,
            "z": 3,
            "elements": "casings_all"
        },
        {
            "x": -3,
            "y": 2,
            "z": 2,
            "elements": ["thermalfoundation:glass@7"]
        },
        {
            "x": -3,
            "y": 0,
            "z": 1,
            "elements": ["modularmachinery:blockcasing@4"]
        },
        {
            "x": -2,
            "y": 0,
            "z": 1,
            "elements": ["modularmachinery:blockcasing@4"]
        },
        {
            "x": -1,
            "y": 2,
            "z": 2,
            "elements": ["draconicevolution:infused_obsidian@0"]
        },
        {
            "x": 0,
            "y": 2,
            "z": 2,
            "elements": ["draconicevolution:infused_obsidian@0"]
        },
        {
            "x": -1,
            "y": 0,
            "z": 1,
            "elements": ["modularmachinery:blockcasing@4"]
        },
        {
            "x": 0,
            "y": 0,
            "z": 1,
            "elements": ["modularmachinery:blockcasing@4"]
        },
        {
            "x": 1,
            "y": 2,
            "z": 2,
            "elements": ["draconicevolution:infused_obsidian@0"]
        },
        {
            "x": 3,
            "y": 4,
            "z": 3,
            "elements": "casings_all"
        },
        {
            "x": 1,
            "y": 0,
            "z": 1,
            "elements": ["modularmachinery:blockcasing@4"]
        },
        {
            "x": 3,
            "y": 2,
            "z": 2,
            "elements": ["thermalfoundation:glass@7"]
        },
        {
            "x": 2,
            "y": 0,
            "z": 1,
            "elements": ["modularmachinery:blockcasing@4"]
        },
        {
            "x": 3,
            "y": 0,
            "z": 1,
            "elements": ["modularmachinery:blockcasing@4"]
        },
        {
            "x": -3,
            "y": 5,
            "z": 3,
            "elements": ["draconicevolution:draconium_block@0"]
        },
        {
            "x": -3,
            "y": 3,
            "z": 2,
            "elements": ["thermalfoundation:glass@7"]
        },
        {
            "x": -3,
            "y": 1,
            "z": 1,
            "elements": "casings_all"
        },
        {
            "x": -1,
            "y": 3,
            "z": 2,
            "elements": ["draconicevolution:infused_obsidian@0"]
        },
        {
            "x": 0,
            "y": 3,
            "z": 2,
            "elements": ["draconicevolution:infused_obsidian@0"]
        },
        {
            "x": 1,
            "y": 3,
            "z": 2,
            "elements": ["draconicevolution:infused_obsidian@0"]
        },
        {
            "x": 3,
            "y": 5,
            "z": 3,
            "elements": ["draconicevolution:draconium_block@0"]
        },
        {
            "x": 3,
            "y": 3,
            "z": 2,
            "elements": ["thermalfoundation:glass@7"]
        },
        {
            "x": 3,
            "y": 1,
            "z": 1,
            "elements": "casings_all"
        },
        {
            "x": -3,
            "y": 4,
            "z": 2,
            "elements": "casings_all"
        },
        {
            "x": -2,
            "y": 6,
            "z": 3,
            "elements": ["additions:greedycraft-aeonsteel_block@0"]
        },
        {
            "x": -3,
            "y": 2,
            "z": 1,
            "elements": ["thermalfoundation:glass@7"]
        },
        {
            "x": -1,
            "y": 6,
            "z": 3,
            "elements": ["draconicevolution:infused_obsidian@0"]
        },
        {
            "x": -1,
            "y": 4,
            "z": 2,
            "elements": ["draconicevolution:infused_obsidian@0"]
        },
        {
            "x": 0,
            "y": 6,
            "z": 3,
            "elements": ["draconicevolution:infused_obsidian@0"]
        },
        {
            "x": 1,
            "y": 6,
            "z": 3,
            "elements": ["draconicevolution:infused_obsidian@0"]
        },
        {
            "x": 0,
            "y": 4,
            "z": 2,
            "elements": ["draconicevolution:infused_obsidian@0"]
        },
        {
            "x": 2,
            "y": 6,
            "z": 3,
            "elements": ["additions:greedycraft-aeonsteel_block@0"]
        },
        {
            "x": 1,
            "y": 4,
            "z": 2,
            "elements": ["draconicevolution:infused_obsidian@0"]
        }
    ]
}
