{
    "registryname": "durasteel_forge",
    "localizedname": "耐钢熔炉",
    "requires-blueprint": true,
    "failure-action": "still",
    "color": "aaaaaa",
    "modifiers": [
        {
            "elements": "modularmachinery:blockcasing@1",
            "x": 0,
            "y": 1,
            "z": 0,
            "description": "将控制器上方紧挨着的方块换成此方块以降低配方制作时间至75%！",
            "modifier": {
                "io": "output",
                "target": "duration",
                "operation": 1,
                "multiplier": 0.75
            }
        },
        {
            "elements": "modularmachinery:blockcasing@2",
            "x": 0,
            "y": 1,
            "z": 0,
            "description": "将控制器上方紧挨着的方块换成此方块以降低配方制作时间至66%！",
            "modifier": {
                "io": "output",
                "target": "duration",
                "operation": 1,
                "multiplier": 0.66
            }
        },
        {
            "elements": "modularmachinery:blockcasing@3",
            "x": 0,
            "y": 1,
            "z": 0,
            "description": "将控制器上方紧挨着的方块换成此方块以降低配方制作时间至50%！",
            "modifier": {
                "io": "output",
                "target": "duration",
                "operation": 1,
                "multiplier": 0.5
            }
        },
        {
            "elements": "modularmachinery:blockcasing@5",
            "x": 0,
            "y": 1,
            "z": 0,
            "description": "将控制器上方紧挨着的方块换成此方块以降低配方制作时间至33%！",
            "modifier": {
                "io": "output",
                "target": "duration",
                "operation": 1,
                "multiplier": 0.33
            }
        }
    ],
    "parts": [
        {
            "x": [-1, 0, 1],
            "y": [1, 2],
            "z": 1,
            "elements": ["abyssalcraft:solidlava"]
        },
        {
            "x": -2,
            "y": 0,
            "z": 2,
            "elements": ["additions:greedycraft-stainless_steel_block@0"]
        },
        {
            "x": -1,
            "y": 0,
            "z": 0,
            "elements": ["modularmachinery:blockcasing@4"]
        },
        {
            "x": -2,
            "y": 0,
            "z": 0,
            "elements": ["additions:greedycraft-stainless_steel_block@0"]
        },
        {
            "x": 2,
            "y": 2,
            "z": 1,
            "elements": "casings_all"
        },
        {
            "x": 1,
            "y": 0,
            "z": 0,
            "elements": ["modularmachinery:blockcasing@4"]
        },
        {
            "x": -1,
            "y": 0,
            "z": 2,
            "elements": ["modularmachinery:blockcasing@4"]
        },
        {
            "x": 0,
            "y": 0,
            "z": 2,
            "elements": ["modularmachinery:blockcasing@4"]
        },
        {
            "x": 2,
            "y": 0,
            "z": 0,
            "elements": ["additions:greedycraft-stainless_steel_block@0"]
        },
        {
            "x": 1,
            "y": 0,
            "z": 2,
            "elements": ["modularmachinery:blockcasing@4"]
        },
        {
            "x": 2,
            "y": 0,
            "z": 2,
            "elements": ["additions:greedycraft-stainless_steel_block@0"]
        },
        {
            "x": -2,
            "y": 3,
            "z": 1,
            "elements": ["modularmachinery:blockcasing@4"]
        },
        {
            "x": -2,
            "y": 1,
            "z": 0,
            "elements": "casings_all"
        },
        {
            "x": -1,
            "y": 3,
            "z": 1,
            "elements": ["minecraft:obsidian@0"]
        },
        {
            "x": -1,
            "y": 1,
            "z": 0,
            "elements": ["thermalfoundation:glass@3"]
        },
        {
            "x": 0,
            "y": 3,
            "z": 1,
            "elements": "iron_bars"
        },
        {
            "x": 1,
            "y": 3,
            "z": 1,
            "elements": ["minecraft:obsidian@0"]
        },
        {
            "x": 0,
            "y": 1,
            "z": 0,
            "elements": ["thermalfoundation:glass@3"]
        },
        {
            "x": -2,
            "y": 1,
            "z": 2,
            "elements": "casings_all"
        },
        {
            "x": -1,
            "y": 1,
            "z": 2,
            "elements": ["thermalfoundation:glass@3"]
        },
        {
            "x": 2,
            "y": 3,
            "z": 1,
            "elements": ["modularmachinery:blockcasing@4"]
        },
        {
            "x": 1,
            "y": 1,
            "z": 0,
            "elements": ["thermalfoundation:glass@3"]
        },
        {
            "x": 0,
            "y": 1,
            "z": 2,
            "elements": ["thermalfoundation:glass@3"]
        },
        {
            "x": 2,
            "y": 1,
            "z": 0,
            "elements": "casings_all"
        },
        {
            "x": 1,
            "y": 1,
            "z": 2,
            "elements": ["thermalfoundation:glass@3"]
        },
        {
            "x": 2,
            "y": 1,
            "z": 2,
            "elements": "casings_all"
        },
        {
            "x": -2,
            "y": 2,
            "z": 0,
            "elements": "casings_all"
        },
        {
            "x": -1,
            "y": 2,
            "z": 0,
            "elements": ["thermalfoundation:glass@3"]
        },
        {
            "x": 0,
            "y": 2,
            "z": 0,
            "elements": ["thermalfoundation:glass@3"]
        },
        {
            "x": -2,
            "y": 2,
            "z": 2,
            "elements": "casings_all"
        },
        {
            "x": -2,
            "y": 0,
            "z": 1,
            "elements": ["modularmachinery:blockcasing@4"]
        },
        {
            "x": -1,
            "y": 2,
            "z": 2,
            "elements": ["thermalfoundation:glass@3"]
        },
        {
            "x": 1,
            "y": 2,
            "z": 0,
            "elements": ["thermalfoundation:glass@3"]
        },
        {
            "x": 0,
            "y": 2,
            "z": 2,
            "elements": ["thermalfoundation:glass@3"]
        },
        {
            "x": 2,
            "y": 2,
            "z": 0,
            "elements": "casings_all"
        },
        {
            "x": -1,
            "y": 0,
            "z": 1,
            "elements": ["modularmachinery:blockcasing@4"]
        },
        {
            "x": 0,
            "y": 0,
            "z": 1,
            "elements": ["modularmachinery:blockcasing@4"]
        },
        {
            "x": 1,
            "y": 2,
            "z": 2,
            "elements": ["thermalfoundation:glass@3"]
        },
        {
            "x": 2,
            "y": 2,
            "z": 2,
            "elements": "casings_all"
        },
        {
            "x": 1,
            "y": 0,
            "z": 1,
            "elements": ["modularmachinery:blockcasing@4"]
        },
        {
            "x": 2,
            "y": 0,
            "z": 1,
            "elements": ["modularmachinery:blockcasing@4"]
        },
        {
            "x": -1,
            "y": 3,
            "z": 0,
            "elements": ["minecraft:glowstone@0"]
        },
        {
            "x": 0,
            "y": 3,
            "z": 0,
            "elements": ["minecraft:obsidian@0"]
        },
        {
            "x": 1,
            "y": 3,
            "z": 0,
            "elements": ["minecraft:glowstone@0"]
        },
        {
            "x": -2,
            "y": 1,
            "z": 1,
            "elements": "casings_all"
        },
        {
            "x": -1,
            "y": 3,
            "z": 2,
            "elements": ["minecraft:glowstone@0"]
        },
        {
            "x": 0,
            "y": 3,
            "z": 2,
            "elements": ["minecraft:obsidian@0"]
        },
        {
            "x": 1,
            "y": 3,
            "z": 2,
            "elements": ["minecraft:glowstone@0"]
        },
        {
            "x": 2,
            "y": 1,
            "z": 1,
            "elements": "casings_all"
        },
        {
            "x": -2,
            "y": 2,
            "z": 1,
            "elements": "casings_all"
        }
    ]
}
