{
    "parts": [
        {
            "x": 0,
            "y": 0,
            "z": 0,
            "nbt": {"statusTag":{"type":"0","message":""},"casingColor":"16730368","ForgeCaps":{"abyssalcraft:itemtransfer":{"isRunning":"0b","configurations":[]}},"id":"minecraft:tilemachinecontroller","items":{"inventoryArray":[{"holderEmpty":"1b","holderId":"0"},{"holderEmpty":"1b","holderId":"1"}],"outSlots":,"miscSlots":,"inSlots":,"sides":}},
            "elements": [
                "modularmachinery:blockcontroller@2"
            ]
        },
        {
            "x": -1,
            "y": 0,
            "z": 0,
            "elements": [
                "additions:greedycraft-modularium_block@0"
            ]
        },
        {
            "x": 3,
            "y": 6,
            "z": 3,
            "elements": [
                "gct_ores:fire_alloy@0"
            ]
        },
        {
            "x": 2,
            "y": 4,
            "z": 2,
            "nbt": {"casingColor":"16730368","ForgeCaps":{"abyssalcraft:itemtransfer":{"isRunning":"0b","configurations":[]}},"id":"minecraft:tilecolorablemachinecomponent"},
            "elements": [
                "modularmachinery:blockcasing@4"
            ]
        },
        {
            "x": 1,
            "y": 2,
            "z": 1,
            "elements": [
                "gct_ores:fire_alloy@0"
            ]
        },
        {
            "x": -2,
            "y": 0,
            "z": 0,
            "nbt": {"casingColor":"16730368","ForgeCaps":{"abyssalcraft:itemtransfer":{"isRunning":"0b","configurations":[]}},"id":"minecraft:tilecolorablemachinecomponent"},
            "elements": [
                "modularmachinery:blockcasing@4"
            ]
        },
        {
            "x": 4,
            "y": 6,
            "z": 3,
            "elements": [
                "extendedcrafting:storage@2"
            ]
        },
        {
            "x": 3,
            "y": 4,
            "z": 2,
            "elements": [
                "gct_ores:fire_alloy@0"
            ]
        },
        {
            "x": 2,
            "y": 2,
            "z": 1,
            "elements": [
                "gct_ores:fire_alloy@0"
            ]
        },
        {
            "x": 1,
            "y": 0,
            "z": 0,
            "nbt": {"casingColor":"16730368","ForgeCaps":{"abyssalcraft:itemtransfer":{"isRunning":"0b","configurations":[]}},"id":"minecraft:tilecolorablemachinecomponent"},
            "elements": [
                "modularmachinery:blockcasing@4"
            ]
        },
        {
            "x": -3,
            "y": 0,
            "z": 0,
            "nbt": {"casingColor":"16730368","ForgeCaps":{"abyssalcraft:itemtransfer":{"isRunning":"0b","configurations":[]}},"id":"minecraft:tilecolorablemachinecomponent"},
            "elements": [
                "modularmachinery:blockcasing@4"
            ]
        },
        {
            "x": 4,
            "y": 4,
            "z": 2,
            "elements": [
                "extendedcrafting:storage@2"
            ]
        },
        {
            "x": 3,
            "y": 2,
            "z": 1,
            "elements": [
                "gct_ores:fire_alloy@0"
            ]
        },
        {
            "x": 2,
            "y": 0,
            "z": 0,
            "nbt": {"casingColor":"16730368","ForgeCaps":{"abyssalcraft:itemtransfer":{"isRunning":"0b","configurations":[]}},"id":"minecraft:tilecolorablemachinecomponent"},
            "elements": [
                "modularmachinery:blockcasing@4"
            ]
        },
        {
            "x": -4,
            "y": 0,
            "z": 0,
            "nbt": {"casingColor":"16730368","ForgeCaps":{"abyssalcraft:itemtransfer":{"isRunning":"0b","configurations":[]}},"id":"minecraft:tilecolorablemachinecomponent"},
            "elements": [
                "modularmachinery:blockcasing@4"
            ]
        },
        {
            "x": 4,
            "y": 2,
            "z": 1,
            "elements": [
                "minecraft:barrier@0"
            ]
        },
        {
            "x": 3,
            "y": 0,
            "z": 0,
            "nbt": {"casingColor":"16730368","ForgeCaps":{"abyssalcraft:itemtransfer":{"isRunning":"0b","configurations":[]}},"id":"minecraft:tilecolorablemachinecomponent"},
            "elements": [
                "modularmachinery:blockcasing@4"
            ]
        },
        {
            "x": -5,
            "y": 0,
            "z": 0,
            "elements": [
                "additions:greedycraft-cosmilite_block@0"
            ]
        },
        {
            "x": 4,
            "y": 0,
            "z": 0,
            "elements": [
                "additions:greedycraft-cosmilite_block@0"
            ]
        },
        {
            "x": -5,
            "y": 7,
            "z": 3,
            "elements": [
                "gct_ores:ordered_metal_block@0"
            ]
        },
        {
            "x": -5,
            "y": 5,
            "z": 2,
            "elements": [
                "minecraft:barrier@0"
            ]
        },
        {
            "x": -5,
            "y": 3,
            "z": 1,
            "elements": [
                "minecraft:barrier@0"
            ]
        },
        {
            "x": -4,
            "y": 5,
            "z": 2,
            "elements": [
                "gct_ores:fire_alloy@0"
            ]
        },
        {
            "x": -5,
            "y": 1,
            "z": 0,
            "elements": [
                "additions:greedycraft-fusion_matrix_block@0"
            ]
        },
        {
            "x": -4,
            "y": 3,
            "z": 1,
            "elements": [
                "gct_ores:fire_alloy@0"
            ]
        },
        {
            "x": -3,
            "y": 5,
            "z": 2,
            "elements": [
                "gct_ores:everite_block@0"
            ]
        },
        {
            "x": -2,
            "y": 7,
            "z": 3,
            "elements": [
                "minecraft:fire@0"
            ]
        },
        {
            "x": -4,
            "y": 1,
            "z": 0,
            "elements": [
                "minecraft:barrier@0"
            ]
        },
        {
            "x": -3,
            "y": 3,
            "z": 1,
            "elements": [
                "gct_ores:fire_alloy@0"
            ]
        },
        {
            "x": -2,
            "y": 5,
            "z": 2,
            "elements": [
                "gct_ores:everite_block@0"
            ]
        },
        {
            "x": -1,
            "y": 7,
            "z": 3,
            "elements": [
                "minecraft:fire@0"
            ]
        },
        {
            "x": 0,
            "y": 7,
            "z": 3,
            "elements": [
                "minecraft:fire@0"
            ]
        },
        {
            "x": -3,
            "y": 1,
            "z": 0,
            "elements": [
                "minecraft:barrier@0"
            ]
        },
        {
            "x": -2,
            "y": 3,
            "z": 1,
            "elements": [
                "gct_ores:fire_alloy@0"
            ]
        },
        {
            "x": -1,
            "y": 5,
            "z": 2,
            "elements": [
                "gct_ores:everite_block@0"
            ]
        },
        {
            "x": 1,
            "y": 7,
            "z": 3,
            "elements": [
                "minecraft:fire@0"
            ]
        },
        {
            "x": 0,
            "y": 5,
            "z": 2,
            "elements": [
                "gct_ores:everite_block@0"
            ]
        },
        {
            "x": -2,
            "y": 1,
            "z": 0,
            "elements": [
                "minecraft:barrier@0"
            ]
        },
        {
            "x": -1,
            "y": 3,
            "z": 1,
            "elements": [
                "gct_ores:fire_alloy@0"
            ]
        },
        {
            "x": 1,
            "y": 5,
            "z": 2,
            "elements": [
                "gct_ores:everite_block@0"
            ]
        },
        {
            "x": 0,
            "y": 3,
            "z": 1,
            "elements": [
                "gct_ores:fire_alloy@0"
            ]
        },
        {
            "x": -1,
            "y": 1,
            "z": 0,
            "elements": [
                "minecraft:barrier@0"
            ]
        },
        {
            "x": 2,
            "y": 5,
            "z": 2,
            "elements": [
                "gct_ores:everite_block@0"
            ]
        },
        {
            "x": 1,
            "y": 3,
            "z": 1,
            "elements": [
                "gct_ores:fire_alloy@0"
            ]
        },
        {
            "x": 0,
            "y": 1,
            "z": 0,
            "elements": [
                "minecraft:barrier@0"
            ]
        },
        {
            "x": 4,
            "y": 7,
            "z": 3,
            "elements": [
                "gct_ores:ordered_metal_block@0"
            ]
        },
        {
            "x": 3,
            "y": 5,
            "z": 2,
            "elements": [
                "gct_ores:fire_alloy@0"
            ]
        },
        {
            "x": 2,
            "y": 3,
            "z": 1,
            "elements": [
                "gct_ores:fire_alloy@0"
            ]
        },
        {
            "x": 1,
            "y": 1,
            "z": 0,
            "elements": [
                "minecraft:barrier@0"
            ]
        },
        {
            "x": 4,
            "y": 5,
            "z": 2,
            "elements": [
                "minecraft:barrier@0"
            ]
        },
        {
            "x": 3,
            "y": 3,
            "z": 1,
            "elements": [
                "gct_ores:fire_alloy@0"
            ]
        },
        {
            "x": 2,
            "y": 1,
            "z": 0,
            "elements": [
                "minecraft:barrier@0"
            ]
        },
        {
            "x": 4,
            "y": 3,
            "z": 1,
            "elements": [
                "minecraft:barrier@0"
            ]
        },
        {
            "x": 3,
            "y": 1,
            "z": 0,
            "elements": [
                "minecraft:barrier@0"
            ]
        },
        {
            "x": 4,
            "y": 1,
            "z": 0,
            "elements": [
                "additions:greedycraft-fusion_matrix_block@0"
            ]
        },
        {
            "x": -5,
            "y": 6,
            "z": 2,
            "elements": [
                "extendedcrafting:storage@2"
            ]
        },
        {
            "x": -4,
            "y": 8,
            "z": 3,
            "elements": [
                "mekanism:basicblock@2"
            ]
        },
        {
            "x": -5,
            "y": 4,
            "z": 1,
            "elements": [
                "minecraft:barrier@0"
            ]
        },
        {
            "x": -4,
            "y": 6,
            "z": 2,
            "elements": [
                "gct_ores:fire_alloy@0"
            ]
        },
        {
            "x": -3,
            "y": 8,
            "z": 3,
            "elements": [
                "thermalfoundation:glass@8"
            ]
        },
        {
            "x": -5,
            "y": 2,
            "z": 0,
            "elements": [
                "additions:greedycraft-fusion_matrix_block@0"
            ]
        },
        {
            "x": -4,
            "y": 4,
            "z": 1,
            "elements": [
                "gct_ores:fire_alloy@0"
            ]
        },
        {
            "x": -3,
            "y": 6,
            "z": 2,
            "elements": [
                "thermalfoundation:fluid_pyrotheum@0"
            ]
        },
        {
            "x": -2,
            "y": 8,
            "z": 3,
            "elements": [
                "enderio:block_end_iron_bars@0"
            ]
        },
        {
            "x": -4,
            "y": 2,
            "z": 0,
            "elements": [
                "minecraft:barrier@0"
            ]
        },
        {
            "x": -3,
            "y": 4,
            "z": 1,
            "elements": [
                "gct_ores:fire_alloy@0"
            ]
        },
        {
            "x": -2,
            "y": 6,
            "z": 2,
            "elements": [
                "thermalfoundation:fluid_pyrotheum@0"
            ]
        },
        {
            "x": -1,
            "y": 8,
            "z": 3,
            "elements": [
                "enderio:block_end_iron_bars@0"
            ]
        },
        {
            "x": 0,
            "y": 8,
            "z": 3,
            "elements": [
                "enderio:block_end_iron_bars@0"
            ]
        },
        {
            "x": -3,
            "y": 2,
            "z": 0,
            "elements": [
                "minecraft:barrier@0"
            ]
        },
        {
            "x": -2,
            "y": 4,
            "z": 1,
            "elements": [
                "gct_ores:fire_alloy@0"
            ]
        },
        {
            "x": -1,
            "y": 6,
            "z": 2,
            "elements": [
                "thermalfoundation:fluid_pyrotheum@0"
            ]
        },
        {
            "x": 1,
            "y": 8,
            "z": 3,
            "elements": [
                "enderio:block_end_iron_bars@0"
            ]
        },
        {
            "x": 0,
            "y": 6,
            "z": 2,
            "elements": [
                "thermalfoundation:fluid_pyrotheum@0"
            ]
        },
        {
            "x": -2,
            "y": 2,
            "z": 0,
            "elements": [
                "minecraft:barrier@0"
            ]
        },
        {
            "x": -1,
            "y": 4,
            "z": 1,
            "elements": [
                "gct_ores:fire_alloy@0"
            ]
        },
        {
            "x": 2,
            "y": 8,
            "z": 3,
            "elements": [
                "thermalfoundation:glass@8"
            ]
        },
        {
            "x": 1,
            "y": 6,
            "z": 2,
            "elements": [
                "thermalfoundation:fluid_pyrotheum@0"
            ]
        },
        {
            "x": 0,
            "y": 4,
            "z": 1,
            "elements": [
                "gct_ores:fire_alloy@0"
            ]
        },
        {
            "x": -1,
            "y": 2,
            "z": 0,
            "elements": [
                "minecraft:barrier@0"
            ]
        },
        {
            "x": 3,
            "y": 8,
            "z": 3,
            "elements": [
                "mekanism:basicblock@2"
            ]
        },
        {
            "x": 2,
            "y": 6,
            "z": 2,
            "elements": [
                "thermalfoundation:fluid_pyrotheum@0"
            ]
        },
        {
            "x": 1,
            "y": 4,
            "z": 1,
            "elements": [
                "gct_ores:fire_alloy@0"
            ]
        },
        {
            "x": 0,
            "y": 2,
            "z": 0,
            "elements": [
                "minecraft:barrier@0"
            ]
        },
        {
            "x": 3,
            "y": 6,
            "z": 2,
            "elements": [
                "gct_ores:fire_alloy@0"
            ]
        },
        {
            "x": 2,
            "y": 4,
            "z": 1,
            "elements": [
                "gct_ores:fire_alloy@0"
            ]
        },
        {
            "x": 1,
            "y": 2,
            "z": 0,
            "elements": [
                "minecraft:barrier@0"
            ]
        },
        {
            "x": 4,
            "y": 6,
            "z": 2,
            "elements": [
                "extendedcrafting:storage@2"
            ]
        },
        {
            "x": 3,
            "y": 4,
            "z": 1,
            "elements": [
                "gct_ores:fire_alloy@0"
            ]
        },
        {
            "x": 2,
            "y": 2,
            "z": 0,
            "elements": [
                "minecraft:barrier@0"
            ]
        },
        {
            "x": 4,
            "y": 4,
            "z": 1,
            "elements": [
                "minecraft:barrier@0"
            ]
        },
        {
            "x": 3,
            "y": 2,
            "z": 0,
            "elements": [
                "minecraft:barrier@0"
            ]
        },
        {
            "x": 4,
            "y": 2,
            "z": 0,
            "elements": [
                "additions:greedycraft-fusion_matrix_block@0"
            ]
        },
        {
            "x": -5,
            "y": 7,
            "z": 2,
            "elements": [
                "gct_ores:ruled_draconium_block@0"
            ]
        },
        {
            "x": -5,
            "y": 5,
            "z": 1,
            "elements": [
                "minecraft:barrier@0"
            ]
        },
        {
            "x": -5,
            "y": 3,
            "z": 0,
            "elements": [
                "additions:greedycraft-fusion_matrix_block@0"
            ]
        },
        {
            "x": -4,
            "y": 5,
            "z": 1,
            "elements": [
                "gct_ores:fire_alloy@0"
            ]
        },
        {
            "x": -4,
            "y": 3,
            "z": 0,
            "elements": [
                "minecraft:barrier@0"
            ]
        },
        {
            "x": -3,
            "y": 5,
            "z": 1,
            "elements": [
                "gct_ores:fire_alloy@0"
            ]
        },
        {
            "x": -3,
            "y": 3,
            "z": 0,
            "elements": [
                "minecraft:barrier@0"
            ]
        },
        {
            "x": -2,
            "y": 5,
            "z": 1,
            "elements": [
                "gct_ores:fire_alloy@0"
            ]
        },
        {
            "x": -2,
            "y": 3,
            "z": 0,
            "elements": [
                "minecraft:barrier@0"
            ]
        },
        {
            "x": -1,
            "y": 5,
            "z": 1,
            "elements": [
                "gct_ores:fire_alloy@0"
            ]
        },
        {
            "x": 0,
            "y": 5,
            "z": 1,
            "elements": [
                "gct_ores:fire_alloy@0"
            ]
        },
        {
            "x": -1,
            "y": 3,
            "z": 0,
            "elements": [
                "minecraft:barrier@0"
            ]
        },
        {
            "x": 1,
            "y": 5,
            "z": 1,
            "elements": [
                "gct_ores:fire_alloy@0"
            ]
        },
        {
            "x": 0,
            "y": 3,
            "z": 0,
            "elements": [
                "minecraft:barrier@0"
            ]
        },
        {
            "x": 2,
            "y": 5,
            "z": 1,
            "elements": [
                "gct_ores:fire_alloy@0"
            ]
        },
        {
            "x": 1,
            "y": 3,
            "z": 0,
            "elements": [
                "minecraft:barrier@0"
            ]
        },
        {
            "x": 4,
            "y": 7,
            "z": 2,
            "elements": [
                "gct_ores:ruled_draconium_block@0"
            ]
        },
        {
            "x": 3,
            "y": 5,
            "z": 1,
            "elements": [
                "gct_ores:fire_alloy@0"
            ]
        },
        {
            "x": 2,
            "y": 3,
            "z": 0,
            "elements": [
                "minecraft:barrier@0"
            ]
        },
        {
            "x": 4,
            "y": 5,
            "z": 1,
            "elements": [
                "minecraft:barrier@0"
            ]
        },
        {
            "x": 3,
            "y": 3,
            "z": 0,
            "elements": [
                "minecraft:barrier@0"
            ]
        },
        {
            "x": 4,
            "y": 3,
            "z": 0,
            "elements": [
                "additions:greedycraft-fusion_matrix_block@0"
            ]
        },
        {
            "x": -5,
            "y": 6,
            "z": 1,
            "elements": [
                "extendedcrafting:storage@2"
            ]
        },
        {
            "x": -4,
            "y": 8,
            "z": 2,
            "elements": [
                "mekanism:basicblock@2"
            ]
        },
        {
            "x": -5,
            "y": 4,
            "z": 0,
            "elements": [
                "extendedcrafting:storage@2"
            ]
        },
        {
            "x": -4,
            "y": 6,
            "z": 1,
            "elements": [
                "gct_ores:fire_alloy@0"
            ]
        },
        {
            "x": -3,
            "y": 8,
            "z": 2,
            "elements": [
                "thermalfoundation:glass@8"
            ]
        },
        {
            "x": -4,
            "y": 4,
            "z": 0,
            "elements": [
                "minecraft:barrier@0"
            ]
        },
        {
            "x": -3,
            "y": 6,
            "z": 1,
            "elements": [
                "gct_ores:fire_alloy@0"
            ]
        },
        {
            "x": -2,
            "y": 8,
            "z": 2,
            "elements": [
                "thermalfoundation:glass@8"
            ]
        },
        {
            "x": -3,
            "y": 4,
            "z": 0,
            "elements": [
                "minecraft:barrier@0"
            ]
        },
        {
            "x": -2,
            "y": 6,
            "z": 1,
            "elements": [
                "gct_ores:fire_alloy@0"
            ]
        },
        {
            "x": -1,
            "y": 8,
            "z": 2,
            "elements": [
                "thermalfoundation:glass@8"
            ]
        },
        {
            "x": 0,
            "y": 8,
            "z": 2,
            "elements": [
                "thermalfoundation:glass@8"
            ]
        },
        {
            "x": -2,
            "y": 4,
            "z": 0,
            "elements": [
                "minecraft:barrier@0"
            ]
        },
        {
            "x": -1,
            "y": 6,
            "z": 1,
            "elements": [
                "gct_ores:fire_alloy@0"
            ]
        },
        {
            "x": 1,
            "y": 8,
            "z": 2,
            "elements": [
                "thermalfoundation:glass@8"
            ]
        },
        {
            "x": 0,
            "y": 6,
            "z": 1,
            "elements": [
                "gct_ores:fire_alloy@0"
            ]
        },
        {
            "x": -1,
            "y": 4,
            "z": 0,
            "elements": [
                "minecraft:barrier@0"
            ]
        },
        {
            "x": 2,
            "y": 8,
            "z": 2,
            "elements": [
                "thermalfoundation:glass@8"
            ]
        },
        {
            "x": 1,
            "y": 6,
            "z": 1,
            "elements": [
                "gct_ores:fire_alloy@0"
            ]
        },
        {
            "x": 0,
            "y": 4,
            "z": 0,
            "elements": [
                "minecraft:barrier@0"
            ]
        },
        {
            "x": 3,
            "y": 8,
            "z": 2,
            "elements": [
                "mekanism:basicblock@2"
            ]
        },
        {
            "x": 2,
            "y": 6,
            "z": 1,
            "elements": [
                "gct_ores:fire_alloy@0"
            ]
        },
        {
            "x": 1,
            "y": 4,
            "z": 0,
            "elements": [
                "minecraft:barrier@0"
            ]
        },
        {
            "x": 3,
            "y": 6,
            "z": 1,
            "elements": [
                "gct_ores:fire_alloy@0"
            ]
        },
        {
            "x": 2,
            "y": 4,
            "z": 0,
            "elements": [
                "minecraft:barrier@0"
            ]
        },
        {
            "x": 4,
            "y": 6,
            "z": 1,
            "elements": [
                "extendedcrafting:storage@2"
            ]
        },
        {
            "x": 3,
            "y": 4,
            "z": 0,
            "elements": [
                "minecraft:barrier@0"
            ]
        },
        {
            "x": 4,
            "y": 4,
            "z": 0,
            "elements": [
                "extendedcrafting:storage@2"
            ]
        },
        {
            "x": -5,
            "y": 7,
            "z": 1,
            "elements": [
                "gct_ores:ruled_draconium_block@0"
            ]
        },
        {
            "x": -5,
            "y": 5,
            "z": 0,
            "elements": [
                "extendedcrafting:storage@2"
            ]
        },
        {
            "x": -4,
            "y": 5,
            "z": 0,
            "elements": [
                "minecraft:barrier@0"
            ]
        },
        {
            "x": -3,
            "y": 5,
            "z": 0,
            "elements": [
                "minecraft:barrier@0"
            ]
        },
        {
            "x": -2,
            "y": 5,
            "z": 0,
            "elements": [
                "minecraft:barrier@0"
            ]
        },
        {
            "x": -1,
            "y": 5,
            "z": 0,
            "elements": [
                "minecraft:barrier@0"
            ]
        },
        {
            "x": 0,
            "y": 5,
            "z": 0,
            "elements": [
                "minecraft:barrier@0"
            ]
        },
        {
            "x": 1,
            "y": 5,
            "z": 0,
            "elements": [
                "minecraft:barrier@0"
            ]
        },
        {
            "x": 2,
            "y": 5,
            "z": 0,
            "elements": [
                "minecraft:barrier@0"
            ]
        },
        {
            "x": 4,
            "y": 7,
            "z": 1,
            "elements": [
                "gct_ores:ruled_draconium_block@0"
            ]
        },
        {
            "x": 3,
            "y": 5,
            "z": 0,
            "elements": [
                "minecraft:barrier@0"
            ]
        },
        {
            "x": 4,
            "y": 5,
            "z": 0,
            "elements": [
                "extendedcrafting:storage@2"
            ]
        },
        {
            "x": -5,
            "y": 6,
            "z": 0,
            "elements": [
                "extendedcrafting:storage@2"
            ]
        },
        {
            "x": -4,
            "y": 8,
            "z": 1,
            "elements": [
                "additions:greedycraft-cosmilite_block@0"
            ]
        },
        {
            "x": -4,
            "y": 6,
            "z": 0,
            "elements": [
                "minecraft:barrier@0"
            ]
        },
        {
            "x": -3,
            "y": 8,
            "z": 1,
            "elements": [
                "mekanism:basicblock@2"
            ]
        },
        {
            "x": -3,
            "y": 6,
            "z": 0,
            "elements": [
                "minecraft:barrier@0"
            ]
        },
        {
            "x": -2,
            "y": 8,
            "z": 1,
            "elements": [
                "mekanism:basicblock@2"
            ]
        },
        {
            "x": -2,
            "y": 6,
            "z": 0,
            "elements": [
                "minecraft:barrier@0"
            ]
        },
        {
            "x": -1,
            "y": 8,
            "z": 1,
            "elements": [
                "thaumadditions:mithminite_block@0"
            ]
        },
        {
            "x": 0,
            "y": 8,
            "z": 1,
            "elements": [
                "thaumadditions:mithminite_block@0"
            ]
        },
        {
            "x": -1,
            "y": 6,
            "z": 0,
            "elements": [
                "minecraft:barrier@0"
            ]
        },
        {
            "x": 1,
            "y": 8,
            "z": 1,
            "elements": [
                "mekanism:basicblock@2"
            ]
        },
        {
            "x": 0,
            "y": 6,
            "z": 0,
            "elements": [
                "minecraft:barrier@0"
            ]
        },
        {
            "x": 2,
            "y": 8,
            "z": 1,
            "elements": [
                "mekanism:basicblock@2"
            ]
        },
        {
            "x": 1,
            "y": 6,
            "z": 0,
            "elements": [
                "minecraft:barrier@0"
            ]
        },
        {
            "x": 3,
            "y": 8,
            "z": 1,
            "elements": [
                "additions:greedycraft-cosmilite_block@0"
            ]
        },
        {
            "x": 2,
            "y": 6,
            "z": 0,
            "elements": [
                "minecraft:barrier@0"
            ]
        },
        {
            "x": 3,
            "y": 6,
            "z": 0,
            "elements": [
                "minecraft:barrier@0"
            ]
        },
        {
            "x": 4,
            "y": 6,
            "z": 0,
            "elements": [
                "extendedcrafting:storage@2"
            ]
        },
        {
            "x": -5,
            "y": 7,
            "z": 0,
            "elements": [
                "additions:greedycraft-cosmilite_block@0"
            ]
        },
        {
            "x": -4,
            "y": 7,
            "z": 0,
            "elements": [
                "extrabotany:blockorichalcos@0"
            ]
        },
        {
            "x": -3,
            "y": 7,
            "z": 0,
            "elements": [
                "gct_ores:equipment_witherium_block@0"
            ]
        },
        {
            "x": -2,
            "y": 7,
            "z": 0,
            "elements": [
                "gct_ores:equipment_witherium_block@0"
            ]
        },
        {
            "x": -1,
            "y": 7,
            "z": 0,
            "elements": [
                "draconicevolution:infused_obsidian@0"
            ]
        },
        {
            "x": 0,
            "y": 7,
            "z": 0,
            "elements": [
                "draconicevolution:infused_obsidian@0"
            ]
        },
        {
            "x": 1,
            "y": 7,
            "z": 0,
            "elements": [
                "gct_ores:equipment_witherium_block@0"
            ]
        },
        {
            "x": 2,
            "y": 7,
            "z": 0,
            "elements": [
                "gct_ores:equipment_witherium_block@0"
            ]
        },
        {
            "x": 3,
            "y": 7,
            "z": 0,
            "elements": [
                "extrabotany:blockorichalcos@0"
            ]
        },
        {
            "x": 4,
            "y": 7,
            "z": 0,
            "elements": [
                "additions:greedycraft-cosmilite_block@0"
            ]
        },
        {
            "x": -5,
            "y": 0,
            "z": 6,
            "elements": [
                "additions:greedycraft-cosmilite_block@0"
            ]
        },
        {
            "x": -4,
            "y": 0,
            "z": 6,
            "nbt": {"casingColor":"16730368","ForgeCaps":{"abyssalcraft:itemtransfer":{"isRunning":"0b","configurations":[]}},"id":"minecraft:tilecolorablemachinecomponent"},
            "elements": [
                "modularmachinery:blockcasing@4"
            ]
        },
        {
            "x": -3,
            "y": 0,
            "z": 6,
            "nbt": {"casingColor":"16730368","ForgeCaps":{"abyssalcraft:itemtransfer":{"isRunning":"0b","configurations":[]}},"id":"minecraft:tilecolorablemachinecomponent"},
            "elements": [
                "modularmachinery:blockcasing@4"
            ]
        },
        {
            "x": -2,
            "y": 0,
            "z": 6,
            "nbt": {"casingColor":"16730368","ForgeCaps":{"abyssalcraft:itemtransfer":{"isRunning":"0b","configurations":[]}},"id":"minecraft:tilecolorablemachinecomponent"},
            "elements": [
                "modularmachinery:blockcasing@4"
            ]
        },
        {
            "x": -1,
            "y": 0,
            "z": 6,
            "nbt": {"casingColor":"16730368","ForgeCaps":{"abyssalcraft:itemtransfer":{"isRunning":"0b","configurations":[]}},"id":"minecraft:tilecolorablemachinecomponent"},
            "elements": [
                "modularmachinery:blockcasing@4"
            ]
        },
        {
            "x": 0,
            "y": 0,
            "z": 6,
            "nbt": {"casingColor":"16730368","ForgeCaps":{"abyssalcraft:itemtransfer":{"isRunning":"0b","configurations":[]}},"id":"minecraft:tilecolorablemachinecomponent"},
            "elements": [
                "modularmachinery:blockcasing@4"
            ]
        },
        {
            "x": 1,
            "y": 0,
            "z": 6,
            "nbt": {"casingColor":"16730368","ForgeCaps":{"abyssalcraft:itemtransfer":{"isRunning":"0b","configurations":[]}},"id":"minecraft:tilecolorablemachinecomponent"},
            "elements": [
                "modularmachinery:blockcasing@4"
            ]
        },
        {
            "x": 2,
            "y": 0,
            "z": 6,
            "nbt": {"casingColor":"16730368","ForgeCaps":{"abyssalcraft:itemtransfer":{"isRunning":"0b","configurations":[]}},"id":"minecraft:tilecolorablemachinecomponent"},
            "elements": [
                "modularmachinery:blockcasing@4"
            ]
        },
        {
            "x": 3,
            "y": 0,
            "z": 6,
            "nbt": {"casingColor":"16730368","ForgeCaps":{"abyssalcraft:itemtransfer":{"isRunning":"0b","configurations":[]}},"id":"minecraft:tilecolorablemachinecomponent"},
            "elements": [
                "modularmachinery:blockcasing@4"
            ]
        },
        {
            "x": 4,
            "y": 0,
            "z": 6,
            "elements": [
                "additions:greedycraft-cosmilite_block@0"
            ]
        },
        {
            "x": -5,
            "y": 1,
            "z": 6,
            "elements": [
                "additions:greedycraft-fusion_matrix_block@0"
            ]
        },
        {
            "x": -4,
            "y": 1,
            "z": 6,
            "elements": [
                "minecraft:barrier@0"
            ]
        },
        {
            "x": -3,
            "y": 1,
            "z": 6,
            "elements": [
                "minecraft:barrier@0"
            ]
        },
        {
            "x": -2,
            "y": 1,
            "z": 6,
            "elements": [
                "minecraft:barrier@0"
            ]
        },
        {
            "x": -1,
            "y": 1,
            "z": 6,
            "elements": [
                "minecraft:barrier@0"
            ]
        },
        {
            "x": 0,
            "y": 1,
            "z": 6,
            "elements": [
                "minecraft:barrier@0"
            ]
        },
        {
            "x": 1,
            "y": 1,
            "z": 6,
            "elements": [
                "minecraft:barrier@0"
            ]
        },
        {
            "x": 2,
            "y": 1,
            "z": 6,
            "elements": [
                "minecraft:barrier@0"
            ]
        },
        {
            "x": 3,
            "y": 1,
            "z": 6,
            "elements": [
                "minecraft:barrier@0"
            ]
        },
        {
            "x": 4,
            "y": 1,
            "z": 6,
            "elements": [
                "additions:greedycraft-fusion_matrix_block@0"
            ]
        },
        {
            "x": -5,
            "y": 2,
            "z": 6,
            "elements": [
                "additions:greedycraft-fusion_matrix_block@0"
            ]
        },
        {
            "x": -5,
            "y": 0,
            "z": 5,
            "nbt": {"casingColor":"16730368","ForgeCaps":{"abyssalcraft:itemtransfer":{"isRunning":"0b","configurations":[]}},"id":"minecraft:tilecolorablemachinecomponent"},
            "elements": [
                "modularmachinery:blockcasing@4"
            ]
        },
        {
            "x": -4,
            "y": 2,
            "z": 6,
            "elements": [
                "minecraft:barrier@0"
            ]
        },
        {
            "x": -4,
            "y": 0,
            "z": 5,
            "nbt": {"casingColor":"16730368","ForgeCaps":{"abyssalcraft:itemtransfer":{"isRunning":"0b","configurations":[]}},"id":"minecraft:tilecolorablemachinecomponent"},
            "elements": [
                "modularmachinery:blockcasing@4"
            ]
        },
        {
            "x": -3,
            "y": 2,
            "z": 6,
            "elements": [
                "minecraft:barrier@0"
            ]
        },
        {
            "x": -3,
            "y": 0,
            "z": 5,
            "nbt": {"casingColor":"16730368","ForgeCaps":{"abyssalcraft:itemtransfer":{"isRunning":"0b","configurations":[]}},"id":"minecraft:tilecolorablemachinecomponent"},
            "elements": [
                "modularmachinery:blockcasing@4"
            ]
        },
        {
            "x": -2,
            "y": 2,
            "z": 6,
            "elements": [
                "minecraft:barrier@0"
            ]
        },
        {
            "x": -2,
            "y": 0,
            "z": 5,
            "nbt": {"casingColor":"16730368","ForgeCaps":{"abyssalcraft:itemtransfer":{"isRunning":"0b","configurations":[]}},"id":"minecraft:tilecolorablemachinecomponent"},
            "elements": [
                "modularmachinery:blockcasing@4"
            ]
        },
        {
            "x": -1,
            "y": 2,
            "z": 6,
            "elements": [
                "minecraft:barrier@0"
            ]
        },
        {
            "x": 0,
            "y": 2,
            "z": 6,
            "elements": [
                "minecraft:barrier@0"
            ]
        },
        {
            "x": -1,
            "y": 0,
            "z": 5,
            "nbt": {"casingColor":"16730368","ForgeCaps":{"abyssalcraft:itemtransfer":{"isRunning":"0b","configurations":[]}},"id":"minecraft:tilecolorablemachinecomponent"},
            "elements": [
                "modularmachinery:blockcasing@4"
            ]
        },
        {
            "x": 0,
            "y": 0,
            "z": 5,
            "nbt": {"casingColor":"16730368","ForgeCaps":{"abyssalcraft:itemtransfer":{"isRunning":"0b","configurations":[]}},"id":"minecraft:tilecolorablemachinecomponent"},
            "elements": [
                "modularmachinery:blockcasing@4"
            ]
        },
        {
            "x": 1,
            "y": 2,
            "z": 6,
            "elements": [
                "minecraft:barrier@0"
            ]
        },
        {
            "x": 2,
            "y": 2,
            "z": 6,
            "elements": [
                "minecraft:barrier@0"
            ]
        },
        {
            "x": 1,
            "y": 0,
            "z": 5,
            "nbt": {"casingColor":"16730368","ForgeCaps":{"abyssalcraft:itemtransfer":{"isRunning":"0b","configurations":[]}},"id":"minecraft:tilecolorablemachinecomponent"},
            "elements": [
                "modularmachinery:blockcasing@4"
            ]
        },
        {
            "x": 3,
            "y": 2,
            "z": 6,
            "elements": [
                "minecraft:barrier@0"
            ]
        },
        {
            "x": 2,
            "y": 0,
            "z": 5,
            "nbt": {"casingColor":"16730368","ForgeCaps":{"abyssalcraft:itemtransfer":{"isRunning":"0b","configurations":[]}},"id":"minecraft:tilecolorablemachinecomponent"},
            "elements": [
                "modularmachinery:blockcasing@4"
            ]
        },
        {
            "x": 4,
            "y": 2,
            "z": 6,
            "elements": [
                "additions:greedycraft-fusion_matrix_block@0"
            ]
        },
        {
            "x": 3,
            "y": 0,
            "z": 5,
            "nbt": {"casingColor":"16730368","ForgeCaps":{"abyssalcraft:itemtransfer":{"isRunning":"0b","configurations":[]}},"id":"minecraft:tilecolorablemachinecomponent"},
            "elements": [
                "modularmachinery:blockcasing@4"
            ]
        },
        {
            "x": 4,
            "y": 0,
            "z": 5,
            "nbt": {"casingColor":"16730368","ForgeCaps":{"abyssalcraft:itemtransfer":{"isRunning":"0b","configurations":[]}},"id":"minecraft:tilecolorablemachinecomponent"},
            "elements": [
                "modularmachinery:blockcasing@4"
            ]
        },
        {
            "x": -5,
            "y": 3,
            "z": 6,
            "elements": [
                "additions:greedycraft-fusion_matrix_block@0"
            ]
        },
        {
            "x": -5,
            "y": 1,
            "z": 5,
            "elements": [
                "additions:greedycraft-fusion_matrix_block@0"
            ]
        },
        {
            "x": -4,
            "y": 3,
            "z": 6,
            "elements": [
                "minecraft:barrier@0"
            ]
        },
        {
            "x": -4,
            "y": 1,
            "z": 5,
            "elements": [
                "gct_ores:fire_alloy@0"
            ]
        },
        {
            "x": -3,
            "y": 3,
            "z": 6,
            "elements": [
                "minecraft:barrier@0"
            ]
        },
        {
            "x": -3,
            "y": 1,
            "z": 5,
            "elements": [
                "gct_ores:fire_alloy@0"
            ]
        },
        {
            "x": -2,
            "y": 3,
            "z": 6,
            "elements": [
                "minecraft:barrier@0"
            ]
        },
        {
            "x": -2,
            "y": 1,
            "z": 5,
            "elements": [
                "gct_ores:fire_alloy@0"
            ]
        },
        {
            "x": -1,
            "y": 3,
            "z": 6,
            "elements": [
                "minecraft:barrier@0"
            ]
        },
        {
            "x": 0,
            "y": 3,
            "z": 6,
            "elements": [
                "minecraft:barrier@0"
            ]
        },
        {
            "x": -1,
            "y": 1,
            "z": 5,
            "elements": [
                "gct_ores:fire_alloy@0"
            ]
        },
        {
            "x": 1,
            "y": 3,
            "z": 6,
            "elements": [
                "minecraft:barrier@0"
            ]
        },
        {
            "x": 0,
            "y": 1,
            "z": 5,
            "elements": [
                "gct_ores:fire_alloy@0"
            ]
        },
        {
            "x": 2,
            "y": 3,
            "z": 6,
            "elements": [
                "minecraft:barrier@0"
            ]
        },
        {
            "x": 1,
            "y": 1,
            "z": 5,
            "elements": [
                "gct_ores:fire_alloy@0"
            ]
        },
        {
            "x": 3,
            "y": 3,
            "z": 6,
            "elements": [
                "minecraft:barrier@0"
            ]
        },
        {
            "x": 2,
            "y": 1,
            "z": 5,
            "elements": [
                "gct_ores:fire_alloy@0"
            ]
        },
        {
            "x": 4,
            "y": 3,
            "z": 6,
            "elements": [
                "additions:greedycraft-fusion_matrix_block@0"
            ]
        },
        {
            "x": 3,
            "y": 1,
            "z": 5,
            "elements": [
                "gct_ores:fire_alloy@0"
            ]
        },
        {
            "x": 4,
            "y": 1,
            "z": 5,
            "elements": [
                "additions:greedycraft-fusion_matrix_block@0"
            ]
        },
        {
            "x": -5,
            "y": 4,
            "z": 6,
            "elements": [
                "extendedcrafting:storage@2"
            ]
        },
        {
            "x": -5,
            "y": 2,
            "z": 5,
            "elements": [
                "minecraft:barrier@0"
            ]
        },
        {
            "x": -4,
            "y": 4,
            "z": 6,
            "elements": [
                "minecraft:barrier@0"
            ]
        },
        {
            "x": -5,
            "y": 0,
            "z": 4,
            "nbt": {"casingColor":"16730368","ForgeCaps":{"abyssalcraft:itemtransfer":{"isRunning":"0b","configurations":[]}},"id":"minecraft:tilecolorablemachinecomponent"},
            "elements": [
                "modularmachinery:blockcasing@4"
            ]
        },
        {
            "x": -4,
            "y": 2,
            "z": 5,
            "elements": [
                "gct_ores:fire_alloy@0"
            ]
        },
        {
            "x": -3,
            "y": 4,
            "z": 6,
            "elements": [
                "minecraft:barrier@0"
            ]
        },
        {
            "x": -4,
            "y": 0,
            "z": 4,
            "nbt": {"casingColor":"16730368","ForgeCaps":{"abyssalcraft:itemtransfer":{"isRunning":"0b","configurations":[]}},"id":"minecraft:tilecolorablemachinecomponent"},
            "elements": [
                "modularmachinery:blockcasing@4"
            ]
        },
        {
            "x": -3,
            "y": 2,
            "z": 5,
            "elements": [
                "gct_ores:fire_alloy@0"
            ]
        },
        {
            "x": -2,
            "y": 4,
            "z": 6,
            "elements": [
                "minecraft:barrier@0"
            ]
        },
        {
            "x": -3,
            "y": 0,
            "z": 4,
            "nbt": {"casingColor":"16730368","ForgeCaps":{"abyssalcraft:itemtransfer":{"isRunning":"0b","configurations":[]}},"id":"minecraft:tilecolorablemachinecomponent"},
            "elements": [
                "modularmachinery:blockcasing@4"
            ]
        },
        {
            "x": -2,
            "y": 2,
            "z": 5,
            "elements": [
                "gct_ores:fire_alloy@0"
            ]
        },
        {
            "x": -1,
            "y": 4,
            "z": 6,
            "elements": [
                "minecraft:barrier@0"
            ]
        },
        {
            "x": 0,
            "y": 4,
            "z": 6,
            "elements": [
                "minecraft:barrier@0"
            ]
        },
        {
            "x": -2,
            "y": 0,
            "z": 4,
            "nbt": {"casingColor":"16730368","ForgeCaps":{"abyssalcraft:itemtransfer":{"isRunning":"0b","configurations":[]}},"id":"minecraft:tilecolorablemachinecomponent"},
            "elements": [
                "modularmachinery:blockcasing@4"
            ]
        },
        {
            "x": -1,
            "y": 2,
            "z": 5,
            "elements": [
                "gct_ores:fire_alloy@0"
            ]
        },
        {
            "x": 1,
            "y": 4,
            "z": 6,
            "elements": [
                "minecraft:barrier@0"
            ]
        },
        {
            "x": 0,
            "y": 2,
            "z": 5,
            "elements": [
                "gct_ores:fire_alloy@0"
            ]
        },
        {
            "x": -1,
            "y": 0,
            "z": 4,
            "nbt": {"casingColor":"16730368","ForgeCaps":{"abyssalcraft:itemtransfer":{"isRunning":"0b","configurations":[]}},"id":"minecraft:tilecolorablemachinecomponent"},
            "elements": [
                "modularmachinery:blockcasing@4"
            ]
        },
        {
            "x": 0,
            "y": 0,
            "z": 4,
            "nbt": {"casingColor":"16730368","ForgeCaps":{"abyssalcraft:itemtransfer":{"isRunning":"0b","configurations":[]}},"id":"minecraft:tilecolorablemachinecomponent"},
            "elements": [
                "modularmachinery:blockcasing@4"
            ]
        },
        {
            "x": 2,
            "y": 4,
            "z": 6,
            "elements": [
                "minecraft:barrier@0"
            ]
        },
        {
            "x": 1,
            "y": 2,
            "z": 5,
            "elements": [
                "gct_ores:fire_alloy@0"
            ]
        },
        {
            "x": 3,
            "y": 4,
            "z": 6,
            "elements": [
                "minecraft:barrier@0"
            ]
        },
        {
            "x": 2,
            "y": 2,
            "z": 5,
            "elements": [
                "gct_ores:fire_alloy@0"
            ]
        },
        {
            "x": 1,
            "y": 0,
            "z": 4,
            "nbt": {"casingColor":"16730368","ForgeCaps":{"abyssalcraft:itemtransfer":{"isRunning":"0b","configurations":[]}},"id":"minecraft:tilecolorablemachinecomponent"},
            "elements": [
                "modularmachinery:blockcasing@4"
            ]
        },
        {
            "x": 4,
            "y": 4,
            "z": 6,
            "elements": [
                "extendedcrafting:storage@2"
            ]
        },
        {
            "x": 3,
            "y": 2,
            "z": 5,
            "elements": [
                "gct_ores:fire_alloy@0"
            ]
        },
        {
            "x": 2,
            "y": 0,
            "z": 4,
            "nbt": {"casingColor":"16730368","ForgeCaps":{"abyssalcraft:itemtransfer":{"isRunning":"0b","configurations":[]}},"id":"minecraft:tilecolorablemachinecomponent"},
            "elements": [
                "modularmachinery:blockcasing@4"
            ]
        },
        {
            "x": 4,
            "y": 2,
            "z": 5,
            "elements": [
                "minecraft:barrier@0"
            ]
        },
        {
            "x": 3,
            "y": 0,
            "z": 4,
            "nbt": {"casingColor":"16730368","ForgeCaps":{"abyssalcraft:itemtransfer":{"isRunning":"0b","configurations":[]}},"id":"minecraft:tilecolorablemachinecomponent"},
            "elements": [
                "modularmachinery:blockcasing@4"
            ]
        },
        {
            "x": 4,
            "y": 0,
            "z": 4,
            "nbt": {"casingColor":"16730368","ForgeCaps":{"abyssalcraft:itemtransfer":{"isRunning":"0b","configurations":[]}},"id":"minecraft:tilecolorablemachinecomponent"},
            "elements": [
                "modularmachinery:blockcasing@4"
            ]
        },
        {
            "x": -5,
            "y": 5,
            "z": 6,
            "elements": [
                "extendedcrafting:storage@2"
            ]
        },
        {
            "x": -5,
            "y": 3,
            "z": 5,
            "elements": [
                "minecraft:barrier@0"
            ]
        },
        {
            "x": -4,
            "y": 5,
            "z": 6,
            "elements": [
                "minecraft:barrier@0"
            ]
        },
        {
            "x": -5,
            "y": 1,
            "z": 4,
            "elements": [
                "additions:greedycraft-fusion_matrix_block@0"
            ]
        },
        {
            "x": -4,
            "y": 3,
            "z": 5,
            "elements": [
                "gct_ores:fire_alloy@0"
            ]
        },
        {
            "x": -3,
            "y": 5,
            "z": 6,
            "elements": [
                "minecraft:barrier@0"
            ]
        },
        {
            "x": -4,
            "y": 1,
            "z": 4,
            "elements": [
                "gct_ores:fire_alloy@0"
            ]
        },
        {
            "x": -3,
            "y": 3,
            "z": 5,
            "elements": [
                "gct_ores:fire_alloy@0"
            ]
        },
        {
            "x": -2,
            "y": 5,
            "z": 6,
            "elements": [
                "minecraft:barrier@0"
            ]
        },
        {
            "x": -3,
            "y": 1,
            "z": 4,
            "elements": [
                "gct_ores:everite_block@0"
            ]
        },
        {
            "x": -2,
            "y": 3,
            "z": 5,
            "elements": [
                "gct_ores:fire_alloy@0"
            ]
        },
        {
            "x": -1,
            "y": 5,
            "z": 6,
            "elements": [
                "minecraft:barrier@0"
            ]
        },
        {
            "x": 0,
            "y": 5,
            "z": 6,
            "elements": [
                "minecraft:barrier@0"
            ]
        },
        {
            "x": -2,
            "y": 1,
            "z": 4,
            "elements": [
                "gct_ores:everite_block@0"
            ]
        },
        {
            "x": -1,
            "y": 3,
            "z": 5,
            "elements": [
                "gct_ores:fire_alloy@0"
            ]
        },
        {
            "x": 1,
            "y": 5,
            "z": 6,
            "elements": [
                "minecraft:barrier@0"
            ]
        },
        {
            "x": 0,
            "y": 3,
            "z": 5,
            "elements": [
                "gct_ores:fire_alloy@0"
            ]
        },
        {
            "x": -1,
            "y": 1,
            "z": 4,
            "elements": [
                "gct_ores:everite_block@0"
            ]
        },
        {
            "x": 2,
            "y": 5,
            "z": 6,
            "elements": [
                "minecraft:barrier@0"
            ]
        },
        {
            "x": 1,
            "y": 3,
            "z": 5,
            "elements": [
                "gct_ores:fire_alloy@0"
            ]
        },
        {
            "x": 0,
            "y": 1,
            "z": 4,
            "elements": [
                "gct_ores:everite_block@0"
            ]
        },
        {
            "x": 3,
            "y": 5,
            "z": 6,
            "elements": [
                "minecraft:barrier@0"
            ]
        },
        {
            "x": 2,
            "y": 3,
            "z": 5,
            "elements": [
                "gct_ores:fire_alloy@0"
            ]
        },
        {
            "x": 1,
            "y": 1,
            "z": 4,
            "elements": [
                "gct_ores:everite_block@0"
            ]
        },
        {
            "x": 4,
            "y": 5,
            "z": 6,
            "elements": [
                "extendedcrafting:storage@2"
            ]
        },
        {
            "x": 3,
            "y": 3,
            "z": 5,
            "elements": [
                "gct_ores:fire_alloy@0"
            ]
        },
        {
            "x": 2,
            "y": 1,
            "z": 4,
            "elements": [
                "gct_ores:everite_block@0"
            ]
        },
        {
            "x": 4,
            "y": 3,
            "z": 5,
            "elements": [
                "minecraft:barrier@0"
            ]
        },
        {
            "x": 3,
            "y": 1,
            "z": 4,
            "elements": [
                "gct_ores:fire_alloy@0"
            ]
        },
        {
            "x": 4,
            "y": 1,
            "z": 4,
            "elements": [
                "additions:greedycraft-fusion_matrix_block@0"
            ]
        },
        {
            "x": -5,
            "y": 6,
            "z": 6,
            "elements": [
                "extendedcrafting:storage@2"
            ]
        },
        {
            "x": -5,
            "y": 4,
            "z": 5,
            "elements": [
                "minecraft:barrier@0"
            ]
        },
        {
            "x": -4,
            "y": 6,
            "z": 6,
            "elements": [
                "minecraft:barrier@0"
            ]
        },
        {
            "x": -5,
            "y": 2,
            "z": 4,
            "elements": [
                "minecraft:barrier@0"
            ]
        },
        {
            "x": -4,
            "y": 4,
            "z": 5,
            "elements": [
                "gct_ores:fire_alloy@0"
            ]
        },
        {
            "x": -3,
            "y": 6,
            "z": 6,
            "elements": [
                "minecraft:barrier@0"
            ]
        },
        {
            "x": -5,
            "y": 0,
            "z": 3,
            "nbt": {"casingColor":"16730368","ForgeCaps":{"abyssalcraft:itemtransfer":{"isRunning":"0b","configurations":[]}},"id":"minecraft:tilecolorablemachinecomponent"},
            "elements": [
                "modularmachinery:blockcasing@4"
            ]
        },
        {
            "x": -4,
            "y": 2,
            "z": 4,
            "elements": [
                "gct_ores:fire_alloy@0"
            ]
        },
        {
            "x": -3,
            "y": 4,
            "z": 5,
            "elements": [
                "gct_ores:fire_alloy@0"
            ]
        },
        {
            "x": -2,
            "y": 6,
            "z": 6,
            "elements": [
                "minecraft:barrier@0"
            ]
        },
        {
            "x": -4,
            "y": 0,
            "z": 3,
            "nbt": {"casingColor":"16730368","ForgeCaps":{"abyssalcraft:itemtransfer":{"isRunning":"0b","configurations":[]}},"id":"minecraft:tilecolorablemachinecomponent"},
            "elements": [
                "modularmachinery:blockcasing@4"
            ]
        },
        {
            "x": -3,
            "y": 2,
            "z": 4,
            "nbt": {"casingColor":"16730368","ForgeCaps":{"abyssalcraft:itemtransfer":{"isRunning":"0b","configurations":[]}},"id":"minecraft:tilecolorablemachinecomponent"},
            "elements": [
                "modularmachinery:blockcasing@4"
            ]
        },
        {
            "x": -2,
            "y": 4,
            "z": 5,
            "elements": [
                "gct_ores:fire_alloy@0"
            ]
        },
        {
            "x": -1,
            "y": 6,
            "z": 6,
            "elements": [
                "minecraft:barrier@0"
            ]
        },
        {
            "x": 0,
            "y": 6,
            "z": 6,
            "elements": [
                "minecraft:barrier@0"
            ]
        },
        {
            "x": -3,
            "y": 0,
            "z": 3,
            "nbt": {"casingColor":"16730368","ForgeCaps":{"abyssalcraft:itemtransfer":{"isRunning":"0b","configurations":[]}},"id":"minecraft:tilecolorablemachinecomponent"},
            "elements": [
                "modularmachinery:blockcasing@4"
            ]
        },
        {
            "x": -2,
            "y": 2,
            "z": 4,
            "elements": [
                "gct_ores:balanced_matrix_block@0"
            ]
        },
        {
            "x": -1,
            "y": 4,
            "z": 5,
            "elements": [
                "gct_ores:fire_alloy@0"
            ]
        },
        {
            "x": 1,
            "y": 6,
            "z": 6,
            "elements": [
                "minecraft:barrier@0"
            ]
        },
        {
            "x": 0,
            "y": 4,
            "z": 5,
            "elements": [
                "gct_ores:fire_alloy@0"
            ]
        },
        {
            "x": -2,
            "y": 0,
            "z": 3,
            "nbt": {"casingColor":"16730368","ForgeCaps":{"abyssalcraft:itemtransfer":{"isRunning":"0b","configurations":[]}},"id":"minecraft:tilecolorablemachinecomponent"},
            "elements": [
                "modularmachinery:blockcasing@4"
            ]
        },
        {
            "x": -1,
            "y": 2,
            "z": 4,
            "nbt": {"casingColor":"16730368","ForgeCaps":{"abyssalcraft:itemtransfer":{"isRunning":"0b","configurations":[]}},"id":"minecraft:tilecolorablemachinecomponent"},
            "elements": [
                "modularmachinery:blockcasing@4"
            ]
        },
        {
            "x": 2,
            "y": 6,
            "z": 6,
            "elements": [
                "minecraft:barrier@0"
            ]
        },
        {
            "x": 1,
            "y": 4,
            "z": 5,
            "elements": [
                "gct_ores:fire_alloy@0"
            ]
        },
        {
            "x": 0,
            "y": 2,
            "z": 4,
            "nbt": {"casingColor":"16730368","ForgeCaps":{"abyssalcraft:itemtransfer":{"isRunning":"0b","configurations":[]}},"id":"minecraft:tilecolorablemachinecomponent"},
            "elements": [
                "modularmachinery:blockcasing@4"
            ]
        },
        {
            "x": -1,
            "y": 0,
            "z": 3,
            "nbt": {"casingColor":"16730368","ForgeCaps":{"abyssalcraft:itemtransfer":{"isRunning":"0b","configurations":[]}},"id":"minecraft:tilecolorablemachinecomponent"},
            "elements": [
                "modularmachinery:blockcasing@4"
            ]
        },
        {
            "x": 0,
            "y": 0,
            "z": 3,
            "nbt": {"casingColor":"16730368","ForgeCaps":{"abyssalcraft:itemtransfer":{"isRunning":"0b","configurations":[]}},"id":"minecraft:tilecolorablemachinecomponent"},
            "elements": [
                "modularmachinery:blockcasing@4"
            ]
        },
        {
            "x": 3,
            "y": 6,
            "z": 6,
            "elements": [
                "minecraft:barrier@0"
            ]
        },
        {
            "x": 2,
            "y": 4,
            "z": 5,
            "elements": [
                "gct_ores:fire_alloy@0"
            ]
        },
        {
            "x": 1,
            "y": 2,
            "z": 4,
            "elements": [
                "gct_ores:balanced_matrix_block@0"
            ]
        },
        {
            "x": 4,
            "y": 6,
            "z": 6,
            "elements": [
                "extendedcrafting:storage@2"
            ]
        },
        {
            "x": 3,
            "y": 4,
            "z": 5,
            "elements": [
                "gct_ores:fire_alloy@0"
            ]
        },
        {
            "x": 2,
            "y": 2,
            "z": 4,
            "nbt": {"casingColor":"16730368","ForgeCaps":{"abyssalcraft:itemtransfer":{"isRunning":"0b","configurations":[]}},"id":"minecraft:tilecolorablemachinecomponent"},
            "elements": [
                "modularmachinery:blockcasing@4"
            ]
        },
        {
            "x": 1,
            "y": 0,
            "z": 3,
            "nbt": {"casingColor":"16730368","ForgeCaps":{"abyssalcraft:itemtransfer":{"isRunning":"0b","configurations":[]}},"id":"minecraft:tilecolorablemachinecomponent"},
            "elements": [
                "modularmachinery:blockcasing@4"
            ]
        },
        {
            "x": 4,
            "y": 4,
            "z": 5,
            "elements": [
                "minecraft:barrier@0"
            ]
        },
        {
            "x": 3,
            "y": 2,
            "z": 4,
            "elements": [
                "gct_ores:fire_alloy@0"
            ]
        },
        {
            "x": 2,
            "y": 0,
            "z": 3,
            "nbt": {"casingColor":"16730368","ForgeCaps":{"abyssalcraft:itemtransfer":{"isRunning":"0b","configurations":[]}},"id":"minecraft:tilecolorablemachinecomponent"},
            "elements": [
                "modularmachinery:blockcasing@4"
            ]
        },
        {
            "x": 4,
            "y": 2,
            "z": 4,
            "elements": [
                "minecraft:barrier@0"
            ]
        },
        {
            "x": 3,
            "y": 0,
            "z": 3,
            "nbt": {"casingColor":"16730368","ForgeCaps":{"abyssalcraft:itemtransfer":{"isRunning":"0b","configurations":[]}},"id":"minecraft:tilecolorablemachinecomponent"},
            "elements": [
                "modularmachinery:blockcasing@4"
            ]
        },
        {
            "x": 4,
            "y": 0,
            "z": 3,
            "nbt": {"casingColor":"16730368","ForgeCaps":{"abyssalcraft:itemtransfer":{"isRunning":"0b","configurations":[]}},"id":"minecraft:tilecolorablemachinecomponent"},
            "elements": [
                "modularmachinery:blockcasing@4"
            ]
        },
        {
            "x": -5,
            "y": 7,
            "z": 6,
            "elements": [
                "additions:greedycraft-cosmilite_block@0"
            ]
        },
        {
            "x": -5,
            "y": 5,
            "z": 5,
            "elements": [
                "minecraft:barrier@0"
            ]
        },
        {
            "x": -4,
            "y": 7,
            "z": 6,
            "elements": [
                "extrabotany:blockorichalcos@0"
            ]
        },
        {
            "x": -5,
            "y": 3,
            "z": 4,
            "elements": [
                "additions:greedycraft-fusion_matrix_block@0"
            ]
        },
        {
            "x": -4,
            "y": 5,
            "z": 5,
            "elements": [
                "gct_ores:fire_alloy@0"
            ]
        },
        {
            "x": -3,
            "y": 7,
            "z": 6,
            "elements": [
                "gct_ores:equipment_witherium_block@0"
            ]
        },
        {
            "x": -5,
            "y": 1,
            "z": 3,
            "elements": [
                "additions:greedycraft-fusion_matrix_block@0"
            ]
        },
        {
            "x": -4,
            "y": 3,
            "z": 4,
            "elements": [
                "gct_ores:fire_alloy@0"
            ]
        },
        {
            "x": -3,
            "y": 5,
            "z": 5,
            "elements": [
                "gct_ores:fire_alloy@0"
            ]
        },
        {
            "x": -2,
            "y": 7,
            "z": 6,
            "elements": [
                "gct_ores:equipment_witherium_block@0"
            ]
        },
        {
            "x": -4,
            "y": 1,
            "z": 3,
            "elements": [
                "gct_ores:fire_alloy@0"
            ]
        },
        {
            "x": -3,
            "y": 3,
            "z": 4,
            "elements": [
                "gct_ores:everite_block@0"
            ]
        },
        {
            "x": -2,
            "y": 5,
            "z": 5,
            "elements": [
                "gct_ores:fire_alloy@0"
            ]
        },
        {
            "x": -1,
            "y": 7,
            "z": 6,
            "elements": [
                "draconicevolution:infused_obsidian@0"
            ]
        },
        {
            "x": 0,
            "y": 7,
            "z": 6,
            "elements": [
                "draconicevolution:infused_obsidian@0"
            ]
        },
        {
            "x": -3,
            "y": 1,
            "z": 3,
            "elements": [
                "gct_ores:everite_block@0"
            ]
        },
        {
            "x": -2,
            "y": 3,
            "z": 4,
            "elements": [
                "gct_ores:everite_block@0"
            ]
        },
        {
            "x": -1,
            "y": 5,
            "z": 5,
            "elements": [
                "gct_ores:fire_alloy@0"
            ]
        },
        {
            "x": 1,
            "y": 7,
            "z": 6,
            "elements": [
                "gct_ores:equipment_witherium_block@0"
            ]
        },
        {
            "x": 0,
            "y": 5,
            "z": 5,
            "elements": [
                "gct_ores:fire_alloy@0"
            ]
        },
        {
            "x": -2,
            "y": 1,
            "z": 3,
            "elements": [
                "abyssalcraft:antiwater@0"
            ]
        },
        {
            "x": -1,
            "y": 3,
            "z": 4,
            "elements": [
                "gct_ores:everite_block@0"
            ]
        },
        {
            "x": 2,
            "y": 7,
            "z": 6,
            "elements": [
                "gct_ores:equipment_witherium_block@0"
            ]
        },
        {
            "x": 1,
            "y": 5,
            "z": 5,
            "elements": [
                "gct_ores:fire_alloy@0"
            ]
        },
        {
            "x": 0,
            "y": 3,
            "z": 4,
            "elements": [
                "gct_ores:everite_block@0"
            ]
        },
        {
            "x": -1,
            "y": 1,
            "z": 3,
            "elements": [
                "abyssalcraft:antiwater@0"
            ]
        },
        {
            "x": 3,
            "y": 7,
            "z": 6,
            "elements": [
                "extrabotany:blockorichalcos@0"
            ]
        },
        {
            "x": 2,
            "y": 5,
            "z": 5,
            "elements": [
                "gct_ores:fire_alloy@0"
            ]
        },
        {
            "x": 1,
            "y": 3,
            "z": 4,
            "elements": [
                "gct_ores:everite_block@0"
            ]
        },
        {
            "x": 0,
            "y": 1,
            "z": 3,
            "elements": [
                "abyssalcraft:antiwater@0"
            ]
        },
        {
            "x": 4,
            "y": 7,
            "z": 6,
            "elements": [
                "additions:greedycraft-cosmilite_block@0"
            ]
        },
        {
            "x": 3,
            "y": 5,
            "z": 5,
            "elements": [
                "gct_ores:fire_alloy@0"
            ]
        },
        {
            "x": 2,
            "y": 3,
            "z": 4,
            "elements": [
                "gct_ores:everite_block@0"
            ]
        },
        {
            "x": 1,
            "y": 1,
            "z": 3,
            "elements": [
                "abyssalcraft:antiwater@0"
            ]
        },
        {
            "x": 4,
            "y": 5,
            "z": 5,
            "elements": [
                "minecraft:barrier@0"
            ]
        },
        {
            "x": 3,
            "y": 3,
            "z": 4,
            "elements": [
                "gct_ores:fire_alloy@0"
            ]
        },
        {
            "x": 2,
            "y": 1,
            "z": 3,
            "elements": [
                "gct_ores:everite_block@0"
            ]
        },
        {
            "x": 4,
            "y": 3,
            "z": 4,
            "elements": [
                "additions:greedycraft-fusion_matrix_block@0"
            ]
        },
        {
            "x": 3,
            "y": 1,
            "z": 3,
            "elements": [
                "gct_ores:fire_alloy@0"
            ]
        },
        {
            "x": 4,
            "y": 1,
            "z": 3,
            "elements": [
                "additions:greedycraft-fusion_matrix_block@0"
            ]
        },
        {
            "x": -5,
            "y": 6,
            "z": 5,
            "elements": [
                "extendedcrafting:storage@2"
            ]
        },
        {
            "x": -5,
            "y": 4,
            "z": 4,
            "elements": [
                "extendedcrafting:storage@2"
            ]
        },
        {
            "x": -4,
            "y": 6,
            "z": 5,
            "elements": [
                "gct_ores:fire_alloy@0"
            ]
        },
        {
            "x": -5,
            "y": 2,
            "z": 3,
            "elements": [
                "minecraft:barrier@0"
            ]
        },
        {
            "x": -4,
            "y": 4,
            "z": 4,
            "elements": [
                "gct_ores:fire_alloy@0"
            ]
        },
        {
            "x": -3,
            "y": 6,
            "z": 5,
            "elements": [
                "gct_ores:fire_alloy@0"
            ]
        },
        {
            "x": -5,
            "y": 0,
            "z": 2,
            "nbt": {"casingColor":"16730368","ForgeCaps":{"abyssalcraft:itemtransfer":{"isRunning":"0b","configurations":[]}},"id":"minecraft:tilecolorablemachinecomponent"},
            "elements": [
                "modularmachinery:blockcasing@4"
            ]
        },
        {
            "x": -4,
            "y": 2,
            "z": 3,
            "elements": [
                "gct_ores:fire_alloy@0"
            ]
        },
        {
            "x": -3,
            "y": 4,
            "z": 4,
            "nbt": {"casingColor":"16730368","ForgeCaps":{"abyssalcraft:itemtransfer":{"isRunning":"0b","configurations":[]}},"id":"minecraft:tilecolorablemachinecomponent"},
            "elements": [
                "modularmachinery:blockcasing@4"
            ]
        },
        {
            "x": -2,
            "y": 6,
            "z": 5,
            "elements": [
                "gct_ores:fire_alloy@0"
            ]
        },
        {
            "x": -4,
            "y": 0,
            "z": 2,
            "nbt": {"casingColor":"16730368","ForgeCaps":{"abyssalcraft:itemtransfer":{"isRunning":"0b","configurations":[]}},"id":"minecraft:tilecolorablemachinecomponent"},
            "elements": [
                "modularmachinery:blockcasing@4"
            ]
        },
        {
            "x": -3,
            "y": 2,
            "z": 3,
            "elements": [
                "gct_ores:balanced_matrix_block@0"
            ]
        },
        {
            "x": -2,
            "y": 4,
            "z": 4,
            "elements": [
                "gct_ores:balanced_matrix_block@0"
            ]
        },
        {
            "x": -1,
            "y": 6,
            "z": 5,
            "elements": [
                "gct_ores:fire_alloy@0"
            ]
        },
        {
            "x": 0,
            "y": 6,
            "z": 5,
            "elements": [
                "gct_ores:fire_alloy@0"
            ]
        },
        {
            "x": -3,
            "y": 0,
            "z": 2,
            "nbt": {"casingColor":"16730368","ForgeCaps":{"abyssalcraft:itemtransfer":{"isRunning":"0b","configurations":[]}},"id":"minecraft:tilecolorablemachinecomponent"},
            "elements": [
                "modularmachinery:blockcasing@4"
            ]
        },
        {
            "x": -2,
            "y": 2,
            "z": 3,
            "elements": [
                "abyssalcraft:antiwater@0"
            ]
        },
        {
            "x": -1,
            "y": 4,
            "z": 4,
            "nbt": {"casingColor":"16730368","ForgeCaps":{"abyssalcraft:itemtransfer":{"isRunning":"0b","configurations":[]}},"id":"minecraft:tilecolorablemachinecomponent"},
            "elements": [
                "modularmachinery:blockcasing@4"
            ]
        },
        {
            "x": 1,
            "y": 6,
            "z": 5,
            "elements": [
                "gct_ores:fire_alloy@0"
            ]
        },
        {
            "x": 0,
            "y": 4,
            "z": 4,
            "nbt": {"casingColor":"16730368","ForgeCaps":{"abyssalcraft:itemtransfer":{"isRunning":"0b","configurations":[]}},"id":"minecraft:tilecolorablemachinecomponent"},
            "elements": [
                "modularmachinery:blockcasing@4"
            ]
        },
        {
            "x": -2,
            "y": 0,
            "z": 2,
            "nbt": {"casingColor":"16730368","ForgeCaps":{"abyssalcraft:itemtransfer":{"isRunning":"0b","configurations":[]}},"id":"minecraft:tilecolorablemachinecomponent"},
            "elements": [
                "modularmachinery:blockcasing@4"
            ]
        },
        {
            "x": -1,
            "y": 2,
            "z": 3,
            "elements": [
                "abyssalcraft:antiwater@0"
            ]
        },
        {
            "x": 2,
            "y": 6,
            "z": 5,
            "elements": [
                "gct_ores:fire_alloy@0"
            ]
        },
        {
            "x": 1,
            "y": 4,
            "z": 4,
            "elements": [
                "gct_ores:balanced_matrix_block@0"
            ]
        },
        {
            "x": 0,
            "y": 2,
            "z": 3,
            "elements": [
                "abyssalcraft:antiwater@1"
            ]
        },
        {
            "x": -1,
            "y": 0,
            "z": 2,
            "nbt": {"casingColor":"16730368","ForgeCaps":{"abyssalcraft:itemtransfer":{"isRunning":"0b","configurations":[]}},"id":"minecraft:tilecolorablemachinecomponent"},
            "elements": [
                "modularmachinery:blockcasing@4"
            ]
        },
        {
            "x": 0,
            "y": 0,
            "z": 2,
            "nbt": {"casingColor":"16730368","ForgeCaps":{"abyssalcraft:itemtransfer":{"isRunning":"0b","configurations":[]}},"id":"minecraft:tilecolorablemachinecomponent"},
            "elements": [
                "modularmachinery:blockcasing@4"
            ]
        },
        {
            "x": 3,
            "y": 6,
            "z": 5,
            "elements": [
                "gct_ores:fire_alloy@0"
            ]
        },
        {
            "x": 2,
            "y": 4,
            "z": 4,
            "nbt": {"casingColor":"16730368","ForgeCaps":{"abyssalcraft:itemtransfer":{"isRunning":"0b","configurations":[]}},"id":"minecraft:tilecolorablemachinecomponent"},
            "elements": [
                "modularmachinery:blockcasing@4"
            ]
        },
        {
            "x": 1,
            "y": 2,
            "z": 3,
            "elements": [
                "abyssalcraft:antiwater@0"
            ]
        },
        {
            "x": 4,
            "y": 6,
            "z": 5,
            "elements": [
                "extendedcrafting:storage@2"
            ]
        },
        {
            "x": 3,
            "y": 4,
            "z": 4,
            "elements": [
                "gct_ores:fire_alloy@0"
            ]
        },
        {
            "x": 2,
            "y": 2,
            "z": 3,
            "elements": [
                "gct_ores:balanced_matrix_block@0"
            ]
        },
        {
            "x": 1,
            "y": 0,
            "z": 2,
            "nbt": {"casingColor":"16730368","ForgeCaps":{"abyssalcraft:itemtransfer":{"isRunning":"0b","configurations":[]}},"id":"minecraft:tilecolorablemachinecomponent"},
            "elements": [
                "modularmachinery:blockcasing@4"
            ]
        },
        {
            "x": 4,
            "y": 4,
            "z": 4,
            "elements": [
                "extendedcrafting:storage@2"
            ]
        },
        {
            "x": 3,
            "y": 2,
            "z": 3,
            "elements": [
                "gct_ores:fire_alloy@0"
            ]
        },
        {
            "x": 2,
            "y": 0,
            "z": 2,
            "nbt": {"casingColor":"16730368","ForgeCaps":{"abyssalcraft:itemtransfer":{"isRunning":"0b","configurations":[]}},"id":"minecraft:tilecolorablemachinecomponent"},
            "elements": [
                "modularmachinery:blockcasing@4"
            ]
        },
        {
            "x": 4,
            "y": 2,
            "z": 3,
            "elements": [
                "minecraft:barrier@0"
            ]
        },
        {
            "x": 3,
            "y": 0,
            "z": 2,
            "nbt": {"casingColor":"16730368","ForgeCaps":{"abyssalcraft:itemtransfer":{"isRunning":"0b","configurations":[]}},"id":"minecraft:tilecolorablemachinecomponent"},
            "elements": [
                "modularmachinery:blockcasing@4"
            ]
        },
        {
            "x": 4,
            "y": 0,
            "z": 2,
            "nbt": {"casingColor":"16730368","ForgeCaps":{"abyssalcraft:itemtransfer":{"isRunning":"0b","configurations":[]}},"id":"minecraft:tilecolorablemachinecomponent"},
            "elements": [
                "modularmachinery:blockcasing@4"
            ]
        },
        {
            "x": -5,
            "y": 7,
            "z": 5,
            "elements": [
                "gct_ores:ruled_draconium_block@0"
            ]
        },
        {
            "x": -5,
            "y": 5,
            "z": 4,
            "elements": [
                "minecraft:barrier@0"
            ]
        },
        {
            "x": -5,
            "y": 3,
            "z": 3,
            "elements": [
                "additions:greedycraft-fusion_matrix_block@0"
            ]
        },
        {
            "x": -4,
            "y": 5,
            "z": 4,
            "elements": [
                "gct_ores:fire_alloy@0"
            ]
        },
        {
            "x": -5,
            "y": 1,
            "z": 2,
            "elements": [
                "additions:greedycraft-fusion_matrix_block@0"
            ]
        },
        {
            "x": -4,
            "y": 3,
            "z": 3,
            "elements": [
                "gct_ores:fire_alloy@0"
            ]
        },
        {
            "x": -3,
            "y": 5,
            "z": 4,
            "elements": [
                "gct_ores:everite_block@0"
            ]
        },
        {
            "x": -4,
            "y": 1,
            "z": 2,
            "elements": [
                "gct_ores:fire_alloy@0"
            ]
        },
        {
            "x": -3,
            "y": 3,
            "z": 3,
            "elements": [
                "gct_ores:everite_block@0"
            ]
        },
        {
            "x": -2,
            "y": 5,
            "z": 4,
            "elements": [
                "gct_ores:everite_block@0"
            ]
        },
        {
            "x": -3,
            "y": 1,
            "z": 2,
            "elements": [
                "gct_ores:everite_block@0"
            ]
        },
        {
            "x": -2,
            "y": 3,
            "z": 3,
            "elements": [
                "abyssalcraft:antiwater@0"
            ]
        },
        {
            "x": -1,
            "y": 5,
            "z": 4,
            "elements": [
                "gct_ores:everite_block@0"
            ]
        },
        {
            "x": 0,
            "y": 5,
            "z": 4,
            "elements": [
                "gct_ores:everite_block@0"
            ]
        },
        {
            "x": -2,
            "y": 1,
            "z": 2,
            "elements": [
                "gct_ores:everite_block@0"
            ]
        },
        {
            "x": -1,
            "y": 3,
            "z": 3,
            "elements": [
                "abyssalcraft:antiwater@0"
            ]
        },
        {
            "x": 1,
            "y": 5,
            "z": 4,
            "elements": [
                "gct_ores:everite_block@0"
            ]
        },
        {
            "x": 0,
            "y": 3,
            "z": 3,
            "elements": [
                "abyssalcraft:antiwater@0"
            ]
        },
        {
            "x": -1,
            "y": 1,
            "z": 2,
            "elements": [
                "gct_ores:everite_block@0"
            ]
        },
        {
            "x": 2,
            "y": 5,
            "z": 4,
            "elements": [
                "gct_ores:everite_block@0"
            ]
        },
        {
            "x": 1,
            "y": 3,
            "z": 3,
            "elements": [
                "abyssalcraft:antiwater@0"
            ]
        },
        {
            "x": 0,
            "y": 1,
            "z": 2,
            "elements": [
                "gct_ores:everite_block@0"
            ]
        },
        {
            "x": 4,
            "y": 7,
            "z": 5,
            "elements": [
                "gct_ores:ruled_draconium_block@0"
            ]
        },
        {
            "x": 3,
            "y": 5,
            "z": 4,
            "elements": [
                "gct_ores:fire_alloy@0"
            ]
        },
        {
            "x": 2,
            "y": 3,
            "z": 3,
            "elements": [
                "gct_ores:everite_block@0"
            ]
        },
        {
            "x": 1,
            "y": 1,
            "z": 2,
            "elements": [
                "gct_ores:everite_block@0"
            ]
        },
        {
            "x": 4,
            "y": 5,
            "z": 4,
            "elements": [
                "minecraft:barrier@0"
            ]
        },
        {
            "x": 3,
            "y": 3,
            "z": 3,
            "elements": [
                "gct_ores:fire_alloy@0"
            ]
        },
        {
            "x": 2,
            "y": 1,
            "z": 2,
            "elements": [
                "gct_ores:everite_block@0"
            ]
        },
        {
            "x": 4,
            "y": 3,
            "z": 3,
            "elements": [
                "additions:greedycraft-fusion_matrix_block@0"
            ]
        },
        {
            "x": 3,
            "y": 1,
            "z": 2,
            "elements": [
                "gct_ores:fire_alloy@0"
            ]
        },
        {
            "x": 4,
            "y": 1,
            "z": 2,
            "elements": [
                "additions:greedycraft-fusion_matrix_block@0"
            ]
        },
        {
            "x": -5,
            "y": 6,
            "z": 4,
            "elements": [
                "extendedcrafting:storage@2"
            ]
        },
        {
            "x": -4,
            "y": 8,
            "z": 5,
            "elements": [
                "additions:greedycraft-cosmilite_block@0"
            ]
        },
        {
            "x": -5,
            "y": 4,
            "z": 3,
            "elements": [
                "extendedcrafting:storage@2"
            ]
        },
        {
            "x": -4,
            "y": 6,
            "z": 4,
            "elements": [
                "gct_ores:fire_alloy@0"
            ]
        },
        {
            "x": -3,
            "y": 8,
            "z": 5,
            "elements": [
                "mekanism:basicblock@2"
            ]
        },
        {
            "x": -5,
            "y": 2,
            "z": 2,
            "elements": [
                "minecraft:barrier@0"
            ]
        },
        {
            "x": -4,
            "y": 4,
            "z": 3,
            "elements": [
                "gct_ores:fire_alloy@0"
            ]
        },
        {
            "x": -3,
            "y": 6,
            "z": 4,
            "elements": [
                "thermalfoundation:fluid_pyrotheum@0"
            ]
        },
        {
            "x": -2,
            "y": 8,
            "z": 5,
            "elements": [
                "mekanism:basicblock@2"
            ]
        },
        {
            "x": -5,
            "y": 0,
            "z": 1,
            "nbt": {"casingColor":"16730368","ForgeCaps":{"abyssalcraft:itemtransfer":{"isRunning":"0b","configurations":[]}},"id":"minecraft:tilecolorablemachinecomponent"},
            "elements": [
                "modularmachinery:blockcasing@4"
            ]
        },
        {
            "x": -4,
            "y": 2,
            "z": 2,
            "elements": [
                "gct_ores:fire_alloy@0"
            ]
        },
        {
            "x": -3,
            "y": 4,
            "z": 3,
            "elements": [
                "gct_ores:balanced_matrix_block@0"
            ]
        },
        {
            "x": -2,
            "y": 6,
            "z": 4,
            "elements": [
                "thermalfoundation:fluid_pyrotheum@0"
            ]
        },
        {
            "x": -1,
            "y": 8,
            "z": 5,
            "elements": [
                "thaumadditions:mithminite_block@0"
            ]
        },
        {
            "x": 0,
            "y": 8,
            "z": 5,
            "elements": [
                "thaumadditions:mithminite_block@0"
            ]
        },
        {
            "x": -4,
            "y": 0,
            "z": 1,
            "nbt": {"casingColor":"16730368","ForgeCaps":{"abyssalcraft:itemtransfer":{"isRunning":"0b","configurations":[]}},"id":"minecraft:tilecolorablemachinecomponent"},
            "elements": [
                "modularmachinery:blockcasing@4"
            ]
        },
        {
            "x": -3,
            "y": 2,
            "z": 2,
            "nbt": {"casingColor":"16730368","ForgeCaps":{"abyssalcraft:itemtransfer":{"isRunning":"0b","configurations":[]}},"id":"minecraft:tilecolorablemachinecomponent"},
            "elements": [
                "modularmachinery:blockcasing@4"
            ]
        },
        {
            "x": -2,
            "y": 4,
            "z": 3,
            "elements": [
                "abyssalcraft:antiwater@0"
            ]
        },
        {
            "x": -1,
            "y": 6,
            "z": 4,
            "elements": [
                "thermalfoundation:fluid_pyrotheum@0"
            ]
        },
        {
            "x": 1,
            "y": 8,
            "z": 5,
            "elements": [
                "mekanism:basicblock@2"
            ]
        },
        {
            "x": 0,
            "y": 6,
            "z": 4,
            "elements": [
                "thermalfoundation:fluid_pyrotheum@0"
            ]
        },
        {
            "x": -3,
            "y": 0,
            "z": 1,
            "nbt": {"casingColor":"16730368","ForgeCaps":{"abyssalcraft:itemtransfer":{"isRunning":"0b","configurations":[]}},"id":"minecraft:tilecolorablemachinecomponent"},
            "elements": [
                "modularmachinery:blockcasing@4"
            ]
        },
        {
            "x": -2,
            "y": 2,
            "z": 2,
            "elements": [
                "gct_ores:balanced_matrix_block@0"
            ]
        },
        {
            "x": -1,
            "y": 4,
            "z": 3,
            "elements": [
                "abyssalcraft:antiwater@0"
            ]
        },
        {
            "x": 2,
            "y": 8,
            "z": 5,
            "elements": [
                "mekanism:basicblock@2"
            ]
        },
        {
            "x": 1,
            "y": 6,
            "z": 4,
            "elements": [
                "thermalfoundation:fluid_pyrotheum@0"
            ]
        },
        {
            "x": 0,
            "y": 4,
            "z": 3,
            "elements": [
                "abyssalcraft:antiwater@0"
            ]
        },
        {
            "x": -2,
            "y": 0,
            "z": 1,
            "nbt": {"casingColor":"16730368","ForgeCaps":{"abyssalcraft:itemtransfer":{"isRunning":"0b","configurations":[]}},"id":"minecraft:tilecolorablemachinecomponent"},
            "elements": [
                "modularmachinery:blockcasing@4"
            ]
        },
        {
            "x": -1,
            "y": 2,
            "z": 2,
            "nbt": {"casingColor":"16730368","ForgeCaps":{"abyssalcraft:itemtransfer":{"isRunning":"0b","configurations":[]}},"id":"minecraft:tilecolorablemachinecomponent"},
            "elements": [
                "modularmachinery:blockcasing@4"
            ]
        },
        {
            "x": 3,
            "y": 8,
            "z": 5,
            "elements": [
                "additions:greedycraft-cosmilite_block@0"
            ]
        },
        {
            "x": 2,
            "y": 6,
            "z": 4,
            "elements": [
                "thermalfoundation:fluid_pyrotheum@0"
            ]
        },
        {
            "x": 1,
            "y": 4,
            "z": 3,
            "elements": [
                "abyssalcraft:antiwater@0"
            ]
        },
        {
            "x": 0,
            "y": 2,
            "z": 2,
            "nbt": {"casingColor":"16730368","ForgeCaps":{"abyssalcraft:itemtransfer":{"isRunning":"0b","configurations":[]}},"id":"minecraft:tilecolorablemachinecomponent"},
            "elements": [
                "modularmachinery:blockcasing@4"
            ]
        },
        {
            "x": -1,
            "y": 0,
            "z": 1,
            "nbt": {"casingColor":"16730368","ForgeCaps":{"abyssalcraft:itemtransfer":{"isRunning":"0b","configurations":[]}},"id":"minecraft:tilecolorablemachinecomponent"},
            "elements": [
                "modularmachinery:blockcasing@4"
            ]
        },
        {
            "x": 0,
            "y": 0,
            "z": 1,
            "nbt": {"casingColor":"16730368","ForgeCaps":{"abyssalcraft:itemtransfer":{"isRunning":"0b","configurations":[]}},"id":"minecraft:tilecolorablemachinecomponent"},
            "elements": [
                "modularmachinery:blockcasing@4"
            ]
        },
        {
            "x": 3,
            "y": 6,
            "z": 4,
            "elements": [
                "gct_ores:fire_alloy@0"
            ]
        },
        {
            "x": 2,
            "y": 4,
            "z": 3,
            "elements": [
                "gct_ores:balanced_matrix_block@0"
            ]
        },
        {
            "x": 1,
            "y": 2,
            "z": 2,
            "elements": [
                "gct_ores:balanced_matrix_block@0"
            ]
        },
        {
            "x": 4,
            "y": 6,
            "z": 4,
            "elements": [
                "extendedcrafting:storage@2"
            ]
        },
        {
            "x": 3,
            "y": 4,
            "z": 3,
            "elements": [
                "gct_ores:fire_alloy@0"
            ]
        },
        {
            "x": 2,
            "y": 2,
            "z": 2,
            "nbt": {"casingColor":"16730368","ForgeCaps":{"abyssalcraft:itemtransfer":{"isRunning":"0b","configurations":[]}},"id":"minecraft:tilecolorablemachinecomponent"},
            "elements": [
                "modularmachinery:blockcasing@4"
            ]
        },
        {
            "x": 1,
            "y": 0,
            "z": 1,
            "nbt": {"casingColor":"16730368","ForgeCaps":{"abyssalcraft:itemtransfer":{"isRunning":"0b","configurations":[]}},"id":"minecraft:tilecolorablemachinecomponent"},
            "elements": [
                "modularmachinery:blockcasing@4"
            ]
        },
        {
            "x": 4,
            "y": 4,
            "z": 3,
            "elements": [
                "extendedcrafting:storage@2"
            ]
        },
        {
            "x": 3,
            "y": 2,
            "z": 2,
            "elements": [
                "gct_ores:fire_alloy@0"
            ]
        },
        {
            "x": 2,
            "y": 0,
            "z": 1,
            "nbt": {"casingColor":"16730368","ForgeCaps":{"abyssalcraft:itemtransfer":{"isRunning":"0b","configurations":[]}},"id":"minecraft:tilecolorablemachinecomponent"},
            "elements": [
                "modularmachinery:blockcasing@4"
            ]
        },
        {
            "x": 4,
            "y": 2,
            "z": 2,
            "elements": [
                "minecraft:barrier@0"
            ]
        },
        {
            "x": 3,
            "y": 0,
            "z": 1,
            "nbt": {"casingColor":"16730368","ForgeCaps":{"abyssalcraft:itemtransfer":{"isRunning":"0b","configurations":[]}},"id":"minecraft:tilecolorablemachinecomponent"},
            "elements": [
                "modularmachinery:blockcasing@4"
            ]
        },
        {
            "x": 4,
            "y": 0,
            "z": 1,
            "nbt": {"casingColor":"16730368","ForgeCaps":{"abyssalcraft:itemtransfer":{"isRunning":"0b","configurations":[]}},"id":"minecraft:tilecolorablemachinecomponent"},
            "elements": [
                "modularmachinery:blockcasing@4"
            ]
        },
        {
            "x": -5,
            "y": 7,
            "z": 4,
            "elements": [
                "gct_ores:ruled_draconium_block@0"
            ]
        },
        {
            "x": -5,
            "y": 5,
            "z": 3,
            "elements": [
                "minecraft:barrier@0"
            ]
        },
        {
            "x": -5,
            "y": 3,
            "z": 2,
            "elements": [
                "additions:greedycraft-fusion_matrix_block@0"
            ]
        },
        {
            "x": -4,
            "y": 5,
            "z": 3,
            "elements": [
                "gct_ores:fire_alloy@0"
            ]
        },
        {
            "x": -5,
            "y": 1,
            "z": 1,
            "elements": [
                "additions:greedycraft-fusion_matrix_block@0"
            ]
        },
        {
            "x": -4,
            "y": 3,
            "z": 2,
            "elements": [
                "gct_ores:fire_alloy@0"
            ]
        },
        {
            "x": -3,
            "y": 5,
            "z": 3,
            "elements": [
                "gct_ores:everite_block@0"
            ]
        },
        {
            "x": -4,
            "y": 1,
            "z": 1,
            "elements": [
                "gct_ores:fire_alloy@0"
            ]
        },
        {
            "x": -3,
            "y": 3,
            "z": 2,
            "elements": [
                "gct_ores:everite_block@0"
            ]
        },
        {
            "x": -2,
            "y": 5,
            "z": 3,
            "elements": [
                "abyssalcraft:antiwater@0"
            ]
        },
        {
            "x": -3,
            "y": 1,
            "z": 1,
            "elements": [
                "gct_ores:fire_alloy@0"
            ]
        },
        {
            "x": -2,
            "y": 3,
            "z": 2,
            "elements": [
                "gct_ores:everite_block@0"
            ]
        },
        {
            "x": -1,
            "y": 5,
            "z": 3,
            "elements": [
                "abyssalcraft:antiwater@0"
            ]
        },
        {
            "x": 0,
            "y": 5,
            "z": 3,
            "elements": [
                "abyssalcraft:antiwater@0"
            ]
        },
        {
            "x": -2,
            "y": 1,
            "z": 1,
            "elements": [
                "gct_ores:fire_alloy@0"
            ]
        },
        {
            "x": -1,
            "y": 3,
            "z": 2,
            "elements": [
                "gct_ores:everite_block@0"
            ]
        },
        {
            "x": 1,
            "y": 5,
            "z": 3,
