{
    "registryname": "aeonsteel_forge",
    "localizedname": "恒钢熔合机",
    "requires-blueprint": true,
    "color": "cccccc",
    "failure-action": "still",
    "modifiers": [
        {
            "elements": "modularmachinery:blockcasing@1",
            "x": 0,
            "y": 1,
            "z": 0,
            "description": "将控制器上方紧挨着的方块换成此方块以降低配方制作时间至80%！",
            "modifier": {
                "io": "output",
                "target": "duration",
                "operation": 1,
                "multiplier": 0.80
            }
        },
        {
            "elements": "modularmachinery:blockcasing@2",
            "x": 0,
            "y": 1,
            "z": 0,
            "description": "将控制器上方紧挨着的方块换成此方块以降低配方制作时间至70%！",
            "modifier": {
                "io": "output",
                "target": "duration",
                "operation": 1,
                "multiplier": 0.70
            }
        },
        {
            "elements": "modularmachinery:blockcasing@3",
            "x": 0,
            "y": 1,
            "z": 0,
            "description": "将控制器上方紧挨着的方块换成此方块以降低配方制作时间至60%！",
            "modifier": {
                "io": "output",
                "target": "duration",
                "operation": 1,
                "multiplier": 0.60
            }
        },
        {
            "elements": "modularmachinery:blockcasing@5",
            "x": 0,
            "y": 1,
            "z": 0,
            "description": "将控制器上方紧挨着的方块换成此方块以降低配方制作时间至50%！",
            "modifier": {
                "io": "output",
                "target": "duration",
                "operation": 1,
                "multiplier": 0.50
            }
        }
    ],
    "parts": [
        {
            "x": 1,
            "y": 2,
            "z": 1,
            "elements": [
                "casings_upgrade"
            ]
        },
        {
            "x": 2,
            "y": 2,
            "z": 1,
            "elements": [
                "casings_upgrade"
            ]
        },
        {
            "x": 1,
            "y": 0,
            "z": 0,
            "elements": [
                "casings_upgrade"
            ]
        },
        {
            "x": 7,
            "y": 2,
            "z": 1,
            "elements": [
                "casings_all"
            ]
        },
        {
            "x": 5,
            "y": -3,
            "z": -1,
            "elements": [
                "casings_all"
            ]
        },
        {
            "x": -5,
            "y": 3,
            "z": 1,
            "elements": [
                "casings_all"
            ]
        },
        {
            "x": -5,
            "y": 1,
            "z": 0,
            "elements": [
                "casings_all"
            ]
        },
        {
            "x": -3,
            "y": 5,
            "z": 2,
            "elements": [
                "casings_all"
            ]
        },
        {
            "x": 1,
            "y": 7,
            "z": 3,
            "elements": [
                "casings_all"
            ]
        },
        {
            "x": 0,
            "y": 1,
            "z": 0,
            "elements": [
                "casings_upgrade"
            ]
        },
        {
            "x": -3,
            "y": -3,
            "z": -1,
            "elements": [
                "casings_all"
            ]
        },
        {
            "x": 1,
            "y": 1,
            "z": 0,
            "elements": [
                "casings_upgrade"
            ]
        },
        {
            "x": 2,
            "y": 1,
            "z": 0,
            "elements": [
                "casings_upgrade"
            ]
        },
        {
            "x": 5,
            "y": 5,
            "z": 2,
            "elements": [
                "casings_all"
            ]
        },
        {
            "x": 7,
            "y": 3,
            "z": 1,
            "elements": [
                "casings_all"
            ]
        },
        {
            "x": 7,
            "y": 1,
            "z": 0,
            "elements": [
                "casings_all"
            ]
        },
        {
            "x": 1,
            "y": -1,
            "z": 7,
            "elements": [
                "casings_all"
            ]
        },
        {
            "x": 1,
            "y": -3,
            "z": 6,
            "elements": [
                "casings_all"
            ]
        },
        {
            "x": -4,
            "y": 4,
            "z": 1,
            "elements": [
                "casings_all"
            ]
        },
        {
            "x": 1,
            "y": 2,
            "z": 0,
            "elements": [
                "casings_upgrade"
            ]
        },
        {
            "x": 6,
            "y": 4,
            "z": 1,
            "elements": [
                "casings_all"
            ]
        },
        {
            "x": 1,
            "y": 0,
            "z": 7,
            "elements": [
                "casings_all"
            ]
        },
        {
            "x": 1,
            "y": -2,
            "z": 6,
            "elements": [
                "casings_all"
            ]
        },
        {
            "x": 1,
            "y": -4,
            "z": 5,
            "elements": [
                "casings_all"
            ]
        },
        {
            "x": 5,
            "y": -3,
            "z": 0,
            "elements": [
                "casings_all"
            ]
        },
        {
            "x": -4,
            "y": 5,
            "z": 1,
            "elements": [
                "casings_all"
            ]
        },
        {
            "x": -3,
            "y": 5,
            "z": 1,
            "elements": [
                "casings_all"
            ]
        },
        {
            "x": 1,
            "y": -5,
            "z": -1,
            "elements": [
                "casings_all"
            ]
        },
        {
            "x": 1,
            "y": 7,
            "z": 2,
            "elements": [
                "casings_all"
            ]
        },
        {
            "x": -3,
            "y": -3,
            "z": 0,
            "elements": [
                "casings_all"
            ]
        },
        {
            "x": 5,
            "y": 5,
            "z": 1,
            "elements": [
                "casings_all"
            ]
        },
        {
            "x": 6,
            "y": 5,
            "z": 1,
            "elements": [
                "casings_all"
            ]
        },
        {
            "x": -3,
            "y": -3,
            "z": 5,
            "elements": [
                "casings_all"
            ]
        },
        {
            "x": -1,
            "y": 1,
            "z": 7,
            "elements": [
                "casings_all"
            ]
        },
        {
            "x": 0,
            "y": 1,
            "z": 7,
            "elements": [
                "casings_all"
            ]
        },
        {
            "x": 1,
            "y": 3,
            "z": -5,
            "elements": [
                "casings_all"
            ]
        },
        {
            "x": -2,
            "y": -3,
            "z": 5,
            "elements": [
                "casings_all"
            ]
        },
        {
            "x": -1,
            "y": -3,
            "z": 5,
            "elements": [
                "casings_all"
            ]
        },
        {
            "x": 1,
            "y": 5,
            "z": -4,
            "elements": [
                "casings_all"
            ]
        },
        {
            "x": 1,
            "y": 1,
            "z": 7,
            "elements": [
                "casings_all"
            ]
        },
        {
            "x": 0,
            "y": -3,
            "z": 5,
            "elements": [
                "casings_all"
            ]
        },
        {
            "x": 2,
            "y": 1,
            "z": 7,
            "elements": [
                "casings_all"
            ]
        },
        {
            "x": 3,
            "y": 1,
            "z": 7,
            "elements": [
                "casings_all"
            ]
        },
        {
            "x": 1,
            "y": -3,
            "z": 5,
            "elements": [
                "casings_all"
            ]
        },
        {
            "x": 2,
            "y": -3,
            "z": 5,
            "elements": [
                "casings_all"
            ]
        },
        {
            "x": 3,
            "y": -3,
            "z": 5,
            "elements": [
                "casings_all"
            ]
        },
        {
            "x": 4,
            "y": -3,
            "z": 5,
            "elements": [
                "casings_all"
            ]
        },
        {
            "x": 5,
            "y": -3,
            "z": 5,
            "elements": [
                "casings_all"
            ]
        },
        {
            "x": -3,
            "y": 6,
            "z": 1,
            "elements": [
                "casings_all"
            ]
        },
        {
            "x": -2,
            "y": 6,
            "z": 1,
            "elements": [
                "casings_all"
            ]
        },
        {
            "x": 4,
            "y": 6,
            "z": 1,
            "elements": [
                "casings_all"
            ]
        },
        {
            "x": 5,
            "y": 6,
            "z": 1,
            "elements": [
                "casings_all"
            ]
        },
        {
            "x": -3,
            "y": -2,
            "z": 5,
            "elements": [
                "casings_all"
            ]
        },
        {
            "x": 1,
            "y": 2,
            "z": -5,
            "elements": [
                "casings_all"
            ]
        },
        {
            "x": 1,
            "y": 4,
            "z": -4,
            "elements": [
                "casings_all"
            ]
        },
        {
            "x": 1,
            "y": 2,
            "z": 7,
            "elements": [
                "casings_all"
            ]
        },
        {
            "x": 1,
            "y": 6,
            "z": -3,
            "elements": [
                "casings_all"
            ]
        },
        {
            "x": 1,
            "y": -4,
            "z": 4,
            "elements": [
                "casings_all"
            ]
        },
        {
            "x": 5,
            "y": -2,
            "z": 5,
            "elements": [
                "casings_all"
            ]
        },
        {
            "x": -3,
            "y": 5,
            "z": 0,
            "elements": [
                "casings_all"
            ]
        },
        {
            "x": -1,
            "y": 7,
            "z": 1,
            "elements": [
                "casings_all"
            ]
        },
        {
            "x": 1,
            "y": -5,
            "z": 0,
            "elements": [
                "casings_all"
            ]
        },
        {
            "x": 0,
            "y": 7,
            "z": 1,
            "elements": [
                "casings_all"
            ]
        },
        {
            "x": 1,
            "y": 7,
            "z": 1,
            "elements": [
                "casings_all"
            ]
        },
        {
            "x": 2,
            "y": 7,
            "z": 1,
            "elements": [
                "casings_all"
            ]
        },
        {
            "x": 3,
            "y": 7,
            "z": 1,
            "elements": [
                "casings_all"
            ]
        },
        {
            "x": 5,
            "y": 5,
            "z": 0,
            "elements": [
                "casings_all"
            ]
        },
        {
            "x": -3,
            "y": 1,
            "z": 6,
            "elements": [
                "casings_all"
            ]
        },
        {
            "x": 5,
            "y": 5,
            "z": -3,
            "elements": [
                "casings_all"
            ]
        },
        {
            "x": 3,
            "y": 1,
            "z": -5,
            "elements": [
                "casings_all"
            ]
        },
        {
            "x": -3,
            "y": -1,
            "z": 5,
            "elements": [
                "casings_all"
            ]
        },
        {
            "x": -2,
            "y": 1,
            "z": 6,
            "elements": [
                "casings_all"
            ]
        },
        {
            "x": 4,
            "y": 5,
            "z": -3,
            "elements": [
                "casings_all"
            ]
        },
        {
            "x": 2,
            "y": 1,
            "z": -5,
            "elements": [
                "casings_all"
            ]
        },
        {
            "x": -3,
            "y": -3,
            "z": 4,
            "elements": [
                "casings_all"
            ]
        },
        {
            "x": 3,
            "y": 5,
            "z": -3,
            "elements": [
                "casings_all"
            ]
        },
        {
            "x": 1,
            "y": 1,
            "z": -5,
            "elements": [
                "casings_all"
            ]
        },
        {
            "x": 1,
            "y": 3,
            "z": 7,
            "elements": [
                "casings_all"
            ]
        },
        {
            "x": 2,
            "y": 5,
            "z": -3,
            "elements": [
                "casings_all"
            ]
        },
        {
            "x": 0,
            "y": 1,
            "z": -5,
            "elements": [
                "casings_all"
            ]
        },
        {
            "x": 1,
            "y": 5,
            "z": -3,
            "elements": [
                "casings_all"
            ]
        },
        {
            "x": -1,
            "y": 1,
            "z": -5,
            "elements": [
                "casings_all"
            ]
        },
        {
            "x": 0,
            "y": 5,
            "z": -3,
            "elements": [
                "casings_all"
            ]
        },
        {
            "x": -1,
            "y": 5,
            "z": -3,
            "elements": [
                "casings_all"
            ]
        },
        {
            "x": -2,
            "y": 5,
            "z": -3,
            "elements": [
                "casings_all"
            ]
        },
        {
            "x": 4,
            "y": 1,
            "z": 6,
            "elements": [
                "casings_all"
            ]
        },
        {
            "x": 1,
            "y": -5,
            "z": 3,
            "elements": [
                "casings_all"
            ]
        },
        {
            "x": -3,
            "y": 5,
            "z": -3,
            "elements": [
                "casings_all"
            ]
        },
        {
            "x": 5,
            "y": 1,
            "z": 6,
            "elements": [
                "casings_all"
            ]
        },
        {
            "x": 5,
            "y": -1,
            "z": 5,
            "elements": [
                "casings_all"
            ]
        },
        {
            "x": 5,
            "y": -3,
            "z": 4,
            "elements": [
                "casings_all"
            ]
        },
        {
            "x": 5,
            "y": 4,
            "z": -3,
            "elements": [
                "casings_all"
            ]
        },
        {
            "x": -3,
            "y": 0,
            "z": 5,
            "elements": [
                "casings_all"
            ]
        },
        {
            "x": 1,
            "y": 0,
            "z": -5,
            "elements": [
                "casings_all"
            ]
        },
        {
            "x": 1,
            "y": 6,
            "z": -2,
            "elements": [
                "casings_all"
            ]
        },
        {
            "x": -3,
            "y": 4,
            "z": -3,
            "elements": [
                "casings_all"
            ]
        },
        {
            "x": 5,
            "y": 0,
            "z": 5,
            "elements": [
                "casings_all"
            ]
        },
        {
            "x": 1,
            "y": 7,
            "z": 0,
            "elements": [
                "casings_all"
            ]
        },
        {
            "x": 5,
            "y": 1,
            "z": -4,
            "elements": [
                "casings_all"
            ]
        },
        {
            "x": -4,
            "y": 1,
            "z": 5,
            "elements": [
                "casings_all"
            ]
        },
        {
            "x": 5,
            "y": 3,
            "z": -3,
            "elements": [
                "casings_all"
            ]
        },
        {
            "x": 4,
            "y": 1,
            "z": -4,
            "elements": [
                "casings_all"
            ]
        },
        {
            "x": -3,
            "y": 1,
            "z": 5,
            "elements": [
                "casings_all"
            ]
        },
        {
            "x": 5,
            "y": 5,
            "z": -2,
            "elements": [
                "casings_all"
            ]
        },
        {
            "x": 1,
            "y": -1,
            "z": -5,
            "elements": [
                "casings_all"
            ]
        },
        {
            "x": -3,
            "y": -3,
            "z": 3,
            "elements": [
                "casings_all"
            ]
        },
        {
            "x": 1,
            "y": 7,
            "z": -1,
            "elements": [
                "casings_all"
            ]
        },
        {
            "x": -2,
            "y": 1,
            "z": -4,
            "elements": [
                "casings_all"
            ]
        },
        {
            "x": -3,
            "y": 1,
            "z": -4,
            "elements": [
                "casings_all"
            ]
        },
        {
            "x": -3,
            "y": 3,
            "z": -3,
            "elements": [
                "casings_all"
            ]
        },
        {
            "x": 1,
            "y": -5,
            "z": 2,
            "elements": [
                "casings_all"
            ]
        },
        {
            "x": -3,
            "y": 5,
            "z": -2,
            "elements": [
                "casings_all"
            ]
        },
        {
            "x": 5,
            "y": 1,
            "z": 5,
            "elements": [
                "casings_all"
            ]
        },
        {
            "x": 6,
            "y": 1,
            "z": 5,
            "elements": [
                "casings_all"
            ]
        },
        {
            "x": 5,
            "y": -3,
            "z": 3,
            "elements": [
                "casings_all"
            ]
        },
        {
            "x": 5,
            "y": 2,
            "z": -3,
            "elements": [
                "casings_all"
            ]
        },
        {
            "x": -3,
            "y": 2,
            "z": 5,
            "elements": [
                "casings_all"
            ]
        },
        {
            "x": 1,
            "y": 4,
            "z": 6,
            "elements": [
                "casings_all"
            ]
        },
        {
            "x": -3,
            "y": 2,
            "z": -3,
            "elements": [
                "casings_all"
            ]
        },
        {
            "x": 5,
            "y": 2,
            "z": 5,
            "elements": [
                "casings_all"
            ]
        },
        {
            "x": 6,
            "y": 1,
            "z": -3,
            "elements": [
                "casings_all"
            ]
        },
        {
            "x": 5,
            "y": 1,
            "z": -3,
            "elements": [
                "casings_all"
            ]
        },
        {
            "x": -4,
            "y": 1,
            "z": 4,
            "elements": [
                "casings_all"
            ]
        },
        {
            "x": -3,
            "y": 3,
            "z": 5,
            "elements": [
                "casings_all"
            ]
        },
        {
            "x": 5,
            "y": 5,
            "z": -1,
            "elements": [
                "casings_all"
            ]
        },
        {
            "x": 1,
            "y": 5,
            "z": 6,
            "elements": [
                "casings_all"
            ]
        },
        {
            "x": -3,
            "y": -3,
            "z": 2,
            "elements": [
                "casings_all"
            ]
        },
        {
            "x": -1,
            "y": -5,
            "z": 1,
            "elements": [
                "casings_all"
            ]
        },
        {
            "x": -4,
            "y": -3,
            "z": -5,
            "elements": [
                "additions:greedycraft-durasteel_block@0"
            ]
        },
        {
            "x": 0,
            "y": -5,
            "z": 1,
            "elements": [
                "casings_all"
            ]
        },
        {
            "x": -3,
            "y": 1,
            "z": -3,
            "elements": [
                "casings_all"
            ]
        },
        {
            "x": -4,
            "y": 1,
            "z": -3,
            "elements": [
                "casings_all"
            ]
        },
        {
            "x": 5,
            "y": 3,
            "z": 5,
            "elements": [
                "casings_all"
            ]
        },
        {
            "x": 1,
            "y": -5,
            "z": 1,
            "elements": [
                "casings_all"
            ]
        },
        {
            "x": -3,
            "y": 5,
            "z": -1,
            "elements": [
                "casings_all"
            ]
        },
        {
            "x": 2,
            "y": -5,
            "z": 1,
            "elements": [
                "casings_all"
            ]
        },
        {
            "x": 6,
            "y": 1,
            "z": 4,
            "elements": [
                "casings_all"
            ]
        },
        {
            "x": 3,
            "y": -5,
            "z": 1,
            "elements": [
                "casings_all"
            ]
        },
        {
            "x": 5,
            "y": -3,
            "z": 2,
            "elements": [
                "casings_all"
            ]
        },
        {
            "x": 5,
            "y": 0,
            "z": -3,
            "elements": [
                "casings_all"
            ]
        },
        {
            "x": -3,
            "y": 4,
            "z": 5,
            "elements": [
                "casings_all"
            ]
        },
        {
            "x": 1,
            "y": -2,
            "z": -4,
            "elements": [
                "casings_all"
            ]
        },
        {
            "x": -3,
            "y": -4,
            "z": 1,
            "elements": [
                "casings_all"
            ]
        },
        {
            "x": -3,
            "y": -4,
            "z": -5,
            "elements": [
                "additions:greedycraft-durasteel_block@0"
            ]
        },
        {
            "x": -2,
            "y": -4,
            "z": 1,
            "elements": [
                "casings_all"
            ]
        },
        {
            "x": -4,
            "y": -4,
            "z": -5,
            "elements": [
                "thermalfoundation:glass_alloy@7"
            ]
        },
        {
            "x": -5,
            "y": -4,
            "z": -5,
            "elements": [
                "additions:greedycraft-durasteel_block@0"
            ]
        },
        {
            "x": -3,
            "y": 0,
            "z": -3,
            "elements": [
                "casings_all"
            ]
        },
        {
            "x": 5,
            "y": 4,
            "z": 5,
            "elements": [
                "casings_all"
            ]
        },
        {
            "x": 4,
            "y": -4,
            "z": 1,
            "elements": [
                "casings_all"
            ]
        },
        {
            "x": 5,
            "y": -4,
            "z": 1,
            "elements": [
                "casings_all"
            ]
        },
        {
            "x": 6,
            "y": 1,
            "z": -2,
            "elements": [
                "casings_all"
            ]
        },
        {
            "x": 5,
            "y": -1,
            "z": -3,
            "elements": [
                "casings_all"
            ]
        },
        {
            "x": -5,
            "y": 1,
            "z": 3,
            "elements": [
                "casings_all"
            ]
        },
        {
            "x": -3,
            "y": 5,
            "z": 5,
            "elements": [
                "casings_all"
            ]
        },
        {
            "x": -2,
            "y": 5,
            "z": 5,
            "elements": [
                "casings_all"
            ]
        },
        {
            "x": -1,
            "y": 5,
            "z": 5,
            "elements": [
                "casings_all"
            ]
        },
        {
            "x": 1,
            "y": -3,
            "z": -4,
            "elements": [
                "casings_all"
            ]
        },
        {
            "x": 0,
            "y": 5,
            "z": 5,
            "elements": [
                "casings_all"
            ]
        },
        {
            "x": -4,
            "y": -3,
            "z": 1,
            "elements": [
                "casings_all"
            ]
        },
        {
            "x": 1,
            "y": 5,
            "z": 5,
            "elements": [
                "casings_all"
            ]
        },
        {
            "x": -3,
            "y": -3,
            "z": 1,
            "elements": [
                "casings_all"
            ]
        },
        {
            "x": 2,
            "y": 5,
            "z": 5,
            "elements": [
                "casings_all"
            ]
        },
        {
            "x": -4,
            "y": -5,
            "z": -5,
            "elements": [
                "additions:greedycraft-durasteel_block@0"
            ]
        },
        {
            "x": -3,
            "y": -3,
            "z": -4,
            "elements": [
                "additions:greedycraft-durasteel_block@0"
            ]
        },
        {
            "x": 3,
            "y": 5,
            "z": 5,
            "elements": [
                "casings_all"
            ]
        },
        {
            "x": -4,
            "y": -3,
            "z": -4,
            "elements": [
                "thermalfoundation:glass_alloy@7"
            ]
        },
        {
            "x": -3,
            "y": -1,
            "z": -3,
            "elements": [
                "casings_all"
            ]
        },
        {
            "x": 4,
            "y": 5,
            "z": 5,
            "elements": [
                "casings_all"
            ]
        },
        {
            "x": -5,
            "y": -3,
            "z": -4,
            "elements": [
                "additions:greedycraft-durasteel_block@0"
            ]
        },
        {
            "x": 5,
            "y": 5,
            "z": 5,
            "elements": [
                "casings_all"
            ]
        },
        {
            "x": -4,
            "y": 1,
            "z": -2,
            "elements": [
                "casings_all"
            ]
        },
        {
            "x": 7,
            "y": 1,
            "z": 3,
            "elements": [
                "casings_all"
            ]
        },
        {
            "x": 5,
            "y": -3,
            "z": 1,
            "elements": [
                "casings_all"
            ]
        },
        {
            "x": 6,
            "y": -3,
            "z": 1,
            "elements": [
                "casings_all"
            ]
        },
        {
            "x": 5,
            "y": -2,
            "z": -3,
            "elements": [
                "casings_all"
            ]
        },
        {
            "x": -4,
            "y": -2,
            "z": 1,
            "elements": [
                "casings_all"
            ]
        },
        {
            "x": 1,
            "y": 6,
            "z": 5,
            "elements": [
                "casings_all"
            ]
        },
        {
            "x": -3,
            "y": -4,
            "z": -4,
            "elements": [
                "thermalfoundation:glass_alloy@7"
            ]
        },
        {
            "x": -4,
            "y": -4,
            "z": -4,
            "elements": [
                "taiga:molten_nitronite_fluid@0"
            ]
        },
        {
            "x": -3,
            "y": -2,
            "z": -3,
            "elements": [
                "casings_all"
            ]
        },
        {
            "x": 1,
            "y": 0,
            "z": 2,
            "elements": [
                "casings_upgrade"
            ]
        },
        {
            "x": -5,
            "y": -4,
            "z": -4,
            "elements": [
                "thermalfoundation:glass_alloy@7"
            ]
        },
        {
            "x": 6,
            "y": -2,
            "z": 1,
            "elements": [
                "casings_all"
            ]
        },
        {
            "x": 7,
            "y": 1,
            "z": -1,
            "elements": [
                "casings_all"
            ]
        },
        {
            "x": 5,
            "y": -3,
            "z": -3,
            "elements": [
                "casings_all"
            ]
        },
        {
            "x": 4,
            "y": -3,
            "z": -3,
            "elements": [
                "casings_all"
            ]
        },
        {
            "x": -5,
            "y": 1,
            "z": 2,
            "elements": [
                "casings_all"
            ]
        },
        {
            "x": -3,
            "y": 5,
            "z": 4,
            "elements": [
                "casings_all"
            ]
        },
        {
            "x": 3,
            "y": -3,
            "z": -3,
            "elements": [
                "casings_all"
            ]
        },
        {
            "x": -5,
            "y": -1,
            "z": 1,
            "elements": [
                "casings_all"
            ]
        },
        {
            "x": 2,
            "y": -3,
            "z": -3,
            "elements": [
                "casings_all"
            ]
        },
        {
            "x": 1,
            "y": -3,
            "z": -3,
            "elements": [
                "casings_all"
            ]
        },
        {
            "x": 0,
            "y": -3,
            "z": -3,
            "elements": [
                "casings_all"
            ]
        },
        {
            "x": -1,
            "y": -3,
            "z": -3,
            "elements": [
                "casings_all"
            ]
        },
        {
            "x": 0,
            "y": 1,
            "z": 2,
            "elements": [
                "casings_upgrade"
            ]
        },
        {
            "x": -3,
            "y": -5,
            "z": -4,
            "elements": [
                "additions:greedycraft-durasteel_block@0"
            ]
        },
        {
            "x": -2,
            "y": -3,
            "z": -3,
            "elements": [
                "casings_all"
            ]
        },
        {
            "x": -4,
            "y": -5,
            "z": -4,
            "elements": [
                "thermalfoundation:glass_alloy@7"
            ]
        },
        {
            "x": -3,
            "y": -3,
            "z": -3,
            "elements": [
                "casings_all"
            ]
        },
        {
            "x": 1,
            "y": 1,
            "z": 2,
            "elements": [
                "casings_upgrade"
            ]
        },
        {
            "x": -5,
            "y": -5,
            "z": -4,
            "elements": [
                "additions:greedycraft-durasteel_block@0"
            ]
        },
        {
            "x": -4,
            "y": -3,
            "z": -3,
            "elements": [
                "additions:greedycraft-durasteel_block@0"
            ]
        },
        {
            "x": 2,
            "y": 1,
            "z": 2,
            "elements": [
                "casings_upgrade"
            ]
        },
        {
            "x": 5,
            "y": 5,
            "z": 4,
            "elements": [
                "casings_all"
            ]
        },
        {
            "x": -5,
            "y": 1,
            "z": -1,
            "elements": [
                "casings_all"
            ]
        },
        {
            "x": 7,
            "y": 1,
            "z": 2,
            "elements": [
                "casings_all"
            ]
        },
        {
            "x": 7,
            "y": -1,
            "z": 1,
            "elements": [
                "casings_all"
            ]
        },
        {
            "x": -5,
            "y": 0,
            "z": 1,
            "elements": [
                "casings_all"
            ]
        },
        {
            "x": 1,
            "y": -4,
            "z": -3,
            "elements": [
                "casings_all"
            ]
        },
        {
            "x": 1,
            "y": 6,
            "z": 4,
            "elements": [
                "casings_all"
            ]
        },
        {
            "x": 0,
            "y": 0,
            "z": 1,
            "elements": [
                "casings_upgrade"
            ]
        },
        {
            "x": -3,
            "y": -4,
            "z": -3,
            "elements": [
                "additions:greedycraft-durasteel_block@0"
            ]
        },
        {
            "x": 1,
            "y": 2,
            "z": 2,
            "elements": [
                "casings_upgrade"
            ]
        },
        {
            "x": -4,
            "y": -4,
            "z": -3,
            "elements": [
                "thermalfoundation:glass_alloy@7"
            ]
        },
        {
            "x": 1,
            "y": 0,
            "z": 1,
            "elements": [
                "casings_upgrade"
            ]
        },
        {
            "x": -5,
            "y": -4,
            "z": -3,
            "elements": [
                "additions:greedycraft-durasteel_block@0"
            ]
        },
        {
            "x": 2,
            "y": 0,
            "z": 1,
            "elements": [
                "casings_upgrade"
            ]
        },
        {
            "x": 7,
            "y": 0,
            "z": 1,
            "elements": [
                "casings_all"
            ]
        },
        {
            "x": 5,
            "y": -3,
            "z": -2,
            "elements": [
                "casings_all"
            ]
        },
        {
            "x": -5,
            "y": 1,
            "z": 1,
            "elements": [
                "casings_all"
            ]
        },
        {
            "x": -3,
            "y": 5,
            "z": 3,
            "elements": [
                "casings_all"
            ]
        },
        {
            "x": 0,
            "y": 1,
            "z": 1,
            "elements": [
                "casings_upgrade"
            ]
        },
        {
            "x": -4,
            "y": -5,
            "z": -3,
            "elements": [
                "additions:greedycraft-durasteel_block@0"
            ]
        },
        {
            "x": -3,
            "y": -3,
            "z": -2,
            "elements": [
                "casings_all"
            ]
        },
        {
            "x": 1,
            "y": 1,
            "z": 1,
            "elements": [
                "casings_upgrade"
            ]
        },
        {
            "x": 2,
            "y": 1,
            "z": 1,
            "elements": [
                "casings_upgrade"
            ]
        },
        {
            "x": 5,
            "y": 5,
            "z": 3,
            "elements": [
                "casings_all"
            ]
        },
        {
            "x": 7,
            "y": 1,
            "z": 1,
            "elements": [
                "casings_all"
            ]
        },
        {
            "x": -5,
            "y": 2,
            "z": 1,
            "elements": [
                "casings_all"
            ]
        },
        {
            "x": 1,
            "y": -4,
            "z": -2,
            "elements": [
                "casings_all"
            ]
        },
        {
            "x": 0,
            "y": 2,
            "z": 1,
            "elements": [
                "casings_upgrade"
            ]
        }
    ]
}
