{
    "registryname": "miner_dark",
    "localizedname": "黑暗矿机",
    "requires-blueprint": true,
    "failure-action": "still",
    "color": "7f8284",
    "modifiers": [
        {
            "elements": "modularmachinery:blockcasing@1",
            "x": 0,
            "y": -1,
            "z": 0,
            "description": "将控制器下方的紧挨着的方块换成此方块以提高25%产品产出率！",
            "modifier": {
                "io": "output",
                "target": "item",
                "operation": 1,
                "multiplier": 1.25,
                "affectChance": true
            }
        },
        {
            "elements": "modularmachinery:blockcasing@2",
            "x": 0,
            "y": -1,
            "z": 0,
            "description": "将控制器下方的紧挨着的方块换成此方块以提高50%产品产出率！",
            "modifier": {
                "io": "output",
                "target": "item",
                "operation": 1,
                "multiplier": 1.5,
                "affectChance": true
            }
        },
        {
            "elements": "modularmachinery:blockcasing@3",
            "x": 0,
            "y": -1,
            "z": 0,
            "description": "将控制器下方的紧挨着的方块换成此方块以提高100%产品产出率！",
            "modifier": {
                "io": "output",
                "target": "item",
                "operation": 1,
                "multiplier": 2.0,
                "affectChance": true
            }
        },
        {
            "elements": "modularmachinery:blockcasing@5",
            "x": 0,
            "y": 1,
            "z": 0,
            "description": "将控制器下方的紧挨着的方块换成此方块以提高150%产品产出率！",
            "modifier": {
                "io": "output",
                "target": "item",
                "operation": 1,
                "multiplier": 2.5,
                "affectChance": true
            }
        }
    ],
    "parts": [
        {
            "x": 2,
            "y": 3,
            "z": 0,
            "elements": [
                "minecraft:iron_bars@0"
            ]
        },
        {
            "x": -3,
            "y": 0,
            "z": 4,
            "elements": [
                "abyssalcraft:ingotblock@3"
            ]
        },
        {
            "x": 2,
            "y": 3,
            "z": 1,
            "elements": [
                "jaopca:block_glasshardenedabyssalnite@0"
            ]
        },
        {
            "x": -4,
            "y": 2,
            "z": 1,
            "elements": [
                "abyssalcraft:dbstairs@0"
            ]
        },
        {
            "x": 4,
            "y": 2,
            "z": 1,
            "elements": [
                "abyssalcraft:dbstairs@1"
            ]
        },
        {
            "x": 2,
            "y": 3,
            "z": 2,
            "elements": [
                "minecraft:iron_bars@0"
            ]
        },
        {
            "x": -4,
            "y": -1,
            "z": -2,
            "elements": [
                "abyssalcraft:stone@0"
            ]
        },
        {
            "x": -1,
            "y": -1,
            "z": 1,
            "elements": [
                "modularmachinery:blockcasing@4"
            ]
        },
        {
            "x": -1,
            "y": -1,
            "z": 2,
            "elements": [
                "extrabotany:blockshadowium@0"
            ]
        },
        {
            "x": 0,
            "y": 4,
            "z": 1,
            "elements": [
                "abyssalcraft:darkbrickslab1@0"
            ]
        },
        {
            "x": -4,
            "y": -1,
            "z": 1,
            "elements": [
                "abyssalcraft:darkstone_brick@0"
            ]
        },
        {
            "x": -3,
            "y": 0,
            "z": -2,
            "elements": [
                "abyssalcraft:stone@0"
            ]
        },
        {
            "x": -1,
            "y": -1,
            "z": 0,
            "elements": [
                "extrabotany:blockshadowium@0"
            ]
        },
        {
            "x": 0,
            "y": 0,
            "z": 5,
            "elements": [
                "abyssalcraft:darkstone_brick@0"
            ]
        },
        {
            "x": 0,
            "y": 0,
            "z": 2,
            "elements": [
                "casings_all"
            ]
        },
        {
            "x": 1,
            "y": 2,
            "z": 3,
            "elements": [
                "abyssalcraft:darkbrickslab1@8"
            ]
        },
        {
            "x": 1,
            "y": 2,
            "z": 2,
            "elements": [
                "abyssalcraft:darkstone_brick@0"
            ]
        },
        {
            "x": -1,
            "y": 3,
            "z": 3,
            "elements": [
                "minecraft:iron_bars@0"
            ]
        },
        {
            "x": 1,
            "y": 2,
            "z": 1,
            "elements": [
                "abyssalcraft:darkstone_brick@0"
            ]
        },
        {
            "x": -1,
            "y": 3,
            "z": 2,
            "elements": [
                "minecraft:iron_bars@0"
            ]
        },
        {
            "x": 0,
            "y": 0,
            "z": -3,
            "elements": [
                "abyssalcraft:darkstone_brick@0"
            ]
        },
        {
            "x": 1,
            "y": 2,
            "z": 0,
            "elements": [
                "abyssalcraft:darkstone_brick@0"
            ]
        },
        {
            "x": -1,
            "y": 3,
            "z": 1,
            "elements": [
                "jaopca:block_glasshardenedabyssalnite@0"
            ]
        },
        {
            "x": 1,
            "y": 2,
            "z": -1,
            "elements": [
                "abyssalcraft:darkbrickslab1@8"
            ]
        },
        {
            "x": -1,
            "y": 3,
            "z": 0,
            "elements": [
                "minecraft:iron_bars@0"
            ]
        },
        {
            "x": -1,
            "y": 3,
            "z": -1,
            "elements": [
                "minecraft:iron_bars@0"
            ]
        },
        {
            "x": 1,
            "y": -1,
            "z": 2,
            "elements": [
                "extrabotany:blockshadowium@0"
            ]
        },
        {
            "x": 1,
            "y": -1,
            "z": 1,
            "elements": [
                "modularmachinery:blockcasing@4"
            ]
        },
        {
            "x": 1,
            "y": -1,
            "z": 0,
            "elements": [
                "extrabotany:blockshadowium@0"
            ]
        },
        {
            "x": 0,
            "y": 3,
            "z": -1,
            "elements": [
                "jaopca:block_glasshardenedabyssalnite@0"
            ]
        },
        {
            "x": 0,
            "y": 3,
            "z": 1,
            "elements": [
                "gct_mobs:sanite_block@0"
            ]
        },
        {
            "x": 0,
            "y": 3,
            "z": 0,
            "elements": [
                "jaopca:block_glasshardenedabyssalnite@0"
            ]
        },
        {
            "x": 0,
            "y": 3,
            "z": 3,
            "elements": [
                "jaopca:block_glasshardenedabyssalnite@0"
            ]
        },
        {
            "x": 0,
            "y": 3,
            "z": 2,
            "elements": [
                "jaopca:block_glasshardenedabyssalnite@0"
            ]
        },
        {
            "x": 1,
            "y": 1,
            "z": 0,
            "elements": [
                "extrabotany:blockshadowium@0"
            ]
        },
        {
            "x": 1,
            "y": 1,
            "z": 2,
            "elements": [
                "extrabotany:blockshadowium@0"
            ]
        },
        {
            "x": 1,
            "y": 1,
            "z": 1,
            "elements": [
                "casings_all"
            ]
        },
        {
            "x": 3,
            "y": 2,
            "z": 1,
            "elements": [
                "abyssalcraft:darkstone_brick@0"
            ]
        },
        {
            "x": 4,
            "y": 0,
            "z": 1,
            "elements": [
                "abyssalcraft:darkstone_brick@0"
            ]
        },
        {
            "x": -4,
            "y": -1,
            "z": 4,
            "elements": [
                "abyssalcraft:ingotblock@3"
            ]
        },
        {
            "x": -2,
            "y": -1,
            "z": 4,
            "elements": [
                "abyssalcraft:ingotblock@3"
            ]
        },
        {
            "x": -2,
            "y": -1,
            "z": -2,
            "elements": [
                "abyssalcraft:stone@0"
            ]
        },
        {
            "x": -2,
            "y": 2,
            "z": 0,
            "elements": [
                "abyssalcraft:darkbrickslab1@8"
            ]
        },
        {
            "x": -2,
            "y": 2,
            "z": 2,
            "elements": [
                "abyssalcraft:darkbrickslab1@8"
            ]
        },
        {
            "x": -2,
            "y": 2,
            "z": 1,
            "elements": [
                "abyssalcraft:darkstone_brick@0"
            ]
        },
        {
            "x": 1,
            "y": 0,
            "z": 2,
            "elements": [
                "extrabotany:blockshadowium@0"
            ]
        },
        {
            "x": 1,
            "y": 0,
            "z": 1,
            "elements": [
                "casings_all"
            ]
        },
        {
            "x": 1,
            "y": 0,
            "z": 0,
            "elements": [
                "extrabotany:blockshadowium@0"
            ]
        },
        {
            "x": 0,
            "y": 2,
            "z": 5,
            "elements": [
                "abyssalcraft:dbstairs@3"
            ]
        },
        {
            "x": 0,
            "y": -1,
            "z": -3,
            "elements": [
                "abyssalcraft:darkstone_brick@0"
            ]
        },
        {
            "x": 3,
            "y": -1,
            "z": 5,
            "elements": [
                "gct_aby:densedarkstone@0"
            ]
        },
        {
            "x": 3,
            "y": -1,
            "z": 3,
            "elements": [
                "gct_aby:densedarkstone@0"
            ]
        },
        {
            "x": 3,
            "y": -1,
            "z": 4,
            "elements": [
                "gct_aby:densedarkstone@0"
            ]
        },
        {
            "x": 3,
            "y": -1,
            "z": -1,
            "elements": [
                "abyssalcraft:ingotblock@2"
            ]
        },
        {
            "x": -1,
            "y": 1,
            "z": 2,
            "elements": [
                "extrabotany:blockshadowium@0"
            ]
        },
        {
            "x": -1,
            "y": 1,
            "z": 1,
            "elements": [
                "casings_all"
            ]
        },
        {
            "x": 3,
            "y": -1,
            "z": -3,
            "elements": [
                "abyssalcraft:ingotblock@2"
            ]
        },
        {
            "x": -1,
            "y": 1,
            "z": 0,
            "elements": [
                "extrabotany:blockshadowium@0"
            ]
        },
        {
            "x": 3,
            "y": -1,
            "z": -2,
            "elements": [
                "abyssalcraft:ingotblock@2"
            ]
        },
        {
            "x": 0,
            "y": 2,
            "z": 2,
            "elements": [
                "abyssalcraft:darkstone_brick@0"
            ]
        },
        {
            "x": 0,
            "y": 2,
            "z": 1,
            "elements": [
                "abyssalcraft:darkstone_brick@0"
            ]
        },
        {
            "x": -2,
            "y": 3,
            "z": 2,
            "elements": [
                "minecraft:iron_bars@0"
            ]
        },
        {
            "x": 1,
            "y": 3,
            "z": 3,
            "elements": [
                "minecraft:iron_bars@0"
            ]
        },
        {
            "x": 0,
            "y": 2,
            "z": 4,
            "elements": [
                "abyssalcraft:darkstone_brick@0"
            ]
        },
        {
            "x": 0,
            "y": 2,
            "z": 3,
            "elements": [
                "abyssalcraft:darkstone_brick@0"
            ]
        },
        {
            "x": 0,
            "y": 2,
            "z": -2,
            "elements": [
                "abyssalcraft:darkstone_brick@0"
            ]
        },
        {
            "x": 0,
            "y": 2,
            "z": -3,
            "elements": [
                "abyssalcraft:dbstairs@2"
            ]
        },
        {
            "x": 0,
            "y": 2,
            "z": 0,
            "elements": [
                "abyssalcraft:darkstone_brick@0"
            ]
        },
        {
            "x": -2,
            "y": 3,
            "z": 1,
            "elements": [
                "jaopca:block_glasshardenedabyssalnite@0"
            ]
        },
        {
            "x": 0,
            "y": 2,
            "z": -1,
            "elements": [
                "abyssalcraft:darkstone_brick@0"
            ]
        },
        {
            "x": -2,
            "y": 3,
            "z": 0,
            "elements": [
                "minecraft:iron_bars@0"
            ]
        },
        {
            "x": 1,
            "y": 3,
            "z": 1,
            "elements": [
                "jaopca:block_glasshardenedabyssalnite@0"
            ]
        },
        {
            "x": 1,
            "y": 3,
            "z": 2,
            "elements": [
                "minecraft:iron_bars@0"
            ]
        },
        {
            "x": 1,
            "y": 3,
            "z": -1,
            "elements": [
                "minecraft:iron_bars@0"
            ]
        },
        {
            "x": 1,
            "y": 3,
            "z": 0,
            "elements": [
                "minecraft:iron_bars@0"
            ]
        },
        {
            "x": 4,
            "y": 1,
            "z": 1,
            "elements": [
                "abyssalcraft:darkstone_brick@0"
            ]
        },
        {
            "x": -4,
            "y": 1,
            "z": 1,
            "elements": [
                "abyssalcraft:darkstone_brick@0"
            ]
        },
        {
            "x": 0,
            "y": -1,
            "z": 0,
            "elements": [
                "modularmachinery:blockcasing@4"
            ]
        },
        {
            "x": 0,
            "y": -1,
            "z": 2,
            "elements": [
                "modularmachinery:blockcasing@4"
            ]
        },
        {
            "x": 0,
            "y": -1,
            "z": 5,
            "elements": [
                "abyssalcraft:darkstone_brick@0"
            ]
        },
        {
            "x": 2,
            "y": 2,
            "z": 0,
            "elements": [
                "abyssalcraft:darkbrickslab1@8"
            ]
        },
        {
            "x": 2,
            "y": 2,
            "z": 1,
            "elements": [
                "abyssalcraft:darkstone_brick@0"
            ]
        },
        {
            "x": 2,
            "y": 2,
            "z": 2,
            "elements": [
                "abyssalcraft:darkbrickslab1@8"
            ]
        },
        {
            "x": -1,
            "y": 0,
            "z": 2,
            "elements": [
                "extrabotany:blockshadowium@0"
            ]
        },
        {
            "x": -1,
            "y": 0,
            "z": 1,
            "elements": [
                "casings_all"
            ]
        },
        {
            "x": 3,
            "y": 0,
            "z": 4,
            "elements": [
                "gct_aby:densedarkstone@0"
            ]
        },
        {
            "x": -1,
            "y": 0,
            "z": 0,
            "elements": [
                "extrabotany:blockshadowium@0"
            ]
        },
        {
            "x": 3,
            "y": 0,
            "z": -2,
            "elements": [
                "abyssalcraft:ingotblock@2"
            ]
        },
        {
            "x": 2,
            "y": -1,
            "z": 4,
            "elements": [
                "gct_aby:densedarkstone@0"
            ]
        },
        {
            "x": 2,
            "y": -1,
            "z": -2,
            "elements": [
                "abyssalcraft:ingotblock@2"
            ]
        },
        {
            "x": -4,
            "y": 0,
            "z": 1,
            "elements": [
                "abyssalcraft:darkstone_brick@0"
            ]
        },
        {
            "x": 0,
            "y": 1,
            "z": -3,
            "elements": [
                "abyssalcraft:darkstone_brick@0"
            ]
        },
        {
            "x": -1,
            "y": 2,
            "z": 1,
            "elements": [
                "abyssalcraft:darkstone_brick@0"
            ]
        },
        {
            "x": -1,
            "y": 2,
            "z": 0,
            "elements": [
                "abyssalcraft:darkstone_brick@0"
            ]
        },
        {
            "x": -3,
            "y": 2,
            "z": 1,
            "elements": [
                "abyssalcraft:darkstone_brick@0"
            ]
        },
        {
            "x": -1,
            "y": 2,
            "z": -1,
            "elements": [
                "abyssalcraft:darkbrickslab1@8"
            ]
        },
        {
            "x": -1,
            "y": 2,
            "z": 3,
            "elements": [
                "abyssalcraft:darkbrickslab1@8"
            ]
        },
        {
            "x": -1,
            "y": 2,
            "z": 2,
            "elements": [
                "abyssalcraft:darkstone_brick@0"
            ]
        },
        {
            "x": -3,
            "y": -1,
            "z": -1,
            "elements": [
                "abyssalcraft:stone@0"
            ]
        },
        {
            "x": 4,
            "y": -1,
            "z": 4,
            "elements": [
                "gct_aby:densedarkstone@0"
            ]
        },
        {
            "x": -3,
            "y": -1,
            "z": -3,
            "elements": [
                "abyssalcraft:stone@0"
            ]
        },
        {
            "x": -3,
            "y": -1,
            "z": -2,
            "elements": [
                "abyssalcraft:stone@0"
            ]
        },
        {
            "x": 4,
            "y": -1,
            "z": -2,
            "elements": [
                "abyssalcraft:ingotblock@2"
            ]
        },
        {
            "x": 0,
            "y": 1,
            "z": 0,
            "elements": [
                "casings_all"
            ]
        },
        {
            "x": -3,
            "y": -1,
            "z": 3,
            "elements": [
                "abyssalcraft:ingotblock@3"
            ]
        },
        {
            "x": 4,
            "y": -1,
            "z": 1,
            "elements": [
                "abyssalcraft:darkstone_brick@0"
            ]
        },
        {
            "x": 0,
            "y": 1,
            "z": 2,
            "elements": [
                "casings_all"
            ]
        },
        {
            "x": -3,
            "y": -1,
            "z": 4,
            "elements": [
                "abyssalcraft:ingotblock@3"
            ]
        },
        {
            "x": -3,
            "y": -1,
            "z": 5,
            "elements": [
                "abyssalcraft:ingotblock@3"
            ]
        },
        {
            "x": 0,
            "y": 1,
            "z": 5,
            "elements": [
                "abyssalcraft:darkstone_brick@0"
            ]
        }
    ]}