{
    "registryname": "solid_centrifuge",
    "localizedname": "固体离心机",
    "requires-blueprint": true,
    "failure-action": "still",
    "color": "42a5f5",
    "modifiers": [
        {
            "elements": "modularmachinery:blockcasing@1",
            "x": 0,
            "y": 1,
            "z": 0,
            "description": "将控制器上方的紧挨着的方块换成此方块以提高25%产品产出率！",
            "modifier": {
                "io": "output",
                "target": "item",
                "operation": 1,
                "multiplier": 1.25,
                "affectChance": true
            }
        },
        {
            "elements": "modularmachinery:blockcasing@2",
            "x": 0,
            "y": 1,
            "z": 0,
            "description": "将控制器上方的紧挨着的方块换成此方块以提高50%产品产出率！",
            "modifier": {
                "io": "output",
                "target": "item",
                "operation": 1,
                "multiplier": 1.5,
                "affectChance": true
            }
        },
        {
            "elements": "modularmachinery:blockcasing@3",
            "x": 0,
            "y": 1,
            "z": 0,
            "description": "将控制器上方的紧挨着的方块换成此方块以提高100%产品产出率！",
            "modifier": {
                "io": "output",
                "target": "item",
                "operation": 1,
                "multiplier": 2.0,
                "affectChance": true
            }
        },
        {
            "elements": "modularmachinery:blockcasing@5",
            "x": 0,
            "y": 1,
            "z": 0,
            "description": "将控制器上方的紧挨着的方块换成此方块以提高150%产品产出率！",
            "modifier": {
                "io": "output",
                "target": "item",
                "operation": 1,
                "multiplier": 2.5,
                "affectChance": true
            }
        }
    ],
    "parts": [
        {
            "x": -1,
            "y": 0,
            "z": 0,
            "elements": "casings_all"
        },
        {
            "x": 2,
            "y": 4,
            "z": 2,
            "elements": ["minecraft:glass@0"]
        },
        {
            "x": 1,
            "y": 2,
            "z": 1,
            "elements": ["minecraft:water"]
        },
        {
            "x": 2,
            "y": 2,
            "z": 1,
            "elements": ["minecraft:glass@0"]
        },
        {
            "x": 1,
            "y": 0,
            "z": 0,
            "elements": "casings_all"
        },
        {
            "x": -1,
            "y": 0,
            "z": 4,
            "elements": "casings_all"
        },
        {
            "x": 0,
            "y": 0,
            "z": 4,
            "elements": "casings_all"
        },
        {
            "x": 1,
            "y": 0,
            "z": 4,
            "elements": "casings_all"
        },
        {
            "x": -2,
            "y": 3,
            "z": 1,
            "elements": ["minecraft:glass@0"]
        },
        {
            "x": -1,
            "y": 5,
            "z": 2,
            "elements": ["minecraft:glass@0"]
        },
        {
            "x": -1,
            "y": 3,
            "z": 1,
            "elements": ["minecraft:water"]
        },
        {
            "x": 0,
            "y": 5,
            "z": 2,
            "elements": ["modularmachinery:blockcasing@4"]
        },
        {
            "x": 1,
            "y": -1,
            "z": 0,
            "elements": "casings_all"
        },
        {
            "x": 0,
            "y": -1,
            "z": 0,
            "elements": "casings_all"
        },
        {
            "x": 1,
            "y": 5,
            "z": 2,
            "elements": ["minecraft:glass@0"]
        },
        {
            "x": 0,
            "y": 3,
            "z": 1,
            "elements": ["minecraft:water"]
        },
        {
            "x": -1,
            "y": 1,
            "z": 0,
            "elements": "casings_all"
        },
        {
            "x": 1,
            "y": 3,
            "z": 1,
            "elements": ["minecraft:water"]
        },
        {
            "x": 0,
            "y": 1,
            "z": 0,
            "elements": "casings_all"
        },
        {
            "x": -1,
            "y": -1,
            "z": 0,
            "elements": "casings_all"
        },
        {
            "x": 2,
            "y": 3,
            "z": 1,
            "elements": ["minecraft:glass@0"]
        },
        {
            "x": 1,
            "y": 1,
            "z": 0,
            "elements": "casings_all"
        },
        {
            "x": -2,
            "y": -1,
            "z": 3,
            "elements": "casings_all"
        },
        {
            "x": -1,
            "y": 1,
            "z": 4,
            "elements": "casings_all"
        },
        {
            "x": 0,
            "y": 1,
            "z": 4,
            "elements": "casings_all"
        },
        {
            "x": -1,
            "y": -1,
            "z": 3,
            "elements": ["modularmachinery:blockcasing@4"]
        },
        {
            "x": 0,
            "y": -1,
            "z": 3,
            "elements": ["modularmachinery:blockcasing@4"]
        },
        {
            "x": 1,
            "y": 1,
            "z": 4,
            "elements": "casings_all"
        },
        {
            "x": 1,
            "y": -1,
            "z": 3,
            "elements": ["modularmachinery:blockcasing@4"]
        },
        {
            "x": 2,
            "y": -1,
            "z": 3,
            "elements": "casings_all"
        },
        {
            "x": -2,
            "y": 4,
            "z": 1,
            "elements": ["minecraft:glass@0"]
        },
        {
            "x": -1,
            "y": 4,
            "z": 1,
            "elements": ["minecraft:water"]
        },
        {
            "x": 0,
            "y": 4,
            "z": 1,
            "elements": ["minecraft:water"]
        },
        {
            "x": -1,
            "y": 2,
            "z": 0,
            "elements": ["minecraft:glass@0"]
        },
        {
            "x": 1,
            "y": 4,
            "z": 1,
            "elements": ["minecraft:water"]
        },
        {
            "x": 0,
            "y": 2,
            "z": 0,
            "elements": ["minecraft:glass@0"]
        },
        {
            "x": 2,
            "y": 4,
            "z": 1,
            "elements": ["minecraft:glass@0"]
        },
        {
            "x": 1,
            "y": 2,
            "z": 0,
            "elements": ["minecraft:glass@0"]
        },
        {
            "x": -2,
            "y": 0,
            "z": 3,
            "elements": "casings_all"
        },
        {
            "x": -1,
            "y": 2,
            "z": 4,
            "elements": ["minecraft:glass@0"]
        },
        {
            "x": 0,
            "y": 2,
            "z": 4,
            "elements": ["minecraft:glass@0"]
        },
        {
            "x": 1,
            "y": 2,
            "z": 4,
            "elements": ["minecraft:glass@0"]
        },
        {
            "x": 2,
            "y": 0,
            "z": 3,
            "elements": "casings_all"
        },
        {
            "x": -1,
            "y": 5,
            "z": 1,
            "elements": ["minecraft:glass@0"]
        },
        {
            "x": -1,
            "y": 3,
            "z": 0,
            "elements": ["minecraft:glass@0"]
        },
        {
            "x": 0,
            "y": 5,
            "z": 1,
            "elements": ["minecraft:glass@0"]
        },
        {
            "x": 1,
            "y": 5,
            "z": 1,
            "elements": ["minecraft:glass@0"]
        },
        {
            "x": 0,
            "y": 3,
            "z": 0,
            "elements": ["minecraft:glass@0"]
        },
        {
            "x": 1,
            "y": 3,
            "z": 0,
            "elements": ["minecraft:glass@0"]
        },
        {
            "x": -2,
            "y": 1,
            "z": 3,
            "elements": "casings_all"
        },
        {
            "x": -1,
            "y": 3,
            "z": 4,
            "elements": ["minecraft:glass@0"]
        },
        {
            "x": 0,
            "y": 3,
            "z": 4,
            "elements": ["minecraft:glass@0"]
        },
        {
            "x": -2,
            "y": -1,
            "z": 2,
            "elements": "casings_all"
        },
        {
            "x": -1,
            "y": 1,
            "z": 3,
            "elements": ["modularmachinery:blockcasing@4"]
        },
        {
            "x": 1,
            "y": 3,
            "z": 4,
            "elements": ["minecraft:glass@0"]
        },
        {
            "x": 0,
            "y": 1,
            "z": 3,
            "elements": ["modularmachinery:blockcasing@4"]
        },
        {
            "x": -1,
            "y": -1,
            "z": 2,
            "elements": ["modularmachinery:blockcasing@4"]
        },
        {
            "x": 0,
            "y": -1,
            "z": 2,
            "elements": ["modularmachinery:blockcasing@4"]
        },
        {
            "x": 1,
            "y": 1,
            "z": 3,
            "elements": ["modularmachinery:blockcasing@4"]
        },
        {
            "x": 2,
            "y": 1,
            "z": 3,
            "elements": "casings_all"
        },
        {
            "x": 1,
            "y": -1,
            "z": 2,
            "elements": ["modularmachinery:blockcasing@4"]
        },
        {
            "x": 2,
            "y": -1,
            "z": 2,
            "elements": "casings_all"
        },
        {
            "x": -1,
            "y": 4,
            "z": 0,
            "elements": ["minecraft:glass@0"]
        },
        {
            "x": 0,
            "y": 4,
            "z": 0,
            "elements": ["minecraft:glass@0"]
        },
        {
            "x": 1,
            "y": 4,
            "z": 0,
            "elements": ["minecraft:glass@0"]
        },
        {
            "x": -2,
            "y": 2,
            "z": 3,
            "elements": ["minecraft:glass@0"]
        },
        {
            "x": -1,
            "y": 4,
            "z": 4,
            "elements": ["minecraft:glass@0"]
        },
        {
            "x": 0,
            "y": 4,
            "z": 4,
            "elements": ["minecraft:glass@0"]
        },
        {
            "x": -2,
            "y": 0,
            "z": 2,
            "elements": "casings_all"
        },
        {
            "x": -1,
            "y": 2,
            "z": 3,
            "elements": ["minecraft:water"]
        },
        {
            "x": 1,
            "y": 4,
            "z": 4,
            "elements": ["minecraft:glass@0"]
        },
        {
            "x": 0,
            "y": 2,
            "z": 3,
            "elements": ["minecraft:water"]
        },
        {
            "x": 1,
            "y": 2,
            "z": 3,
            "elements": ["minecraft:water"]
        },
        {
            "x": 2,
            "y": 2,
            "z": 3,
            "elements": ["minecraft:glass@0"]
        },
        {
            "x": 2,
            "y": 0,
            "z": 2,
            "elements": "casings_all"
        },
        {
            "x": -2,
            "y": 3,
            "z": 3,
            "elements": ["minecraft:glass@0"]
        },
        {
            "x": -2,
            "y": 1,
            "z": 2,
            "elements": "casings_all"
        },
        {
            "x": -1,
            "y": 3,
            "z": 3,
            "elements": ["minecraft:water"]
        },
        {
            "x": 0,
            "y": 3,
            "z": 3,
            "elements": ["minecraft:water"]
        },
        {
            "x": -2,
            "y": -1,
            "z": 1,
            "elements": "casings_all"
        },
        {
            "x": -1,
            "y": 1,
            "z": 2,
            "elements": ["modularmachinery:blockcasing@4"]
        },
        {
            "x": 1,
            "y": 3,
            "z": 3,
            "elements": ["minecraft:water"]
        },
        {
            "x": 0,
            "y": 1,
            "z": 2,
            "elements": ["modularmachinery:blockcasing@4"]
        },
        {
            "x": -1,
            "y": -1,
            "z": 1,
            "elements": ["modularmachinery:blockcasing@4"]
        },
        {
            "x": 0,
            "y": -1,
            "z": 1,
            "elements": ["modularmachinery:blockcasing@4"]
        },
        {
            "x": 2,
            "y": 3,
            "z": 3,
            "elements": ["minecraft:glass@0"]
        },
        {
            "x": 1,
            "y": 1,
            "z": 2,
            "elements": ["modularmachinery:blockcasing@4"]
        },
        {
            "x": 2,
            "y": 1,
            "z": 2,
            "elements": "casings_all"
        },
        {
            "x": 1,
            "y": -1,
            "z": 1,
            "elements": ["modularmachinery:blockcasing@4"]
        },
        {
            "x": 2,
            "y": -1,
            "z": 1,
            "elements": "casings_all"
        },
        {
            "x": -2,
            "y": 4,
            "z": 3,
            "elements": ["minecraft:glass@0"]
        },
        {
            "x": -2,
            "y": 2,
            "z": 2,
            "elements": ["minecraft:glass@0"]
        },
        {
            "x": -1,
            "y": 4,
            "z": 3,
            "elements": ["minecraft:water"]
        },
        {
            "x": 0,
            "y": 4,
            "z": 3,
            "elements": ["minecraft:water"]
        },
        {
            "x": -2,
            "y": 0,
            "z": 1,
            "elements": "casings_all"
        },
        {
            "x": -1,
            "y": 2,
            "z": 2,
            "elements": ["minecraft:water"]
        },
        {
            "x": 1,
            "y": 4,
            "z": 3,
            "elements": ["minecraft:water"]
        },
        {
            "x": 0,
            "y": 2,
            "z": 2,
            "elements": ["thermalfoundation:storage_alloy@0"]
        },
        {
            "x": 2,
            "y": 4,
            "z": 3,
            "elements": ["minecraft:glass@0"]
        },
        {
            "x": 1,
            "y": 2,
            "z": 2,
            "elements": ["minecraft:water"]
        },
        {
            "x": 2,
            "y": 2,
            "z": 2,
            "elements": ["minecraft:glass@0"]
        },
        {
            "x": 2,
            "y": 0,
            "z": 1,
            "elements": "casings_all"
        },
        {
            "x": -2,
            "y": 3,
            "z": 2,
            "elements": ["minecraft:glass@0"]
        },
        {
            "x": -1,
            "y": 5,
            "z": 3,
            "elements": ["minecraft:glass@0"]
        },
        {
            "x": -2,
            "y": 1,
            "z": 1,
            "elements": "casings_all"
        },
        {
            "x": -1,
            "y": 3,
            "z": 2,
            "elements": ["minecraft:water"]
        },
        {
            "x": 0,
            "y": 5,
            "z": 3,
            "elements": ["minecraft:glass@0"]
        },
        {
            "x": 1,
            "y": 5,
            "z": 3,
            "elements": ["minecraft:glass@0"]
        },
        {
            "x": 0,
            "y": 3,
            "z": 2,
            "elements": ["thermalfoundation:storage_alloy@0"]
        },
        {
            "x": -1,
            "y": 1,
            "z": 1,
            "elements": ["modularmachinery:blockcasing@4"]
        },
        {
            "x": 1,
            "y": 3,
            "z": 2,
            "elements": ["minecraft:water"]
        },
        {
            "x": 0,
            "y": 1,
            "z": 1,
            "elements": ["modularmachinery:blockcasing@4"]
        },
        {
            "x": 2,
            "y": 3,
            "z": 2,
            "elements": ["minecraft:glass@0"]
        },
        {
            "x": 1,
            "y": 1,
            "z": 1,
            "elements": ["modularmachinery:blockcasing@4"]
        },
        {
            "x": 2,
            "y": 1,
            "z": 1,
            "elements": "casings_all"
        },
        {
            "x": -1,
            "y": -1,
            "z": 4,
            "elements": "casings_all"
        },
        {
            "x": 0,
            "y": -1,
            "z": 4,
            "elements": "casings_all"
        },
        {
            "x": 1,
            "y": -1,
            "z": 4,
            "elements": "casings_all"
        },
        {
            "x": -2,
            "y": 4,
            "z": 2,
            "elements": ["minecraft:glass@0"]
        },
        {
            "x": -2,
            "y": 2,
            "z": 1,
            "elements": ["minecraft:glass@0"]
        },
        {
            "x": -1,
            "y": 4,
            "z": 2,
            "elements": ["minecraft:water"]
        },
        {
            "x": 0,
            "y": 4,
            "z": 2,
            "elements": ["thermalfoundation:storage_alloy@0"]
        },
        {
            "x": -1,
            "y": 2,
            "z": 1,
            "elements": ["minecraft:water"]
        },
        {
            "x": 1,
            "y": 4,
            "z": 2,
            "elements": ["minecraft:water"]
        },
        {
            "x": 0,
            "y": 2,
            "z": 1,
            "elements": ["minecraft:water"]
        }
    ]
}
