{
    "registryname": "vethea_enchanter",
    "localizedname": "梦魇附魔机",
    "requires-blueprint": false,
    "failure-action": "still",
    "color": "379fb4",
    "parts": [
        {
            "x": -4,
            "y": 0,
            "z": 4,
            "elements": [
                "divinerpg:hyrewood_log@0"
            ]
        },
        {
            "x": 3,
            "y": 0,
            "z": -4,
            "elements": [
                "divinerpg:dream_stone@0"
            ]
        },
        {
            "x": -1,
            "y": 0,
            "z": 0,
            "elements": [
                "casings_all"
            ]
        },
        {
            "x": -2,
            "y": 2,
            "z": 5,
            "elements": [
                "divinerpg:dream_stone@0"
            ]
        },
        {
            "x": -1,
            "y": 2,
            "z": 5,
            "elements": [
                "divinerpg:dream_stone@0"
            ]
        },
        {
            "x": 0,
            "y": 2,
            "z": 5,
            "elements": [
                "divinerpg:dream_stone@0"
            ]
        },
        {
            "x": 4,
            "y": 2,
            "z": 1,
            "elements": [
                "divinerpg:dream_stone@0"
            ]
        },
        {
            "x": 1,
            "y": 2,
            "z": 5,
            "elements": [
                "divinerpg:dream_stone@0"
            ]
        },
        {
            "x": 4,
            "y": 2,
            "z": 5,
            "elements": [
                "divinerpg:fire_crystal@0"
            ]
        },
        {
            "x": 3,
            "y": 0,
            "z": 4,
            "elements": [
                "divinerpg:hyrewood_log@0"
            ]
        },
        {
            "x": -4,
            "y": 0,
            "z": -4,
            "elements": [
                "divinerpg:dream_stone@0"
            ]
        },
        {
            "x": 4,
            "y": 0,
            "z": 4,
            "elements": [
                "divinerpg:dream_stone@0"
            ]
        },
        {
            "x": -5,
            "y": 0,
            "z": -4,
            "elements": [
                "divinerpg:everstone@0"
            ]
        },
        {
            "x": -4,
            "y": 3,
            "z": 1,
            "elements": [
                "divinerpg:dream_stone@0"
            ]
        },
        {
            "x": -3,
            "y": 3,
            "z": 1,
            "elements": [
                "divinerpg:everstone@0"
            ]
        },
        {
            "x": -2,
            "y": 3,
            "z": 1,
            "elements": [
                "divinerpg:everstone@0"
            ]
        },
        {
            "x": 1,
            "y": -3,
            "z": -1,
            "elements": [
                "divinerpg:everstone@0"
            ]
        },
        {
            "x": 0,
            "y": -3,
            "z": -1,
            "elements": [
                "divinerpg:everstone@0"
            ]
        },
        {
            "x": -1,
            "y": 3,
            "z": 1,
            "elements": [
                "divinerpg:everstone@0"
            ]
        },
        {
            "x": -1,
            "y": -3,
            "z": -1,
            "elements": [
                "divinerpg:everstone@0"
            ]
        },
        {
            "x": 0,
            "y": -1,
            "z": 0,
            "nbt": {"id":"divinerpg:te_infusion_table","ForgeCaps":{"abyssalcraft:itemtransfer":{"configurations":[],"isRunning":"0b"}},"Items":[{"Slot":"0b","id":"minecraft:air","Count":"2b","Damage":"15s"},{"Slot":"1b","id":"minecraft:air","Count":"2b","Damage":"15s"},{"Slot":"2b","id":"minecraft:air","Count":"2b","Damage":"15s"}]},
            "elements": [
                "divinerpg:infusion_table@0"
            ]
        },
        {
            "x": 0,
            "y": 3,
            "z": 1,
            "elements": [
                "divinerpg:everstone@0"
            ]
        },
        {
            "x": -1,
            "y": 1,
            "z": 0,
            "elements": [
                "divinerpg:everstone@0"
            ]
        },
        {
            "x": -5,
            "y": 1,
            "z": 4,
            "elements": [
                "divinerpg:everstone@0"
            ]
        },
        {
            "x": 4,
            "y": -1,
            "z": -4,
            "elements": [
                "divinerpg:everstone@0"
            ]
        },
        {
            "x": 1,
            "y": 3,
            "z": 1,
            "elements": [
                "divinerpg:everstone@0"
            ]
        },
        {
            "x": 0,
            "y": 1,
            "z": 0,
            "elements": [
                "divinerpg:everstone@0"
            ]
        },
        {
            "x": 4,
            "y": 1,
            "z": -3,
            "elements": [
                "divinerpg:everstone@0"
            ]
        },
        {
            "x": 3,
            "y": -1,
            "z": -4,
            "elements": [
                "casings_all"
            ]
        },
        {
            "x": -2,
            "y": -3,
            "z": -1,
            "elements": [
                "divinerpg:everstone@0"
            ]
        },
        {
            "x": -1,
            "y": -1,
            "z": 0,
            "nbt": {"id":"divinerpg:te_infusion_table","ForgeCaps":{"abyssalcraft:itemtransfer":{"configurations":[],"isRunning":"0b"}},"Items":[{"Slot":"0b","id":"minecraft:air","Count":"2b","Damage":"15s"},{"Slot":"1b","id":"minecraft:air","Count":"2b","Damage":"15s"},{"Slot":"2b","id":"minecraft:air","Count":"2b","Damage":"15s"}]},
            "elements": [
                "divinerpg:infusion_table@0"
            ]
        },
        {
            "x": -4,
            "y": 1,
            "z": 4,
            "elements": [
                "divinerpg:dream_stone@0"
            ]
        },
        {
            "x": 3,
            "y": 1,
            "z": -3,
            "elements": [
                "divinerpg:dream_stone@0"
            ]
        },
        {
            "x": 2,
            "y": 3,
            "z": 1,
            "elements": [
                "divinerpg:everstone@0"
            ]
        },
        {
            "x": 3,
            "y": 3,
            "z": 1,
            "elements": [
                "divinerpg:dream_stone@0"
            ]
        },
        {
            "x": -2,
            "y": -3,
            "z": 2,
            "elements": [
                "divinerpg:everstone@0"
            ]
        },
        {
            "x": -1,
            "y": -3,
            "z": 2,
            "elements": [
                "divinerpg:everstone@0"
            ]
        },
        {
            "x": 0,
            "y": 3,
            "z": -2,
            "elements": [
                "divinerpg:everstone@0"
            ]
        },
        {
            "x": 0,
            "y": -3,
            "z": 2,
            "elements": [
                "divinerpg:everstone@0"
            ]
        },
        {
            "x": -1,
            "y": 3,
            "z": -2,
            "elements": [
                "divinerpg:everstone@0"
            ]
        },
        {
            "x": -4,
            "y": -1,
            "z": -4,
            "elements": [
                "casings_all"
            ]
        },
        {
            "x": 3,
            "y": 1,
            "z": 4,
            "elements": [
                "divinerpg:dream_stone@0"
            ]
        },
        {
            "x": 1,
            "y": -3,
            "z": 2,
            "elements": [
                "divinerpg:everstone@0"
            ]
        },
        {
            "x": 4,
            "y": 1,
            "z": 4,
            "elements": [
                "divinerpg:everstone@0"
            ]
        },
        {
            "x": -5,
            "y": -1,
            "z": -4,
            "elements": [
                "divinerpg:everstone@0"
            ]
        },
        {
            "x": -4,
            "y": 1,
            "z": -3,
            "elements": [
                "divinerpg:dream_stone@0"
            ]
        },
        {
            "x": -5,
            "y": 1,
            "z": -3,
            "elements": [
                "divinerpg:everstone@0"
            ]
        },
        {
            "x": -5,
            "y": 2,
            "z": 0,
            "elements": [
                "divinerpg:dream_stone@0"
            ]
        },
        {
            "x": 0,
            "y": -2,
            "z": 0,
            "elements": [
                "divinerpg:everstone@0"
            ]
        },
        {
            "x": -1,
            "y": 2,
            "z": 0,
            "elements": [
                "divinerpg:fire_crystal@0"
            ]
        },
        {
            "x": 4,
            "y": -2,
            "z": -4,
            "elements": [
                "divinerpg:everstone@0"
            ]
        },
        {
            "x": 4,
            "y": 0,
            "z": -3,
            "elements": [
                "divinerpg:dream_stone@0"
            ]
        },
        {
            "x": 3,
            "y": -2,
            "z": -4,
            "elements": [
                "divinerpg:dream_stone@0"
            ]
        },
        {
            "x": 0,
            "y": 2,
            "z": 0,
            "elements": [
                "divinerpg:fire_crystal@0"
            ]
        },
        {
            "x": -1,
            "y": -2,
            "z": 0,
            "elements": [
                "divinerpg:everstone@0"
            ]
        },
        {
            "x": 3,
            "y": 0,
            "z": -3,
            "elements": [
                "divinerpg:hyrewood_log@0"
            ]
        },
        {
            "x": 4,
            "y": 2,
            "z": 0,
            "elements": [
                "divinerpg:dream_stone@0"
            ]
        },
        {
            "x": -4,
            "y": -2,
            "z": -4,
            "elements": [
                "divinerpg:dream_stone@0"
            ]
        },
        {
            "x": -4,
            "y": 0,
            "z": -3,
            "elements": [
                "divinerpg:hyrewood_log@0"
            ]
        },
        {
            "x": -5,
            "y": -2,
            "z": -4,
            "elements": [
                "divinerpg:everstone@0"
            ]
        },
        {
            "x": -5,
            "y": 0,
            "z": -3,
            "elements": [
                "divinerpg:dream_stone@0"
            ]
        },
        {
            "x": -4,
            "y": 3,
            "z": 0,
            "elements": [
                "divinerpg:dream_stone@0"
            ]
        },
        {
            "x": -3,
            "y": 3,
            "z": 0,
            "elements": [
                "divinerpg:everstone@0"
            ]
        },
        {
            "x": -2,
            "y": 3,
            "z": 0,
            "elements": [
                "divinerpg:everstone@0"
            ]
        },
        {
            "x": 1,
            "y": -3,
            "z": 0,
            "elements": [
                "divinerpg:everstone@0"
            ]
        },
        {
            "x": 0,
            "y": -3,
            "z": 0,
            "elements": [
                "divinerpg:everstone@0"
            ]
        },
        {
            "x": -1,
            "y": 3,
            "z": 0,
            "elements": [
                "divinerpg:everstone@0"
            ]
        },
        {
            "x": 4,
            "y": -3,
            "z": -4,
            "elements": [
                "divinerpg:everstone@0"
            ]
        },
        {
            "x": -1,
            "y": -3,
            "z": 0,
            "elements": [
                "divinerpg:everstone@0"
            ]
        },
        {
            "x": 0,
            "y": 3,
            "z": 0,
            "elements": [
                "divinerpg:everstone@0"
            ]
        },
        {
            "x": -5,
            "y": 1,
            "z": 3,
            "elements": [
                "divinerpg:dream_stone@0"
            ]
        },
        {
            "x": 4,
            "y": -1,
            "z": -3,
            "elements": [
                "casings_all"
            ]
        },
        {
            "x": 3,
            "y": -3,
            "z": -4,
            "elements": [
                "divinerpg:dream_stone@0"
            ]
        },
        {
            "x": 1,
            "y": 3,
            "z": 0,
            "elements": [
                "divinerpg:everstone@0"
            ]
        },
        {
            "x": 4,
            "y": 1,
            "z": -2,
            "elements": [
                "divinerpg:dream_stone@0"
            ]
        },
        {
            "x": 3,
            "y": -1,
            "z": -3,
            "elements": [
                "divinerpg:hyrewood_log@0"
            ]
        },
        {
            "x": -2,
            "y": -3,
            "z": 0,
            "elements": [
                "divinerpg:everstone@0"
            ]
        },
        {
            "x": 2,
            "y": 3,
            "z": 0,
            "elements": [
                "divinerpg:everstone@0"
            ]
        },
        {
            "x": -1,
            "y": 3,
            "z": 4,
            "elements": [
                "divinerpg:dream_stone@0"
            ]
        },
        {
            "x": 3,
            "y": 3,
            "z": 0,
            "elements": [
                "divinerpg:dream_stone@0"
            ]
        },
        {
            "x": 0,
            "y": 3,
            "z": 4,
            "elements": [
                "divinerpg:dream_stone@0"
            ]
        },
        {
            "x": 1,
            "y": 3,
            "z": -1,
            "elements": [
                "divinerpg:dream_stone@0"
            ]
        },
        {
            "x": -2,
            "y": -3,
            "z": 1,
            "elements": [
                "divinerpg:everstone@0"
            ]
        },
        {
            "x": -1,
            "y": -3,
            "z": 1,
            "elements": [
                "divinerpg:everstone@0"
            ]
        },
        {
            "x": -5,
            "y": -3,
            "z": 5,
            "elements": [
                "divinerpg:everstone@0"
            ]
        },
        {
            "x": 0,
            "y": 3,
            "z": -1,
            "elements": [
                "divinerpg:everstone@0"
            ]
        },
        {
            "x": -4,
            "y": -3,
            "z": -4,
            "elements": [
                "divinerpg:dream_stone@0"
            ]
        },
        {
            "x": 0,
            "y": -3,
            "z": 1,
            "elements": [
                "divinerpg:everstone@0"
            ]
        },
        {
            "x": -1,
            "y": 3,
            "z": -1,
            "elements": [
                "divinerpg:everstone@0"
            ]
        },
        {
            "x": -4,
            "y": -3,
            "z": 5,
            "elements": [
                "divinerpg:dream_stone@0"
            ]
        },
        {
            "x": -5,
            "y": -3,
            "z": -4,
            "elements": [
                "divinerpg:everstone@0"
            ]
        },
        {
            "x": -4,
            "y": -1,
            "z": -3,
            "elements": [
                "divinerpg:hyrewood_log@0"
            ]
        },
        {
            "x": -2,
            "y": 3,
            "z": -1,
            "elements": [
                "divinerpg:dream_stone@0"
            ]
        },
        {
            "x": 1,
            "y": -3,
            "z": 1,
            "elements": [
                "divinerpg:everstone@0"
            ]
        },
        {
            "x": 4,
            "y": 1,
            "z": 3,
            "elements": [
                "divinerpg:dream_stone@0"
            ]
        },
        {
            "x": -5,
            "y": -1,
            "z": -3,
            "elements": [
                "casings_all"
            ]
        },
        {
            "x": -5,
            "y": 1,
            "z": -2,
            "elements": [
                "divinerpg:dream_stone@0"
            ]
        },
        {
            "x": 3,
            "y": -3,
            "z": 5,
            "elements": [
                "divinerpg:dream_stone@0"
            ]
        },
        {
            "x": 4,
            "y": -3,
            "z": 5,
            "elements": [
                "divinerpg:everstone@0"
            ]
        },
        {
            "x": 4,
            "y": -2,
            "z": -3,
            "elements": [
                "divinerpg:dream_stone@0"
            ]
        },
        {
            "x": 3,
            "y": -2,
            "z": -3,
            "elements": [
                "divinerpg:hyrewood_log@0"
            ]
        },
        {
            "x": 4,
            "y": 2,
            "z": -1,
            "elements": [
                "divinerpg:dream_stone@0"
            ]
        },
        {
            "x": -5,
            "y": -2,
            "z": 5,
            "elements": [
                "divinerpg:everstone@0"
            ]
        },
        {
            "x": -1,
            "y": -2,
            "z": 1,
            "elements": [
                "divinerpg:everstone@0"
            ]
        },
        {
            "x": 0,
            "y": -2,
            "z": 1,
            "elements": [
                "divinerpg:everstone@0"
            ]
        },
        {
            "x": -4,
            "y": -2,
            "z": 5,
            "elements": [
                "divinerpg:dream_stone@0"
            ]
        },
        {
            "x": -4,
            "y": -2,
            "z": -3,
            "elements": [
                "divinerpg:hyrewood_log@0"
            ]
        },
        {
            "x": -5,
            "y": -2,
            "z": -3,
            "elements": [
                "divinerpg:dream_stone@0"
            ]
        },
        {
            "x": -5,
            "y": 2,
            "z": -1,
            "elements": [
                "divinerpg:dream_stone@0"
            ]
        },
        {
            "x": 3,
            "y": -2,
            "z": 5,
            "elements": [
                "divinerpg:dream_stone@0"
            ]
        },
        {
            "x": 4,
            "y": -2,
            "z": 5,
            "elements": [
                "divinerpg:everstone@0"
            ]
        },
        {
            "x": 4,
            "y": -3,
            "z": -3,
            "elements": [
                "divinerpg:dream_stone@0"
            ]
        },
        {
            "x": 3,
            "y": -3,
            "z": -3,
            "elements": [
                "divinerpg:hyrewood_log@0"
            ]
        },
        {
            "x": -1,
            "y": 3,
            "z": 3,
            "elements": [
                "divinerpg:everstone@0"
            ]
        },
        {
            "x": 0,
            "y": 3,
            "z": 3,
            "elements": [
                "divinerpg:everstone@0"
            ]
        },
        {
            "x": -1,
            "y": -1,
            "z": 1,
            "nbt": {"id":"divinerpg:te_infusion_table","ForgeCaps":{"abyssalcraft:itemtransfer":{"configurations":[],"isRunning":"0b"}},"Items":[{"Slot":"0b","id":"minecraft:air","Count":"2b","Damage":"15s"},{"Slot":"1b","id":"minecraft:air","Count":"2b","Damage":"15s"},{"Slot":"2b","id":"minecraft:air","Count":"2b","Damage":"15s"}]},
            "elements": [
                "divinerpg:infusion_table@0"
            ]
        },
        {
            "x": -5,
            "y": -1,
            "z": 5,
            "elements": [
                "divinerpg:everstone@0"
            ]
        },
        {
            "x": 0,
            "y": -1,
            "z": 1,
            "nbt": {"id":"divinerpg:te_infusion_table","ForgeCaps":{"abyssalcraft:itemtransfer":{"configurations":[],"isRunning":"0b"}},"Items":[{"Slot":"0b","id":"minecraft:air","Count":"2b","Damage":"15s"},{"Slot":"1b","id":"minecraft:air","Count":"2b","Damage":"15s"},{"Slot":"2b","id":"minecraft:air","Count":"2b","Damage":"15s"}]},
            "elements": [
                "divinerpg:infusion_table@0"
            ]
        },
        {
            "x": -5,
            "y": -3,
            "z": 4,
            "elements": [
                "divinerpg:dream_stone@0"
            ]
        },
        {
            "x": -4,
            "y": -1,
            "z": 5,
            "elements": [
                "casings_all"
            ]
        },
        {
            "x": -4,
            "y": -3,
            "z": -3,
            "elements": [
                "divinerpg:hyrewood_log@0"
            ]
        },
        {
            "x": -4,
            "y": -3,
            "z": 4,
            "elements": [
                "divinerpg:hyrewood_log@0"
            ]
        },
        {
            "x": -5,
            "y": -3,
            "z": -3,
            "elements": [
                "divinerpg:dream_stone@0"
            ]
        },
        {
            "x": 3,
            "y": -1,
            "z": 5,
            "elements": [
                "casings_all"
            ]
        },
        {
            "x": 4,
            "y": -1,
            "z": 5,
            "elements": [
                "divinerpg:everstone@0"
            ]
        },
        {
            "x": 3,
            "y": -3,
            "z": 4,
            "elements": [
                "divinerpg:hyrewood_log@0"
            ]
        },
        {
            "x": 4,
            "y": -3,
            "z": 4,
            "elements": [
                "divinerpg:dream_stone@0"
            ]
        },
        {
            "x": -5,
            "y": 2,
            "z": 2,
            "elements": [
                "divinerpg:dream_stone@0"
            ]
        },
        {
            "x": -1,
            "y": 0,
            "z": 1,
            "elements": [
                "casings_all"
            ]
        },
        {
            "x": -5,
            "y": 0,
            "z": 5,
            "elements": [
                "divinerpg:everstone@0"
            ]
        },
        {
            "x": 0,
            "y": 0,
            "z": 1,
            "elements": [
                "casings_all"
            ]
        },
        {
            "x": -5,
            "y": -2,
            "z": 4,
            "elements": [
                "divinerpg:dream_stone@0"
            ]
        },
        {
            "x": -4,
            "y": 0,
            "z": 5,
            "elements": [
                "divinerpg:dream_stone@0"
            ]
        },
        {
            "x": 4,
            "y": 2,
            "z": -4,
            "elements": [
                "divinerpg:fire_crystal@0"
            ]
        },
        {
            "x": -4,
            "y": -2,
            "z": 4,
            "elements": [
                "divinerpg:hyrewood_log@0"
            ]
        },
        {
            "x": 1,
            "y": 2,
            "z": -4,
            "elements": [
                "divinerpg:dream_stone@0"
            ]
        },
        {
            "x": 4,
            "y": 2,
            "z": 2,
            "elements": [
                "divinerpg:dream_stone@0"
            ]
        },
        {
            "x": 0,
            "y": 2,
            "z": -4,
            "elements": [
                "divinerpg:dream_stone@0"
            ]
        },
        {
            "x": -1,
            "y": 2,
            "z": -4,
            "elements": [
                "divinerpg:dream_stone@0"
            ]
        },
        {
            "x": -2,
            "y": 2,
            "z": -4,
            "elements": [
                "divinerpg:dream_stone@0"
            ]
        },
        {
            "x": 3,
            "y": 0,
            "z": 5,
            "elements": [
                "divinerpg:dream_stone@0"
            ]
        },
        {
            "x": 3,
            "y": -2,
            "z": 4,
            "elements": [
                "divinerpg:hyrewood_log@0"
            ]
        },
        {
            "x": 4,
            "y": 0,
            "z": 5,
            "elements": [
                "divinerpg:everstone@0"
            ]
        },
        {
            "x": -5,
            "y": 2,
            "z": -4,
            "elements": [
                "divinerpg:fire_crystal@0"
            ]
        },
        {
            "x": 4,
            "y": -2,
            "z": 4,
            "elements": [
                "divinerpg:dream_stone@0"
            ]
        },
        {
            "x": -2,
            "y": 3,
            "z": 2,
            "elements": [
                "divinerpg:dream_stone@0"
            ]
        },
        {
            "x": -1,
            "y": 3,
            "z": 2,
            "elements": [
                "divinerpg:everstone@0"
            ]
        },
        {
            "x": 0,
            "y": 3,
            "z": 2,
            "elements": [
                "divinerpg:everstone@0"
            ]
        },
        {
            "x": -1,
            "y": 1,
            "z": 1,
            "elements": [
                "divinerpg:everstone@0"
            ]
        },
        {
            "x": -5,
            "y": 1,
            "z": 5,
            "elements": [
                "divinerpg:everstone@0"
            ]
        },
        {
            "x": 1,
            "y": 3,
            "z": 2,
            "elements": [
                "divinerpg:dream_stone@0"
            ]
        },
        {
            "x": 0,
            "y": 1,
            "z": 1,
            "elements": [
                "divinerpg:everstone@0"
            ]
        },
        {
            "x": 4,
            "y": 1,
            "z": -4,
            "elements": [
                "divinerpg:everstone@0"
            ]
        },
        {
            "x": -5,
            "y": -1,
            "z": 4,
            "elements": [
                "casings_all"
            ]
        },
        {
            "x": -4,
            "y": 1,
            "z": 5,
            "elements": [
                "divinerpg:everstone@0"
            ]
        },
        {
            "x": -4,
            "y": -1,
            "z": 4,
            "elements": [
                "divinerpg:hyrewood_log@0"
            ]
        },
        {
            "x": -3,
            "y": 1,
            "z": 5,
            "elements": [
                "divinerpg:dream_stone@0"
            ]
        },
        {
            "x": 3,
            "y": 1,
            "z": -4,
            "elements": [
                "divinerpg:everstone@0"
            ]
        },
        {
            "x": 2,
            "y": 1,
            "z": -4,
            "elements": [
                "divinerpg:dream_stone@0"
            ]
        },
        {
            "x": 0,
            "y": 3,
            "z": -3,
            "elements": [
                "divinerpg:dream_stone@0"
            ]
        },
        {
            "x": -1,
            "y": 3,
            "z": -3,
            "elements": [
                "divinerpg:dream_stone@0"
            ]
        },
        {
            "x": 2,
            "y": 1,
            "z": 5,
            "elements": [
                "divinerpg:dream_stone@0"
            ]
        },
        {
            "x": -3,
            "y": 1,
            "z": -4,
            "elements": [
                "divinerpg:dream_stone@0"
            ]
        },
        {
            "x": 3,
            "y": 1,
            "z": 5,
            "elements": [
                "divinerpg:everstone@0"
            ]
        },
        {
            "x": 4,
            "y": 1,
            "z": 5,
            "elements": [
                "divinerpg:everstone@0"
            ]
        },
        {
            "x": 3,
            "y": -1,
            "z": 4,
            "elements": [
                "divinerpg:hyrewood_log@0"
            ]
        },
        {
            "x": -4,
            "y": 1,
            "z": -4,
            "elements": [
                "divinerpg:everstone@0"
            ]
        },
        {
            "x": -5,
            "y": 1,
            "z": -4,
            "elements": [
                "divinerpg:everstone@0"
            ]
        },
        {
            "x": 4,
            "y": -1,
            "z": 4,
            "elements": [
                "casings_all"
            ]
        },
        {
            "x": -5,
            "y": 2,
            "z": 1,
            "elements": [
                "divinerpg:dream_stone@0"
            ]
        },
        {
            "x": -1,
            "y": 2,
            "z": 1,
            "elements": [
                "divinerpg:fire_crystal@0"
            ]
        },
        {
            "x": -5,
            "y": 2,
            "z": 5,
            "elements": [
                "divinerpg:fire_crystal@0"
            ]
        },
        {
            "x": 4,
            "y": 0,
            "z": -4,
            "elements": [
                "divinerpg:everstone@0"
            ]
        },
        {
            "x": 0,
            "y": 2,
            "z": 1,
            "elements": [
                "divinerpg:fire_crystal@0"
            ]
        },
        {
            "x": -5,
            "y": 0,
            "z": 4,
            "elements": [
                "divinerpg:dream_stone@0"
            ]
        }
    ]}